{
 "cells": [
  {
   "cell_type": "markdown",
   "id": "abe6a5bb",
   "metadata": {},
   "source": [
    "# Imports"
   ]
  },
  {
   "cell_type": "code",
   "execution_count": 1,
   "id": "c157a9f6",
   "metadata": {},
   "outputs": [],
   "source": [
    "import scikeras"
   ]
  },
  {
   "cell_type": "code",
   "execution_count": 2,
   "id": "af0bd758",
   "metadata": {},
   "outputs": [
    {
     "ename": "ImportError",
     "evalue": "cannot import name 'effective_n_jobs' from 'joblib' (C:\\Users\\vmore\\anaconda3\\envs\\deeplearning-labs\\lib\\site-packages\\joblib\\__init__.py)",
     "output_type": "error",
     "traceback": [
      "\u001b[1;31m---------------------------------------------------------------------------\u001b[0m",
      "\u001b[1;31mImportError\u001b[0m                               Traceback (most recent call last)",
      "Cell \u001b[1;32mIn [2], line 3\u001b[0m\n\u001b[0;32m      1\u001b[0m \u001b[38;5;28;01mimport\u001b[39;00m \u001b[38;5;21;01mpandas\u001b[39;00m \u001b[38;5;28;01mas\u001b[39;00m \u001b[38;5;21;01mpd\u001b[39;00m\n\u001b[0;32m      2\u001b[0m \u001b[38;5;28;01mimport\u001b[39;00m \u001b[38;5;21;01mnumpy\u001b[39;00m \u001b[38;5;28;01mas\u001b[39;00m \u001b[38;5;21;01mnp\u001b[39;00m\n\u001b[1;32m----> 3\u001b[0m \u001b[38;5;28;01mfrom\u001b[39;00m \u001b[38;5;21;01mscikeras\u001b[39;00m\u001b[38;5;21;01m.\u001b[39;00m\u001b[38;5;21;01mwrappers\u001b[39;00m \u001b[38;5;28;01mimport\u001b[39;00m KerasRegressor\n\u001b[0;32m      4\u001b[0m \u001b[38;5;28;01mfrom\u001b[39;00m \u001b[38;5;21;01mtensorflow\u001b[39;00m \u001b[38;5;28;01mimport\u001b[39;00m keras\n\u001b[0;32m      5\u001b[0m \u001b[38;5;28;01mimport\u001b[39;00m \u001b[38;5;21;01mjoblib\u001b[39;00m\n",
      "File \u001b[1;32m~\\anaconda3\\envs\\deeplearning-labs\\lib\\site-packages\\scikeras\\wrappers.py:14\u001b[0m\n\u001b[0;32m     11\u001b[0m \u001b[38;5;28;01mimport\u001b[39;00m \u001b[38;5;21;01mtensorflow\u001b[39;00m \u001b[38;5;28;01mas\u001b[39;00m \u001b[38;5;21;01mtf\u001b[39;00m\n\u001b[0;32m     13\u001b[0m \u001b[38;5;28;01mfrom\u001b[39;00m \u001b[38;5;21;01mscipy\u001b[39;00m\u001b[38;5;21;01m.\u001b[39;00m\u001b[38;5;21;01msparse\u001b[39;00m \u001b[38;5;28;01mimport\u001b[39;00m isspmatrix, lil_matrix\n\u001b[1;32m---> 14\u001b[0m \u001b[38;5;28;01mfrom\u001b[39;00m \u001b[38;5;21;01msklearn\u001b[39;00m\u001b[38;5;21;01m.\u001b[39;00m\u001b[38;5;21;01mbase\u001b[39;00m \u001b[38;5;28;01mimport\u001b[39;00m BaseEstimator, ClassifierMixin, RegressorMixin\n\u001b[0;32m     15\u001b[0m \u001b[38;5;28;01mfrom\u001b[39;00m \u001b[38;5;21;01msklearn\u001b[39;00m\u001b[38;5;21;01m.\u001b[39;00m\u001b[38;5;21;01mexceptions\u001b[39;00m \u001b[38;5;28;01mimport\u001b[39;00m NotFittedError\n\u001b[0;32m     16\u001b[0m \u001b[38;5;28;01mfrom\u001b[39;00m \u001b[38;5;21;01msklearn\u001b[39;00m\u001b[38;5;21;01m.\u001b[39;00m\u001b[38;5;21;01mmetrics\u001b[39;00m \u001b[38;5;28;01mimport\u001b[39;00m accuracy_score \u001b[38;5;28;01mas\u001b[39;00m sklearn_accuracy_score\n",
      "File \u001b[1;32m~\\anaconda3\\envs\\deeplearning-labs\\lib\\site-packages\\sklearn\\__init__.py:82\u001b[0m\n\u001b[0;32m     80\u001b[0m \u001b[38;5;28;01mfrom\u001b[39;00m \u001b[38;5;21;01m.\u001b[39;00m \u001b[38;5;28;01mimport\u001b[39;00m _distributor_init  \u001b[38;5;66;03m# noqa: F401\u001b[39;00m\n\u001b[0;32m     81\u001b[0m \u001b[38;5;28;01mfrom\u001b[39;00m \u001b[38;5;21;01m.\u001b[39;00m \u001b[38;5;28;01mimport\u001b[39;00m __check_build  \u001b[38;5;66;03m# noqa: F401\u001b[39;00m\n\u001b[1;32m---> 82\u001b[0m \u001b[38;5;28;01mfrom\u001b[39;00m \u001b[38;5;21;01m.\u001b[39;00m\u001b[38;5;21;01mbase\u001b[39;00m \u001b[38;5;28;01mimport\u001b[39;00m clone\n\u001b[0;32m     83\u001b[0m \u001b[38;5;28;01mfrom\u001b[39;00m \u001b[38;5;21;01m.\u001b[39;00m\u001b[38;5;21;01mutils\u001b[39;00m\u001b[38;5;21;01m.\u001b[39;00m\u001b[38;5;21;01m_show_versions\u001b[39;00m \u001b[38;5;28;01mimport\u001b[39;00m show_versions\n\u001b[0;32m     85\u001b[0m __all__ \u001b[38;5;241m=\u001b[39m [\n\u001b[0;32m     86\u001b[0m     \u001b[38;5;124m\"\u001b[39m\u001b[38;5;124mcalibration\u001b[39m\u001b[38;5;124m\"\u001b[39m,\n\u001b[0;32m     87\u001b[0m     \u001b[38;5;124m\"\u001b[39m\u001b[38;5;124mcluster\u001b[39m\u001b[38;5;124m\"\u001b[39m,\n\u001b[1;32m   (...)\u001b[0m\n\u001b[0;32m    128\u001b[0m     \u001b[38;5;124m\"\u001b[39m\u001b[38;5;124mshow_versions\u001b[39m\u001b[38;5;124m\"\u001b[39m,\n\u001b[0;32m    129\u001b[0m ]\n",
      "File \u001b[1;32m~\\anaconda3\\envs\\deeplearning-labs\\lib\\site-packages\\sklearn\\base.py:17\u001b[0m\n\u001b[0;32m     15\u001b[0m \u001b[38;5;28;01mfrom\u001b[39;00m \u001b[38;5;21;01m.\u001b[39;00m \u001b[38;5;28;01mimport\u001b[39;00m __version__\n\u001b[0;32m     16\u001b[0m \u001b[38;5;28;01mfrom\u001b[39;00m \u001b[38;5;21;01m.\u001b[39;00m\u001b[38;5;21;01m_config\u001b[39;00m \u001b[38;5;28;01mimport\u001b[39;00m get_config\n\u001b[1;32m---> 17\u001b[0m \u001b[38;5;28;01mfrom\u001b[39;00m \u001b[38;5;21;01m.\u001b[39;00m\u001b[38;5;21;01mutils\u001b[39;00m \u001b[38;5;28;01mimport\u001b[39;00m _IS_32BIT\n\u001b[0;32m     18\u001b[0m \u001b[38;5;28;01mfrom\u001b[39;00m \u001b[38;5;21;01m.\u001b[39;00m\u001b[38;5;21;01mutils\u001b[39;00m\u001b[38;5;21;01m.\u001b[39;00m\u001b[38;5;21;01m_tags\u001b[39;00m \u001b[38;5;28;01mimport\u001b[39;00m (\n\u001b[0;32m     19\u001b[0m     _DEFAULT_TAGS,\n\u001b[0;32m     20\u001b[0m )\n\u001b[0;32m     21\u001b[0m \u001b[38;5;28;01mfrom\u001b[39;00m \u001b[38;5;21;01m.\u001b[39;00m\u001b[38;5;21;01mutils\u001b[39;00m\u001b[38;5;21;01m.\u001b[39;00m\u001b[38;5;21;01mvalidation\u001b[39;00m \u001b[38;5;28;01mimport\u001b[39;00m check_X_y\n",
      "File \u001b[1;32m~\\anaconda3\\envs\\deeplearning-labs\\lib\\site-packages\\sklearn\\utils\\__init__.py:26\u001b[0m\n\u001b[0;32m     24\u001b[0m \u001b[38;5;28;01mfrom\u001b[39;00m \u001b[38;5;21;01m.\u001b[39;00m\u001b[38;5;21;01mmurmurhash\u001b[39;00m \u001b[38;5;28;01mimport\u001b[39;00m murmurhash3_32\n\u001b[0;32m     25\u001b[0m \u001b[38;5;28;01mfrom\u001b[39;00m \u001b[38;5;21;01m.\u001b[39;00m\u001b[38;5;21;01mclass_weight\u001b[39;00m \u001b[38;5;28;01mimport\u001b[39;00m compute_class_weight, compute_sample_weight\n\u001b[1;32m---> 26\u001b[0m \u001b[38;5;28;01mfrom\u001b[39;00m \u001b[38;5;21;01m.\u001b[39;00m \u001b[38;5;28;01mimport\u001b[39;00m _joblib\n\u001b[0;32m     27\u001b[0m \u001b[38;5;28;01mfrom\u001b[39;00m \u001b[38;5;21;01m.\u001b[39;00m\u001b[38;5;21;01m.\u001b[39;00m\u001b[38;5;21;01mexceptions\u001b[39;00m \u001b[38;5;28;01mimport\u001b[39;00m DataConversionWarning\n\u001b[0;32m     28\u001b[0m \u001b[38;5;28;01mfrom\u001b[39;00m \u001b[38;5;21;01m.\u001b[39;00m\u001b[38;5;21;01mdeprecation\u001b[39;00m \u001b[38;5;28;01mimport\u001b[39;00m deprecated\n",
      "File \u001b[1;32m~\\anaconda3\\envs\\deeplearning-labs\\lib\\site-packages\\sklearn\\utils\\_joblib.py:11\u001b[0m\n\u001b[0;32m      9\u001b[0m \u001b[38;5;28;01mfrom\u001b[39;00m \u001b[38;5;21;01mjoblib\u001b[39;00m \u001b[38;5;28;01mimport\u001b[39;00m dump, load\n\u001b[0;32m     10\u001b[0m \u001b[38;5;28;01mfrom\u001b[39;00m \u001b[38;5;21;01mjoblib\u001b[39;00m \u001b[38;5;28;01mimport\u001b[39;00m __version__\n\u001b[1;32m---> 11\u001b[0m \u001b[38;5;28;01mfrom\u001b[39;00m \u001b[38;5;21;01mjoblib\u001b[39;00m \u001b[38;5;28;01mimport\u001b[39;00m effective_n_jobs\n\u001b[0;32m     12\u001b[0m \u001b[38;5;28;01mfrom\u001b[39;00m \u001b[38;5;21;01mjoblib\u001b[39;00m \u001b[38;5;28;01mimport\u001b[39;00m \u001b[38;5;28mhash\u001b[39m\n\u001b[0;32m     13\u001b[0m \u001b[38;5;28;01mfrom\u001b[39;00m \u001b[38;5;21;01mjoblib\u001b[39;00m \u001b[38;5;28;01mimport\u001b[39;00m cpu_count, Parallel, Memory, delayed\n",
      "\u001b[1;31mImportError\u001b[0m: cannot import name 'effective_n_jobs' from 'joblib' (C:\\Users\\vmore\\anaconda3\\envs\\deeplearning-labs\\lib\\site-packages\\joblib\\__init__.py)"
     ]
    }
   ],
   "source": [
    "import pandas as pd\n",
    "import numpy as np\n",
    "from scikeras.wrappers import KerasRegressor\n",
    "from tensorflow import keras\n",
    "import joblib\n",
    "# from plotly.subplots import make_subplots\n",
    "# import plotly.graph_objects as go\n",
    "# import plotly.express as px\n",
    "# import plotly.offline as pyo\n",
    "\n",
    "# import plotly.io as pio\n",
    "# pio.renderers.default='notebook'\n",
    "\n",
    "import matplotlib.pyplot as plt\n",
    "# pyo.init_notebook_mode()\n"
   ]
  },
  {
   "cell_type": "code",
   "execution_count": null,
   "id": "ac2cc1c6",
   "metadata": {},
   "outputs": [],
   "source": [
    "import sklearn.metrics as metrics\n",
    "from sklearn.model_selection import GridSearchCV\n",
    "from sklearn.model_selection import TimeSeriesSplit\n",
    "from sklearn.preprocessing import StandardScaler\n",
    "from sklearn.pipeline import Pipeline\n",
    "# from sklearn.neural_network import MLPRegressor\n",
    "from sklearn.compose import TransformedTargetRegressor"
   ]
  },
  {
   "cell_type": "code",
   "execution_count": 4,
   "id": "2b60731e",
   "metadata": {},
   "outputs": [],
   "source": [
    "# import tensorflow as tf\n",
    "# from tensorflow import keras\n",
    "# from tensorflow.keras import layers\n",
    "# from tensorflow.keras.layers import Dense\n",
    "# from tensorflow.keras.optimizers import SGD\n",
    "# from tensorflow.keras.callbacks import ReduceLROnPlateau\n",
    "# from tensorflow.python.client import device_lib\n",
    "# import sklearn.metrics as metrics\n",
    "# from sklearn.preprocessing import StandardScaler\n",
    "# import h5py"
   ]
  },
  {
   "cell_type": "markdown",
   "id": "fe5a61a1",
   "metadata": {},
   "source": [
    "# Cargar datasets"
   ]
  },
  {
   "cell_type": "code",
   "execution_count": 4,
   "id": "15733a0b",
   "metadata": {},
   "outputs": [],
   "source": [
    "X_train = pd.read_csv('C:/Users/vmore/notebooks/TFM/Modelos eolica/datos/X_train_2y.csv', parse_dates=[0], index_col='datetime_utc')\n",
    "y_train = pd.read_csv('C:/Users/vmore/notebooks/TFM/Modelos eolica/datos/y_train_2y.csv', parse_dates=[0], index_col='datetime_utc')\n",
    "X_test = pd.read_csv('C:/Users/vmore/notebooks/TFM/Modelos eolica/datos/X_test.csv', parse_dates=[0], index_col='datetime_utc')\n",
    "y_test = pd.read_csv('C:/Users/vmore/notebooks/TFM/Modelos eolica/datos/y_test.csv', parse_dates=[0], index_col='datetime_utc')\n",
    "test_data = pd.read_csv('C:/Users/vmore/notebooks/TFM/Modelos eolica/datos/test_data.csv', parse_dates=[0], index_col='datetime_utc')"
   ]
  },
  {
   "cell_type": "markdown",
   "id": "8845a54a",
   "metadata": {},
   "source": [
    "# 4. CNN keras"
   ]
  },
  {
   "cell_type": "code",
   "execution_count": 6,
   "id": "5a5f33f7",
   "metadata": {},
   "outputs": [],
   "source": [
    "target_shape = (12, 1)"
   ]
  },
  {
   "cell_type": "code",
   "execution_count": 7,
   "id": "d1a3904d",
   "metadata": {},
   "outputs": [],
   "source": [
    "# def get_CNN(hidden_layer_sizes, meta, alpha, n_filters, kernel_size):\n",
    "#     model = keras.Sequential()\n",
    "#     model.add(keras.layers.Reshape(target_shape, input_shape=(12,)))\n",
    "#     model.add(keras.layers.Conv1D(filters=n_filters, kernel_size=kernel_size, activation='relu'))\n",
    "#     model.add(keras.layers.MaxPooling1D(pool_size=2))\n",
    "#     model.add(keras.layers.Flatten())\n",
    "#     for hidden_layer_size in hidden_layer_sizes:\n",
    "#         layer = keras.layers.Dense(hidden_layer_size, activation=\"relu\", kernel_regularizer=regularizers.L2(alpha),)\n",
    "#         model.add(layer)       \n",
    "#     out = keras.layers.Dense(6)\n",
    "#     model.add(out)\n",
    "#     return model"
   ]
  },
  {
   "cell_type": "code",
   "execution_count": 8,
   "id": "af58b149",
   "metadata": {},
   "outputs": [],
   "source": [
    "# def get_CNN(hidden_layer_sizes, meta, alpha, n_filters, kernel_size):\n",
    "#     model = keras.Sequential()\n",
    "#     model.add(keras.layers.Reshape(target_shape, input_shape=(12,)))\n",
    "#     model.add(keras.layers.Conv1D(filters=n_filters, kernel_size=kernel_size, activation='relu'))\n",
    "#     model.add(keras.layers.MaxPooling1D(pool_size=2))\n",
    "#     model.add(keras.layers.Flatten())\n",
    "#     for hidden_layer_size in hidden_layer_sizes:\n",
    "#         layer = keras.layers.Dense(hidden_layer_size, activation=\"relu\", kernel_regularizer=regularizers.L2(alpha),)\n",
    "#         model.add(layer)       \n",
    "#     out = keras.layers.Dense(6)\n",
    "#     model.add(out)\n",
    "#     return model\n",
    "\n",
    "# cnn = KerasRegressor(\n",
    "#     model=get_CNN,\n",
    "#     loss=\"mean_absolute_error\",\n",
    "#     optimizer='adam',\n",
    "#     epochs=10000,\n",
    "#     verbose=0,\n",
    "#     shuffle=False,\n",
    "#     batch_size=-1,\n",
    "# )\n",
    "\n",
    "# cnn_pipeline = Pipeline(steps=[('std_sc', StandardScaler()),\n",
    "#                                ('cnn', cnn)])\n",
    "\n",
    "# y_transformer = StandardScaler()\n",
    "# inner_estimator = TransformedTargetRegressor(regressor=cnn_pipeline,\n",
    "#                                              transformer=y_transformer)\n",
    "\n",
    "# param_grid_CNN = {'regressor__cnn__model__hidden_layer_sizes': [(25,), (50,), (100,), (50,50), (100,100),],\n",
    "#                   'regressor__cnn__model__n_filters': [2, 4, 8, 16,],\n",
    "#                   'regressor__cnn__model__alpha': [0.00001, 0.0001, 0.001, 0.01, 0.1, 1, 10,],\n",
    "#                   'regressor__cnn__model__kernel_size': [2, 3, 4, 5],\n",
    "#                  }\n",
    "\n",
    "# # TimeSeries Cross validation\n",
    "# tscv = TimeSeriesSplit(n_splits=2)\n",
    "\n",
    "# # Create the GridSearchCV object\n",
    "# grid_search_CNN = GridSearchCV(inner_estimator, param_grid_CNN, cv=tscv, scoring='neg_mean_absolute_error',\n",
    "#                               n_jobs = 8)\n",
    "\n",
    "# # Fit the GridSearchCV object to the training data\n",
    "# grid_search_CNN.fit(X_train, y_train)"
   ]
  },
  {
   "cell_type": "code",
   "execution_count": 9,
   "id": "52cd49ab",
   "metadata": {},
   "outputs": [
    {
     "name": "stderr",
     "output_type": "stream",
     "text": [
      "C:\\Users\\vmore\\anaconda3\\lib\\site-packages\\sklearn\\model_selection\\_validation.py:378: FitFailedWarning:\n",
      "\n",
      "\n",
      "40 fits failed out of a total of 320.\n",
      "The score on these train-test partitions for these parameters will be set to nan.\n",
      "If these failures are not expected, you can try to debug them by setting error_score='raise'.\n",
      "\n",
      "Below are more details about the failures:\n",
      "--------------------------------------------------------------------------------\n",
      "1 fits failed with the following error:\n",
      "Traceback (most recent call last):\n",
      "  File \"C:\\Users\\vmore\\anaconda3\\lib\\site-packages\\sklearn\\model_selection\\_validation.py\", line 686, in _fit_and_score\n",
      "    estimator.fit(X_train, y_train, **fit_params)\n",
      "  File \"C:\\Users\\vmore\\anaconda3\\lib\\site-packages\\sklearn\\compose\\_target.py\", line 262, in fit\n",
      "    self.regressor_.fit(X, y_trans, **fit_params)\n",
      "  File \"C:\\Users\\vmore\\anaconda3\\lib\\site-packages\\sklearn\\pipeline.py\", line 405, in fit\n",
      "    self._final_estimator.fit(Xt, y, **fit_params_last_step)\n",
      "  File \"C:\\Users\\vmore\\AppData\\Roaming\\Python\\Python38\\site-packages\\scikeras\\wrappers.py\", line 762, in fit\n",
      "    self._fit(\n",
      "  File \"C:\\Users\\vmore\\AppData\\Roaming\\Python\\Python38\\site-packages\\scikeras\\wrappers.py\", line 918, in _fit\n",
      "    X, y = self._initialize(X, y)\n",
      "  File \"C:\\Users\\vmore\\AppData\\Roaming\\Python\\Python38\\site-packages\\scikeras\\wrappers.py\", line 855, in _initialize\n",
      "    self.model_ = self._build_keras_model()\n",
      "  File \"C:\\Users\\vmore\\AppData\\Roaming\\Python\\Python38\\site-packages\\scikeras\\wrappers.py\", line 431, in _build_keras_model\n",
      "    model = final_build_fn(**build_params)\n",
      "  File \"<ipython-input-9-97001f790343>\", line 8, in get_CNN\n",
      "  File \"C:\\Users\\vmore\\anaconda3\\lib\\site-packages\\tensorflow\\python\\training\\tracking\\base.py\", line 587, in _method_wrapper\n",
      "    result = method(self, *args, **kwargs)\n",
      "  File \"C:\\Users\\vmore\\anaconda3\\lib\\site-packages\\keras\\utils\\traceback_utils.py\", line 67, in error_handler\n",
      "    raise e.with_traceback(filtered_tb) from None\n",
      "  File \"C:\\Users\\vmore\\anaconda3\\lib\\site-packages\\tensorflow\\python\\framework\\ops.py\", line 1963, in _create_c_op\n",
      "    raise ValueError(e.message)\n",
      "ValueError: Exception encountered when calling layer \"conv1d_19\" (type Conv1D).\n",
      "\n",
      "Negative dimension size caused by subtracting 5 from 4 for '{{node conv1d_19/Conv1D}} = Conv2D[T=DT_FLOAT, data_format=\"NHWC\", dilations=[1, 1, 1, 1], explicit_paddings=[], padding=\"VALID\", strides=[1, 1, 1, 1], use_cudnn_on_gpu=true](conv1d_19/Conv1D/ExpandDims, conv1d_19/Conv1D/ExpandDims_1)' with input shapes: [?,1,4,2], [1,5,2,2].\n",
      "\n",
      "Call arguments received by layer \"conv1d_19\" (type Conv1D):\n",
      "  • inputs=tf.Tensor(shape=(None, 4, 2), dtype=float32)\n",
      "\n",
      "--------------------------------------------------------------------------------\n",
      "1 fits failed with the following error:\n",
      "Traceback (most recent call last):\n",
      "  File \"C:\\Users\\vmore\\anaconda3\\lib\\site-packages\\sklearn\\model_selection\\_validation.py\", line 686, in _fit_and_score\n",
      "    estimator.fit(X_train, y_train, **fit_params)\n",
      "  File \"C:\\Users\\vmore\\anaconda3\\lib\\site-packages\\sklearn\\compose\\_target.py\", line 262, in fit\n",
      "    self.regressor_.fit(X, y_trans, **fit_params)\n",
      "  File \"C:\\Users\\vmore\\anaconda3\\lib\\site-packages\\sklearn\\pipeline.py\", line 405, in fit\n",
      "    self._final_estimator.fit(Xt, y, **fit_params_last_step)\n",
      "  File \"C:\\Users\\vmore\\AppData\\Roaming\\Python\\Python38\\site-packages\\scikeras\\wrappers.py\", line 762, in fit\n",
      "    self._fit(\n",
      "  File \"C:\\Users\\vmore\\AppData\\Roaming\\Python\\Python38\\site-packages\\scikeras\\wrappers.py\", line 918, in _fit\n",
      "    X, y = self._initialize(X, y)\n",
      "  File \"C:\\Users\\vmore\\AppData\\Roaming\\Python\\Python38\\site-packages\\scikeras\\wrappers.py\", line 855, in _initialize\n",
      "    self.model_ = self._build_keras_model()\n",
      "  File \"C:\\Users\\vmore\\AppData\\Roaming\\Python\\Python38\\site-packages\\scikeras\\wrappers.py\", line 431, in _build_keras_model\n",
      "    model = final_build_fn(**build_params)\n",
      "  File \"<ipython-input-9-97001f790343>\", line 8, in get_CNN\n",
      "  File \"C:\\Users\\vmore\\anaconda3\\lib\\site-packages\\tensorflow\\python\\training\\tracking\\base.py\", line 587, in _method_wrapper\n",
      "    result = method(self, *args, **kwargs)\n",
      "  File \"C:\\Users\\vmore\\anaconda3\\lib\\site-packages\\keras\\utils\\traceback_utils.py\", line 67, in error_handler\n",
      "    raise e.with_traceback(filtered_tb) from None\n",
      "  File \"C:\\Users\\vmore\\anaconda3\\lib\\site-packages\\tensorflow\\python\\framework\\ops.py\", line 1963, in _create_c_op\n",
      "    raise ValueError(e.message)\n",
      "ValueError: Exception encountered when calling layer \"conv1d_21\" (type Conv1D).\n",
      "\n",
      "Negative dimension size caused by subtracting 5 from 4 for '{{node conv1d_21/Conv1D}} = Conv2D[T=DT_FLOAT, data_format=\"NHWC\", dilations=[1, 1, 1, 1], explicit_paddings=[], padding=\"VALID\", strides=[1, 1, 1, 1], use_cudnn_on_gpu=true](conv1d_21/Conv1D/ExpandDims, conv1d_21/Conv1D/ExpandDims_1)' with input shapes: [?,1,4,2], [1,5,2,2].\n",
      "\n",
      "Call arguments received by layer \"conv1d_21\" (type Conv1D):\n",
      "  • inputs=tf.Tensor(shape=(None, 4, 2), dtype=float32)\n",
      "\n",
      "--------------------------------------------------------------------------------\n",
      "1 fits failed with the following error:\n",
      "Traceback (most recent call last):\n",
      "  File \"C:\\Users\\vmore\\anaconda3\\lib\\site-packages\\sklearn\\model_selection\\_validation.py\", line 686, in _fit_and_score\n",
      "    estimator.fit(X_train, y_train, **fit_params)\n",
      "  File \"C:\\Users\\vmore\\anaconda3\\lib\\site-packages\\sklearn\\compose\\_target.py\", line 262, in fit\n",
      "    self.regressor_.fit(X, y_trans, **fit_params)\n",
      "  File \"C:\\Users\\vmore\\anaconda3\\lib\\site-packages\\sklearn\\pipeline.py\", line 405, in fit\n",
      "    self._final_estimator.fit(Xt, y, **fit_params_last_step)\n",
      "  File \"C:\\Users\\vmore\\AppData\\Roaming\\Python\\Python38\\site-packages\\scikeras\\wrappers.py\", line 762, in fit\n",
      "    self._fit(\n",
      "  File \"C:\\Users\\vmore\\AppData\\Roaming\\Python\\Python38\\site-packages\\scikeras\\wrappers.py\", line 918, in _fit\n",
      "    X, y = self._initialize(X, y)\n",
      "  File \"C:\\Users\\vmore\\AppData\\Roaming\\Python\\Python38\\site-packages\\scikeras\\wrappers.py\", line 855, in _initialize\n",
      "    self.model_ = self._build_keras_model()\n",
      "  File \"C:\\Users\\vmore\\AppData\\Roaming\\Python\\Python38\\site-packages\\scikeras\\wrappers.py\", line 431, in _build_keras_model\n",
      "    model = final_build_fn(**build_params)\n",
      "  File \"<ipython-input-9-97001f790343>\", line 8, in get_CNN\n",
      "  File \"C:\\Users\\vmore\\anaconda3\\lib\\site-packages\\tensorflow\\python\\training\\tracking\\base.py\", line 587, in _method_wrapper\n",
      "    result = method(self, *args, **kwargs)\n",
      "  File \"C:\\Users\\vmore\\anaconda3\\lib\\site-packages\\keras\\utils\\traceback_utils.py\", line 67, in error_handler\n",
      "    raise e.with_traceback(filtered_tb) from None\n",
      "  File \"C:\\Users\\vmore\\anaconda3\\lib\\site-packages\\tensorflow\\python\\framework\\ops.py\", line 1963, in _create_c_op\n",
      "    raise ValueError(e.message)\n",
      "ValueError: Exception encountered when calling layer \"conv1d_23\" (type Conv1D).\n",
      "\n",
      "Negative dimension size caused by subtracting 5 from 4 for '{{node conv1d_23/Conv1D}} = Conv2D[T=DT_FLOAT, data_format=\"NHWC\", dilations=[1, 1, 1, 1], explicit_paddings=[], padding=\"VALID\", strides=[1, 1, 1, 1], use_cudnn_on_gpu=true](conv1d_23/Conv1D/ExpandDims, conv1d_23/Conv1D/ExpandDims_1)' with input shapes: [?,1,4,4], [1,5,4,4].\n",
      "\n",
      "Call arguments received by layer \"conv1d_23\" (type Conv1D):\n",
      "  • inputs=tf.Tensor(shape=(None, 4, 4), dtype=float32)\n",
      "\n",
      "--------------------------------------------------------------------------------\n",
      "1 fits failed with the following error:\n",
      "Traceback (most recent call last):\n",
      "  File \"C:\\Users\\vmore\\anaconda3\\lib\\site-packages\\sklearn\\model_selection\\_validation.py\", line 686, in _fit_and_score\n",
      "    estimator.fit(X_train, y_train, **fit_params)\n",
      "  File \"C:\\Users\\vmore\\anaconda3\\lib\\site-packages\\sklearn\\compose\\_target.py\", line 262, in fit\n",
      "    self.regressor_.fit(X, y_trans, **fit_params)\n",
      "  File \"C:\\Users\\vmore\\anaconda3\\lib\\site-packages\\sklearn\\pipeline.py\", line 405, in fit\n",
      "    self._final_estimator.fit(Xt, y, **fit_params_last_step)\n",
      "  File \"C:\\Users\\vmore\\AppData\\Roaming\\Python\\Python38\\site-packages\\scikeras\\wrappers.py\", line 762, in fit\n",
      "    self._fit(\n",
      "  File \"C:\\Users\\vmore\\AppData\\Roaming\\Python\\Python38\\site-packages\\scikeras\\wrappers.py\", line 918, in _fit\n",
      "    X, y = self._initialize(X, y)\n",
      "  File \"C:\\Users\\vmore\\AppData\\Roaming\\Python\\Python38\\site-packages\\scikeras\\wrappers.py\", line 855, in _initialize\n",
      "    self.model_ = self._build_keras_model()\n",
      "  File \"C:\\Users\\vmore\\AppData\\Roaming\\Python\\Python38\\site-packages\\scikeras\\wrappers.py\", line 431, in _build_keras_model\n",
      "    model = final_build_fn(**build_params)\n",
      "  File \"<ipython-input-9-97001f790343>\", line 8, in get_CNN\n",
      "  File \"C:\\Users\\vmore\\anaconda3\\lib\\site-packages\\tensorflow\\python\\training\\tracking\\base.py\", line 587, in _method_wrapper\n",
      "    result = method(self, *args, **kwargs)\n",
      "  File \"C:\\Users\\vmore\\anaconda3\\lib\\site-packages\\keras\\utils\\traceback_utils.py\", line 67, in error_handler\n",
      "    raise e.with_traceback(filtered_tb) from None\n",
      "  File \"C:\\Users\\vmore\\anaconda3\\lib\\site-packages\\tensorflow\\python\\framework\\ops.py\", line 1963, in _create_c_op\n",
      "    raise ValueError(e.message)\n",
      "ValueError: Exception encountered when calling layer \"conv1d_25\" (type Conv1D).\n",
      "\n",
      "Negative dimension size caused by subtracting 5 from 4 for '{{node conv1d_25/Conv1D}} = Conv2D[T=DT_FLOAT, data_format=\"NHWC\", dilations=[1, 1, 1, 1], explicit_paddings=[], padding=\"VALID\", strides=[1, 1, 1, 1], use_cudnn_on_gpu=true](conv1d_25/Conv1D/ExpandDims, conv1d_25/Conv1D/ExpandDims_1)' with input shapes: [?,1,4,4], [1,5,4,4].\n",
      "\n",
      "Call arguments received by layer \"conv1d_25\" (type Conv1D):\n",
      "  • inputs=tf.Tensor(shape=(None, 4, 4), dtype=float32)\n",
      "\n",
      "--------------------------------------------------------------------------------\n",
      "1 fits failed with the following error:\n",
      "Traceback (most recent call last):\n",
      "  File \"C:\\Users\\vmore\\anaconda3\\lib\\site-packages\\sklearn\\model_selection\\_validation.py\", line 686, in _fit_and_score\n",
      "    estimator.fit(X_train, y_train, **fit_params)\n",
      "  File \"C:\\Users\\vmore\\anaconda3\\lib\\site-packages\\sklearn\\compose\\_target.py\", line 262, in fit\n",
      "    self.regressor_.fit(X, y_trans, **fit_params)\n",
      "  File \"C:\\Users\\vmore\\anaconda3\\lib\\site-packages\\sklearn\\pipeline.py\", line 405, in fit\n",
      "    self._final_estimator.fit(Xt, y, **fit_params_last_step)\n",
      "  File \"C:\\Users\\vmore\\AppData\\Roaming\\Python\\Python38\\site-packages\\scikeras\\wrappers.py\", line 762, in fit\n",
      "    self._fit(\n",
      "  File \"C:\\Users\\vmore\\AppData\\Roaming\\Python\\Python38\\site-packages\\scikeras\\wrappers.py\", line 918, in _fit\n",
      "    X, y = self._initialize(X, y)\n",
      "  File \"C:\\Users\\vmore\\AppData\\Roaming\\Python\\Python38\\site-packages\\scikeras\\wrappers.py\", line 855, in _initialize\n",
      "    self.model_ = self._build_keras_model()\n",
      "  File \"C:\\Users\\vmore\\AppData\\Roaming\\Python\\Python38\\site-packages\\scikeras\\wrappers.py\", line 431, in _build_keras_model\n",
      "    model = final_build_fn(**build_params)\n",
      "  File \"<ipython-input-9-97001f790343>\", line 8, in get_CNN\n",
      "  File \"C:\\Users\\vmore\\anaconda3\\lib\\site-packages\\tensorflow\\python\\training\\tracking\\base.py\", line 587, in _method_wrapper\n",
      "    result = method(self, *args, **kwargs)\n",
      "  File \"C:\\Users\\vmore\\anaconda3\\lib\\site-packages\\keras\\utils\\traceback_utils.py\", line 67, in error_handler\n",
      "    raise e.with_traceback(filtered_tb) from None\n",
      "  File \"C:\\Users\\vmore\\anaconda3\\lib\\site-packages\\tensorflow\\python\\framework\\ops.py\", line 1963, in _create_c_op\n",
      "    raise ValueError(e.message)\n",
      "ValueError: Exception encountered when calling layer \"conv1d_27\" (type Conv1D).\n",
      "\n",
      "Negative dimension size caused by subtracting 5 from 4 for '{{node conv1d_27/Conv1D}} = Conv2D[T=DT_FLOAT, data_format=\"NHWC\", dilations=[1, 1, 1, 1], explicit_paddings=[], padding=\"VALID\", strides=[1, 1, 1, 1], use_cudnn_on_gpu=true](conv1d_27/Conv1D/ExpandDims, conv1d_27/Conv1D/ExpandDims_1)' with input shapes: [?,1,4,6], [1,5,6,6].\n",
      "\n",
      "Call arguments received by layer \"conv1d_27\" (type Conv1D):\n",
      "  • inputs=tf.Tensor(shape=(None, 4, 6), dtype=float32)\n",
      "\n",
      "--------------------------------------------------------------------------------\n",
      "1 fits failed with the following error:\n",
      "Traceback (most recent call last):\n",
      "  File \"C:\\Users\\vmore\\anaconda3\\lib\\site-packages\\sklearn\\model_selection\\_validation.py\", line 686, in _fit_and_score\n",
      "    estimator.fit(X_train, y_train, **fit_params)\n",
      "  File \"C:\\Users\\vmore\\anaconda3\\lib\\site-packages\\sklearn\\compose\\_target.py\", line 262, in fit\n",
      "    self.regressor_.fit(X, y_trans, **fit_params)\n",
      "  File \"C:\\Users\\vmore\\anaconda3\\lib\\site-packages\\sklearn\\pipeline.py\", line 405, in fit\n",
      "    self._final_estimator.fit(Xt, y, **fit_params_last_step)\n",
      "  File \"C:\\Users\\vmore\\AppData\\Roaming\\Python\\Python38\\site-packages\\scikeras\\wrappers.py\", line 762, in fit\n",
      "    self._fit(\n",
      "  File \"C:\\Users\\vmore\\AppData\\Roaming\\Python\\Python38\\site-packages\\scikeras\\wrappers.py\", line 918, in _fit\n",
      "    X, y = self._initialize(X, y)\n",
      "  File \"C:\\Users\\vmore\\AppData\\Roaming\\Python\\Python38\\site-packages\\scikeras\\wrappers.py\", line 855, in _initialize\n",
      "    self.model_ = self._build_keras_model()\n",
      "  File \"C:\\Users\\vmore\\AppData\\Roaming\\Python\\Python38\\site-packages\\scikeras\\wrappers.py\", line 431, in _build_keras_model\n",
      "    model = final_build_fn(**build_params)\n",
      "  File \"<ipython-input-9-97001f790343>\", line 8, in get_CNN\n",
      "  File \"C:\\Users\\vmore\\anaconda3\\lib\\site-packages\\tensorflow\\python\\training\\tracking\\base.py\", line 587, in _method_wrapper\n",
      "    result = method(self, *args, **kwargs)\n",
      "  File \"C:\\Users\\vmore\\anaconda3\\lib\\site-packages\\keras\\utils\\traceback_utils.py\", line 67, in error_handler\n",
      "    raise e.with_traceback(filtered_tb) from None\n",
      "  File \"C:\\Users\\vmore\\anaconda3\\lib\\site-packages\\tensorflow\\python\\framework\\ops.py\", line 1963, in _create_c_op\n",
      "    raise ValueError(e.message)\n",
      "ValueError: Exception encountered when calling layer \"conv1d_29\" (type Conv1D).\n",
      "\n",
      "Negative dimension size caused by subtracting 5 from 4 for '{{node conv1d_29/Conv1D}} = Conv2D[T=DT_FLOAT, data_format=\"NHWC\", dilations=[1, 1, 1, 1], explicit_paddings=[], padding=\"VALID\", strides=[1, 1, 1, 1], use_cudnn_on_gpu=true](conv1d_29/Conv1D/ExpandDims, conv1d_29/Conv1D/ExpandDims_1)' with input shapes: [?,1,4,6], [1,5,6,6].\n",
      "\n",
      "Call arguments received by layer \"conv1d_29\" (type Conv1D):\n",
      "  • inputs=tf.Tensor(shape=(None, 4, 6), dtype=float32)\n",
      "\n",
      "--------------------------------------------------------------------------------\n",
      "1 fits failed with the following error:\n",
      "Traceback (most recent call last):\n",
      "  File \"C:\\Users\\vmore\\anaconda3\\lib\\site-packages\\sklearn\\model_selection\\_validation.py\", line 686, in _fit_and_score\n",
      "    estimator.fit(X_train, y_train, **fit_params)\n",
      "  File \"C:\\Users\\vmore\\anaconda3\\lib\\site-packages\\sklearn\\compose\\_target.py\", line 262, in fit\n",
      "    self.regressor_.fit(X, y_trans, **fit_params)\n",
      "  File \"C:\\Users\\vmore\\anaconda3\\lib\\site-packages\\sklearn\\pipeline.py\", line 405, in fit\n",
      "    self._final_estimator.fit(Xt, y, **fit_params_last_step)\n",
      "  File \"C:\\Users\\vmore\\AppData\\Roaming\\Python\\Python38\\site-packages\\scikeras\\wrappers.py\", line 762, in fit\n",
      "    self._fit(\n",
      "  File \"C:\\Users\\vmore\\AppData\\Roaming\\Python\\Python38\\site-packages\\scikeras\\wrappers.py\", line 918, in _fit\n",
      "    X, y = self._initialize(X, y)\n",
      "  File \"C:\\Users\\vmore\\AppData\\Roaming\\Python\\Python38\\site-packages\\scikeras\\wrappers.py\", line 855, in _initialize\n",
      "    self.model_ = self._build_keras_model()\n",
      "  File \"C:\\Users\\vmore\\AppData\\Roaming\\Python\\Python38\\site-packages\\scikeras\\wrappers.py\", line 431, in _build_keras_model\n",
      "    model = final_build_fn(**build_params)\n",
      "  File \"<ipython-input-9-97001f790343>\", line 8, in get_CNN\n",
      "  File \"C:\\Users\\vmore\\anaconda3\\lib\\site-packages\\tensorflow\\python\\training\\tracking\\base.py\", line 587, in _method_wrapper\n",
      "    result = method(self, *args, **kwargs)\n",
      "  File \"C:\\Users\\vmore\\anaconda3\\lib\\site-packages\\keras\\utils\\traceback_utils.py\", line 67, in error_handler\n",
      "    raise e.with_traceback(filtered_tb) from None\n",
      "  File \"C:\\Users\\vmore\\anaconda3\\lib\\site-packages\\tensorflow\\python\\framework\\ops.py\", line 1963, in _create_c_op\n",
      "    raise ValueError(e.message)\n",
      "ValueError: Exception encountered when calling layer \"conv1d_31\" (type Conv1D).\n",
      "\n",
      "Negative dimension size caused by subtracting 5 from 4 for '{{node conv1d_31/Conv1D}} = Conv2D[T=DT_FLOAT, data_format=\"NHWC\", dilations=[1, 1, 1, 1], explicit_paddings=[], padding=\"VALID\", strides=[1, 1, 1, 1], use_cudnn_on_gpu=true](conv1d_31/Conv1D/ExpandDims, conv1d_31/Conv1D/ExpandDims_1)' with input shapes: [?,1,4,8], [1,5,8,8].\n",
      "\n",
      "Call arguments received by layer \"conv1d_31\" (type Conv1D):\n",
      "  • inputs=tf.Tensor(shape=(None, 4, 8), dtype=float32)\n",
      "\n",
      "--------------------------------------------------------------------------------\n",
      "1 fits failed with the following error:\n",
      "Traceback (most recent call last):\n",
      "  File \"C:\\Users\\vmore\\anaconda3\\lib\\site-packages\\sklearn\\model_selection\\_validation.py\", line 686, in _fit_and_score\n",
      "    estimator.fit(X_train, y_train, **fit_params)\n",
      "  File \"C:\\Users\\vmore\\anaconda3\\lib\\site-packages\\sklearn\\compose\\_target.py\", line 262, in fit\n",
      "    self.regressor_.fit(X, y_trans, **fit_params)\n",
      "  File \"C:\\Users\\vmore\\anaconda3\\lib\\site-packages\\sklearn\\pipeline.py\", line 405, in fit\n",
      "    self._final_estimator.fit(Xt, y, **fit_params_last_step)\n",
      "  File \"C:\\Users\\vmore\\AppData\\Roaming\\Python\\Python38\\site-packages\\scikeras\\wrappers.py\", line 762, in fit\n",
      "    self._fit(\n",
      "  File \"C:\\Users\\vmore\\AppData\\Roaming\\Python\\Python38\\site-packages\\scikeras\\wrappers.py\", line 918, in _fit\n",
      "    X, y = self._initialize(X, y)\n",
      "  File \"C:\\Users\\vmore\\AppData\\Roaming\\Python\\Python38\\site-packages\\scikeras\\wrappers.py\", line 855, in _initialize\n",
      "    self.model_ = self._build_keras_model()\n",
      "  File \"C:\\Users\\vmore\\AppData\\Roaming\\Python\\Python38\\site-packages\\scikeras\\wrappers.py\", line 431, in _build_keras_model\n",
      "    model = final_build_fn(**build_params)\n",
      "  File \"<ipython-input-9-97001f790343>\", line 8, in get_CNN\n",
      "  File \"C:\\Users\\vmore\\anaconda3\\lib\\site-packages\\tensorflow\\python\\training\\tracking\\base.py\", line 587, in _method_wrapper\n",
      "    result = method(self, *args, **kwargs)\n",
      "  File \"C:\\Users\\vmore\\anaconda3\\lib\\site-packages\\keras\\utils\\traceback_utils.py\", line 67, in error_handler\n",
      "    raise e.with_traceback(filtered_tb) from None\n",
      "  File \"C:\\Users\\vmore\\anaconda3\\lib\\site-packages\\tensorflow\\python\\framework\\ops.py\", line 1963, in _create_c_op\n",
      "    raise ValueError(e.message)\n",
      "ValueError: Exception encountered when calling layer \"conv1d_33\" (type Conv1D).\n",
      "\n",
      "Negative dimension size caused by subtracting 5 from 4 for '{{node conv1d_33/Conv1D}} = Conv2D[T=DT_FLOAT, data_format=\"NHWC\", dilations=[1, 1, 1, 1], explicit_paddings=[], padding=\"VALID\", strides=[1, 1, 1, 1], use_cudnn_on_gpu=true](conv1d_33/Conv1D/ExpandDims, conv1d_33/Conv1D/ExpandDims_1)' with input shapes: [?,1,4,8], [1,5,8,8].\n",
      "\n",
      "Call arguments received by layer \"conv1d_33\" (type Conv1D):\n",
      "  • inputs=tf.Tensor(shape=(None, 4, 8), dtype=float32)\n",
      "\n",
      "--------------------------------------------------------------------------------\n",
      "1 fits failed with the following error:\n",
      "Traceback (most recent call last):\n",
      "  File \"C:\\Users\\vmore\\anaconda3\\lib\\site-packages\\sklearn\\model_selection\\_validation.py\", line 686, in _fit_and_score\n",
      "    estimator.fit(X_train, y_train, **fit_params)\n",
      "  File \"C:\\Users\\vmore\\anaconda3\\lib\\site-packages\\sklearn\\compose\\_target.py\", line 262, in fit\n",
      "    self.regressor_.fit(X, y_trans, **fit_params)\n",
      "  File \"C:\\Users\\vmore\\anaconda3\\lib\\site-packages\\sklearn\\pipeline.py\", line 405, in fit\n",
      "    self._final_estimator.fit(Xt, y, **fit_params_last_step)\n",
      "  File \"C:\\Users\\vmore\\AppData\\Roaming\\Python\\Python38\\site-packages\\scikeras\\wrappers.py\", line 762, in fit\n",
      "    self._fit(\n",
      "  File \"C:\\Users\\vmore\\AppData\\Roaming\\Python\\Python38\\site-packages\\scikeras\\wrappers.py\", line 918, in _fit\n",
      "    X, y = self._initialize(X, y)\n",
      "  File \"C:\\Users\\vmore\\AppData\\Roaming\\Python\\Python38\\site-packages\\scikeras\\wrappers.py\", line 855, in _initialize\n",
      "    self.model_ = self._build_keras_model()\n",
      "  File \"C:\\Users\\vmore\\AppData\\Roaming\\Python\\Python38\\site-packages\\scikeras\\wrappers.py\", line 431, in _build_keras_model\n",
      "    model = final_build_fn(**build_params)\n",
      "  File \"<ipython-input-9-97001f790343>\", line 8, in get_CNN\n",
      "  File \"C:\\Users\\vmore\\anaconda3\\lib\\site-packages\\tensorflow\\python\\training\\tracking\\base.py\", line 587, in _method_wrapper\n",
      "    result = method(self, *args, **kwargs)\n",
      "  File \"C:\\Users\\vmore\\anaconda3\\lib\\site-packages\\keras\\utils\\traceback_utils.py\", line 67, in error_handler\n",
      "    raise e.with_traceback(filtered_tb) from None\n",
      "  File \"C:\\Users\\vmore\\anaconda3\\lib\\site-packages\\tensorflow\\python\\framework\\ops.py\", line 1963, in _create_c_op\n",
      "    raise ValueError(e.message)\n",
      "ValueError: Exception encountered when calling layer \"conv1d_26\" (type Conv1D).\n",
      "\n",
      "Negative dimension size caused by subtracting 5 from 4 for '{{node conv1d_26/Conv1D}} = Conv2D[T=DT_FLOAT, data_format=\"NHWC\", dilations=[1, 1, 1, 1], explicit_paddings=[], padding=\"VALID\", strides=[1, 1, 1, 1], use_cudnn_on_gpu=true](conv1d_26/Conv1D/ExpandDims, conv1d_26/Conv1D/ExpandDims_1)' with input shapes: [?,1,4,2], [1,5,2,2].\n",
      "\n",
      "Call arguments received by layer \"conv1d_26\" (type Conv1D):\n",
      "  • inputs=tf.Tensor(shape=(None, 4, 2), dtype=float32)\n",
      "\n",
      "--------------------------------------------------------------------------------\n",
      "1 fits failed with the following error:\n",
      "Traceback (most recent call last):\n",
      "  File \"C:\\Users\\vmore\\anaconda3\\lib\\site-packages\\sklearn\\model_selection\\_validation.py\", line 686, in _fit_and_score\n",
      "    estimator.fit(X_train, y_train, **fit_params)\n",
      "  File \"C:\\Users\\vmore\\anaconda3\\lib\\site-packages\\sklearn\\compose\\_target.py\", line 262, in fit\n",
      "    self.regressor_.fit(X, y_trans, **fit_params)\n",
      "  File \"C:\\Users\\vmore\\anaconda3\\lib\\site-packages\\sklearn\\pipeline.py\", line 405, in fit\n",
      "    self._final_estimator.fit(Xt, y, **fit_params_last_step)\n",
      "  File \"C:\\Users\\vmore\\AppData\\Roaming\\Python\\Python38\\site-packages\\scikeras\\wrappers.py\", line 762, in fit\n",
      "    self._fit(\n",
      "  File \"C:\\Users\\vmore\\AppData\\Roaming\\Python\\Python38\\site-packages\\scikeras\\wrappers.py\", line 918, in _fit\n",
      "    X, y = self._initialize(X, y)\n",
      "  File \"C:\\Users\\vmore\\AppData\\Roaming\\Python\\Python38\\site-packages\\scikeras\\wrappers.py\", line 855, in _initialize\n",
      "    self.model_ = self._build_keras_model()\n",
      "  File \"C:\\Users\\vmore\\AppData\\Roaming\\Python\\Python38\\site-packages\\scikeras\\wrappers.py\", line 431, in _build_keras_model\n",
      "    model = final_build_fn(**build_params)\n",
      "  File \"<ipython-input-9-97001f790343>\", line 8, in get_CNN\n",
      "  File \"C:\\Users\\vmore\\anaconda3\\lib\\site-packages\\tensorflow\\python\\training\\tracking\\base.py\", line 587, in _method_wrapper\n",
      "    result = method(self, *args, **kwargs)\n",
      "  File \"C:\\Users\\vmore\\anaconda3\\lib\\site-packages\\keras\\utils\\traceback_utils.py\", line 67, in error_handler\n",
      "    raise e.with_traceback(filtered_tb) from None\n",
      "  File \"C:\\Users\\vmore\\anaconda3\\lib\\site-packages\\tensorflow\\python\\framework\\ops.py\", line 1963, in _create_c_op\n",
      "    raise ValueError(e.message)\n",
      "ValueError: Exception encountered when calling layer \"conv1d_28\" (type Conv1D).\n",
      "\n",
      "Negative dimension size caused by subtracting 5 from 4 for '{{node conv1d_28/Conv1D}} = Conv2D[T=DT_FLOAT, data_format=\"NHWC\", dilations=[1, 1, 1, 1], explicit_paddings=[], padding=\"VALID\", strides=[1, 1, 1, 1], use_cudnn_on_gpu=true](conv1d_28/Conv1D/ExpandDims, conv1d_28/Conv1D/ExpandDims_1)' with input shapes: [?,1,4,2], [1,5,2,2].\n",
      "\n",
      "Call arguments received by layer \"conv1d_28\" (type Conv1D):\n",
      "  • inputs=tf.Tensor(shape=(None, 4, 2), dtype=float32)\n",
      "\n",
      "--------------------------------------------------------------------------------\n",
      "1 fits failed with the following error:\n",
      "Traceback (most recent call last):\n",
      "  File \"C:\\Users\\vmore\\anaconda3\\lib\\site-packages\\sklearn\\model_selection\\_validation.py\", line 686, in _fit_and_score\n",
      "    estimator.fit(X_train, y_train, **fit_params)\n",
      "  File \"C:\\Users\\vmore\\anaconda3\\lib\\site-packages\\sklearn\\compose\\_target.py\", line 262, in fit\n",
      "    self.regressor_.fit(X, y_trans, **fit_params)\n",
      "  File \"C:\\Users\\vmore\\anaconda3\\lib\\site-packages\\sklearn\\pipeline.py\", line 405, in fit\n",
      "    self._final_estimator.fit(Xt, y, **fit_params_last_step)\n",
      "  File \"C:\\Users\\vmore\\AppData\\Roaming\\Python\\Python38\\site-packages\\scikeras\\wrappers.py\", line 762, in fit\n",
      "    self._fit(\n",
      "  File \"C:\\Users\\vmore\\AppData\\Roaming\\Python\\Python38\\site-packages\\scikeras\\wrappers.py\", line 918, in _fit\n",
      "    X, y = self._initialize(X, y)\n",
      "  File \"C:\\Users\\vmore\\AppData\\Roaming\\Python\\Python38\\site-packages\\scikeras\\wrappers.py\", line 855, in _initialize\n",
      "    self.model_ = self._build_keras_model()\n",
      "  File \"C:\\Users\\vmore\\AppData\\Roaming\\Python\\Python38\\site-packages\\scikeras\\wrappers.py\", line 431, in _build_keras_model\n",
      "    model = final_build_fn(**build_params)\n",
      "  File \"<ipython-input-9-97001f790343>\", line 8, in get_CNN\n",
      "  File \"C:\\Users\\vmore\\anaconda3\\lib\\site-packages\\tensorflow\\python\\training\\tracking\\base.py\", line 587, in _method_wrapper\n",
      "    result = method(self, *args, **kwargs)\n",
      "  File \"C:\\Users\\vmore\\anaconda3\\lib\\site-packages\\keras\\utils\\traceback_utils.py\", line 67, in error_handler\n",
      "    raise e.with_traceback(filtered_tb) from None\n",
      "  File \"C:\\Users\\vmore\\anaconda3\\lib\\site-packages\\tensorflow\\python\\framework\\ops.py\", line 1963, in _create_c_op\n",
      "    raise ValueError(e.message)\n",
      "ValueError: Exception encountered when calling layer \"conv1d_30\" (type Conv1D).\n",
      "\n",
      "Negative dimension size caused by subtracting 5 from 4 for '{{node conv1d_30/Conv1D}} = Conv2D[T=DT_FLOAT, data_format=\"NHWC\", dilations=[1, 1, 1, 1], explicit_paddings=[], padding=\"VALID\", strides=[1, 1, 1, 1], use_cudnn_on_gpu=true](conv1d_30/Conv1D/ExpandDims, conv1d_30/Conv1D/ExpandDims_1)' with input shapes: [?,1,4,4], [1,5,4,4].\n",
      "\n",
      "Call arguments received by layer \"conv1d_30\" (type Conv1D):\n",
      "  • inputs=tf.Tensor(shape=(None, 4, 4), dtype=float32)\n",
      "\n",
      "--------------------------------------------------------------------------------\n",
      "1 fits failed with the following error:\n",
      "Traceback (most recent call last):\n",
      "  File \"C:\\Users\\vmore\\anaconda3\\lib\\site-packages\\sklearn\\model_selection\\_validation.py\", line 686, in _fit_and_score\n",
      "    estimator.fit(X_train, y_train, **fit_params)\n",
      "  File \"C:\\Users\\vmore\\anaconda3\\lib\\site-packages\\sklearn\\compose\\_target.py\", line 262, in fit\n",
      "    self.regressor_.fit(X, y_trans, **fit_params)\n",
      "  File \"C:\\Users\\vmore\\anaconda3\\lib\\site-packages\\sklearn\\pipeline.py\", line 405, in fit\n",
      "    self._final_estimator.fit(Xt, y, **fit_params_last_step)\n",
      "  File \"C:\\Users\\vmore\\AppData\\Roaming\\Python\\Python38\\site-packages\\scikeras\\wrappers.py\", line 762, in fit\n",
      "    self._fit(\n",
      "  File \"C:\\Users\\vmore\\AppData\\Roaming\\Python\\Python38\\site-packages\\scikeras\\wrappers.py\", line 918, in _fit\n",
      "    X, y = self._initialize(X, y)\n",
      "  File \"C:\\Users\\vmore\\AppData\\Roaming\\Python\\Python38\\site-packages\\scikeras\\wrappers.py\", line 855, in _initialize\n",
      "    self.model_ = self._build_keras_model()\n",
      "  File \"C:\\Users\\vmore\\AppData\\Roaming\\Python\\Python38\\site-packages\\scikeras\\wrappers.py\", line 431, in _build_keras_model\n",
      "    model = final_build_fn(**build_params)\n",
      "  File \"<ipython-input-9-97001f790343>\", line 8, in get_CNN\n",
      "  File \"C:\\Users\\vmore\\anaconda3\\lib\\site-packages\\tensorflow\\python\\training\\tracking\\base.py\", line 587, in _method_wrapper\n",
      "    result = method(self, *args, **kwargs)\n",
      "  File \"C:\\Users\\vmore\\anaconda3\\lib\\site-packages\\keras\\utils\\traceback_utils.py\", line 67, in error_handler\n",
      "    raise e.with_traceback(filtered_tb) from None\n",
      "  File \"C:\\Users\\vmore\\anaconda3\\lib\\site-packages\\tensorflow\\python\\framework\\ops.py\", line 1963, in _create_c_op\n",
      "    raise ValueError(e.message)\n",
      "ValueError: Exception encountered when calling layer \"conv1d_32\" (type Conv1D).\n",
      "\n",
      "Negative dimension size caused by subtracting 5 from 4 for '{{node conv1d_32/Conv1D}} = Conv2D[T=DT_FLOAT, data_format=\"NHWC\", dilations=[1, 1, 1, 1], explicit_paddings=[], padding=\"VALID\", strides=[1, 1, 1, 1], use_cudnn_on_gpu=true](conv1d_32/Conv1D/ExpandDims, conv1d_32/Conv1D/ExpandDims_1)' with input shapes: [?,1,4,4], [1,5,4,4].\n",
      "\n",
      "Call arguments received by layer \"conv1d_32\" (type Conv1D):\n",
      "  • inputs=tf.Tensor(shape=(None, 4, 4), dtype=float32)\n",
      "\n",
      "--------------------------------------------------------------------------------\n",
      "1 fits failed with the following error:\n",
      "Traceback (most recent call last):\n",
      "  File \"C:\\Users\\vmore\\anaconda3\\lib\\site-packages\\sklearn\\model_selection\\_validation.py\", line 686, in _fit_and_score\n",
      "    estimator.fit(X_train, y_train, **fit_params)\n",
      "  File \"C:\\Users\\vmore\\anaconda3\\lib\\site-packages\\sklearn\\compose\\_target.py\", line 262, in fit\n",
      "    self.regressor_.fit(X, y_trans, **fit_params)\n",
      "  File \"C:\\Users\\vmore\\anaconda3\\lib\\site-packages\\sklearn\\pipeline.py\", line 405, in fit\n",
      "    self._final_estimator.fit(Xt, y, **fit_params_last_step)\n",
      "  File \"C:\\Users\\vmore\\AppData\\Roaming\\Python\\Python38\\site-packages\\scikeras\\wrappers.py\", line 762, in fit\n",
      "    self._fit(\n",
      "  File \"C:\\Users\\vmore\\AppData\\Roaming\\Python\\Python38\\site-packages\\scikeras\\wrappers.py\", line 918, in _fit\n",
      "    X, y = self._initialize(X, y)\n",
      "  File \"C:\\Users\\vmore\\AppData\\Roaming\\Python\\Python38\\site-packages\\scikeras\\wrappers.py\", line 855, in _initialize\n",
      "    self.model_ = self._build_keras_model()\n",
      "  File \"C:\\Users\\vmore\\AppData\\Roaming\\Python\\Python38\\site-packages\\scikeras\\wrappers.py\", line 431, in _build_keras_model\n",
      "    model = final_build_fn(**build_params)\n",
      "  File \"<ipython-input-9-97001f790343>\", line 8, in get_CNN\n",
      "  File \"C:\\Users\\vmore\\anaconda3\\lib\\site-packages\\tensorflow\\python\\training\\tracking\\base.py\", line 587, in _method_wrapper\n",
      "    result = method(self, *args, **kwargs)\n",
      "  File \"C:\\Users\\vmore\\anaconda3\\lib\\site-packages\\keras\\utils\\traceback_utils.py\", line 67, in error_handler\n",
      "    raise e.with_traceback(filtered_tb) from None\n",
      "  File \"C:\\Users\\vmore\\anaconda3\\lib\\site-packages\\tensorflow\\python\\framework\\ops.py\", line 1963, in _create_c_op\n",
      "    raise ValueError(e.message)\n",
      "ValueError: Exception encountered when calling layer \"conv1d_34\" (type Conv1D).\n",
      "\n",
      "Negative dimension size caused by subtracting 5 from 4 for '{{node conv1d_34/Conv1D}} = Conv2D[T=DT_FLOAT, data_format=\"NHWC\", dilations=[1, 1, 1, 1], explicit_paddings=[], padding=\"VALID\", strides=[1, 1, 1, 1], use_cudnn_on_gpu=true](conv1d_34/Conv1D/ExpandDims, conv1d_34/Conv1D/ExpandDims_1)' with input shapes: [?,1,4,6], [1,5,6,6].\n",
      "\n",
      "Call arguments received by layer \"conv1d_34\" (type Conv1D):\n",
      "  • inputs=tf.Tensor(shape=(None, 4, 6), dtype=float32)\n",
      "\n",
      "--------------------------------------------------------------------------------\n",
      "1 fits failed with the following error:\n",
      "Traceback (most recent call last):\n",
      "  File \"C:\\Users\\vmore\\anaconda3\\lib\\site-packages\\sklearn\\model_selection\\_validation.py\", line 686, in _fit_and_score\n",
      "    estimator.fit(X_train, y_train, **fit_params)\n",
      "  File \"C:\\Users\\vmore\\anaconda3\\lib\\site-packages\\sklearn\\compose\\_target.py\", line 262, in fit\n",
      "    self.regressor_.fit(X, y_trans, **fit_params)\n",
      "  File \"C:\\Users\\vmore\\anaconda3\\lib\\site-packages\\sklearn\\pipeline.py\", line 405, in fit\n",
      "    self._final_estimator.fit(Xt, y, **fit_params_last_step)\n",
      "  File \"C:\\Users\\vmore\\AppData\\Roaming\\Python\\Python38\\site-packages\\scikeras\\wrappers.py\", line 762, in fit\n",
      "    self._fit(\n",
      "  File \"C:\\Users\\vmore\\AppData\\Roaming\\Python\\Python38\\site-packages\\scikeras\\wrappers.py\", line 918, in _fit\n",
      "    X, y = self._initialize(X, y)\n",
      "  File \"C:\\Users\\vmore\\AppData\\Roaming\\Python\\Python38\\site-packages\\scikeras\\wrappers.py\", line 855, in _initialize\n",
      "    self.model_ = self._build_keras_model()\n",
      "  File \"C:\\Users\\vmore\\AppData\\Roaming\\Python\\Python38\\site-packages\\scikeras\\wrappers.py\", line 431, in _build_keras_model\n",
      "    model = final_build_fn(**build_params)\n",
      "  File \"<ipython-input-9-97001f790343>\", line 8, in get_CNN\n",
      "  File \"C:\\Users\\vmore\\anaconda3\\lib\\site-packages\\tensorflow\\python\\training\\tracking\\base.py\", line 587, in _method_wrapper\n",
      "    result = method(self, *args, **kwargs)\n",
      "  File \"C:\\Users\\vmore\\anaconda3\\lib\\site-packages\\keras\\utils\\traceback_utils.py\", line 67, in error_handler\n",
      "    raise e.with_traceback(filtered_tb) from None\n",
      "  File \"C:\\Users\\vmore\\anaconda3\\lib\\site-packages\\tensorflow\\python\\framework\\ops.py\", line 1963, in _create_c_op\n",
      "    raise ValueError(e.message)\n",
      "ValueError: Exception encountered when calling layer \"conv1d_36\" (type Conv1D).\n",
      "\n",
      "Negative dimension size caused by subtracting 5 from 4 for '{{node conv1d_36/Conv1D}} = Conv2D[T=DT_FLOAT, data_format=\"NHWC\", dilations=[1, 1, 1, 1], explicit_paddings=[], padding=\"VALID\", strides=[1, 1, 1, 1], use_cudnn_on_gpu=true](conv1d_36/Conv1D/ExpandDims, conv1d_36/Conv1D/ExpandDims_1)' with input shapes: [?,1,4,6], [1,5,6,6].\n",
      "\n",
      "Call arguments received by layer \"conv1d_36\" (type Conv1D):\n",
      "  • inputs=tf.Tensor(shape=(None, 4, 6), dtype=float32)\n",
      "\n",
      "--------------------------------------------------------------------------------\n",
      "1 fits failed with the following error:\n",
      "Traceback (most recent call last):\n",
      "  File \"C:\\Users\\vmore\\anaconda3\\lib\\site-packages\\sklearn\\model_selection\\_validation.py\", line 686, in _fit_and_score\n",
      "    estimator.fit(X_train, y_train, **fit_params)\n",
      "  File \"C:\\Users\\vmore\\anaconda3\\lib\\site-packages\\sklearn\\compose\\_target.py\", line 262, in fit\n",
      "    self.regressor_.fit(X, y_trans, **fit_params)\n",
      "  File \"C:\\Users\\vmore\\anaconda3\\lib\\site-packages\\sklearn\\pipeline.py\", line 405, in fit\n",
      "    self._final_estimator.fit(Xt, y, **fit_params_last_step)\n",
      "  File \"C:\\Users\\vmore\\AppData\\Roaming\\Python\\Python38\\site-packages\\scikeras\\wrappers.py\", line 762, in fit\n",
      "    self._fit(\n",
      "  File \"C:\\Users\\vmore\\AppData\\Roaming\\Python\\Python38\\site-packages\\scikeras\\wrappers.py\", line 918, in _fit\n",
      "    X, y = self._initialize(X, y)\n",
      "  File \"C:\\Users\\vmore\\AppData\\Roaming\\Python\\Python38\\site-packages\\scikeras\\wrappers.py\", line 855, in _initialize\n",
      "    self.model_ = self._build_keras_model()\n",
      "  File \"C:\\Users\\vmore\\AppData\\Roaming\\Python\\Python38\\site-packages\\scikeras\\wrappers.py\", line 431, in _build_keras_model\n",
      "    model = final_build_fn(**build_params)\n",
      "  File \"<ipython-input-9-97001f790343>\", line 8, in get_CNN\n",
      "  File \"C:\\Users\\vmore\\anaconda3\\lib\\site-packages\\tensorflow\\python\\training\\tracking\\base.py\", line 587, in _method_wrapper\n",
      "    result = method(self, *args, **kwargs)\n",
      "  File \"C:\\Users\\vmore\\anaconda3\\lib\\site-packages\\keras\\utils\\traceback_utils.py\", line 67, in error_handler\n",
      "    raise e.with_traceback(filtered_tb) from None\n",
      "  File \"C:\\Users\\vmore\\anaconda3\\lib\\site-packages\\tensorflow\\python\\framework\\ops.py\", line 1963, in _create_c_op\n",
      "    raise ValueError(e.message)\n",
      "ValueError: Exception encountered when calling layer \"conv1d_38\" (type Conv1D).\n",
      "\n",
      "Negative dimension size caused by subtracting 5 from 4 for '{{node conv1d_38/Conv1D}} = Conv2D[T=DT_FLOAT, data_format=\"NHWC\", dilations=[1, 1, 1, 1], explicit_paddings=[], padding=\"VALID\", strides=[1, 1, 1, 1], use_cudnn_on_gpu=true](conv1d_38/Conv1D/ExpandDims, conv1d_38/Conv1D/ExpandDims_1)' with input shapes: [?,1,4,8], [1,5,8,8].\n",
      "\n",
      "Call arguments received by layer \"conv1d_38\" (type Conv1D):\n",
      "  • inputs=tf.Tensor(shape=(None, 4, 8), dtype=float32)\n",
      "\n",
      "--------------------------------------------------------------------------------\n",
      "1 fits failed with the following error:\n",
      "Traceback (most recent call last):\n",
      "  File \"C:\\Users\\vmore\\anaconda3\\lib\\site-packages\\sklearn\\model_selection\\_validation.py\", line 686, in _fit_and_score\n",
      "    estimator.fit(X_train, y_train, **fit_params)\n",
      "  File \"C:\\Users\\vmore\\anaconda3\\lib\\site-packages\\sklearn\\compose\\_target.py\", line 262, in fit\n",
      "    self.regressor_.fit(X, y_trans, **fit_params)\n",
      "  File \"C:\\Users\\vmore\\anaconda3\\lib\\site-packages\\sklearn\\pipeline.py\", line 405, in fit\n",
      "    self._final_estimator.fit(Xt, y, **fit_params_last_step)\n",
      "  File \"C:\\Users\\vmore\\AppData\\Roaming\\Python\\Python38\\site-packages\\scikeras\\wrappers.py\", line 762, in fit\n",
      "    self._fit(\n",
      "  File \"C:\\Users\\vmore\\AppData\\Roaming\\Python\\Python38\\site-packages\\scikeras\\wrappers.py\", line 918, in _fit\n",
      "    X, y = self._initialize(X, y)\n",
      "  File \"C:\\Users\\vmore\\AppData\\Roaming\\Python\\Python38\\site-packages\\scikeras\\wrappers.py\", line 855, in _initialize\n",
      "    self.model_ = self._build_keras_model()\n",
      "  File \"C:\\Users\\vmore\\AppData\\Roaming\\Python\\Python38\\site-packages\\scikeras\\wrappers.py\", line 431, in _build_keras_model\n",
      "    model = final_build_fn(**build_params)\n",
      "  File \"<ipython-input-9-97001f790343>\", line 8, in get_CNN\n",
      "  File \"C:\\Users\\vmore\\anaconda3\\lib\\site-packages\\tensorflow\\python\\training\\tracking\\base.py\", line 587, in _method_wrapper\n",
      "    result = method(self, *args, **kwargs)\n",
      "  File \"C:\\Users\\vmore\\anaconda3\\lib\\site-packages\\keras\\utils\\traceback_utils.py\", line 67, in error_handler\n",
      "    raise e.with_traceback(filtered_tb) from None\n",
      "  File \"C:\\Users\\vmore\\anaconda3\\lib\\site-packages\\tensorflow\\python\\framework\\ops.py\", line 1963, in _create_c_op\n",
      "    raise ValueError(e.message)\n",
      "ValueError: Exception encountered when calling layer \"conv1d_40\" (type Conv1D).\n",
      "\n",
      "Negative dimension size caused by subtracting 5 from 4 for '{{node conv1d_40/Conv1D}} = Conv2D[T=DT_FLOAT, data_format=\"NHWC\", dilations=[1, 1, 1, 1], explicit_paddings=[], padding=\"VALID\", strides=[1, 1, 1, 1], use_cudnn_on_gpu=true](conv1d_40/Conv1D/ExpandDims, conv1d_40/Conv1D/ExpandDims_1)' with input shapes: [?,1,4,8], [1,5,8,8].\n",
      "\n",
      "Call arguments received by layer \"conv1d_40\" (type Conv1D):\n",
      "  • inputs=tf.Tensor(shape=(None, 4, 8), dtype=float32)\n",
      "\n",
      "--------------------------------------------------------------------------------\n",
      "1 fits failed with the following error:\n",
      "Traceback (most recent call last):\n",
      "  File \"C:\\Users\\vmore\\anaconda3\\lib\\site-packages\\sklearn\\model_selection\\_validation.py\", line 686, in _fit_and_score\n",
      "    estimator.fit(X_train, y_train, **fit_params)\n",
      "  File \"C:\\Users\\vmore\\anaconda3\\lib\\site-packages\\sklearn\\compose\\_target.py\", line 262, in fit\n",
      "    self.regressor_.fit(X, y_trans, **fit_params)\n",
      "  File \"C:\\Users\\vmore\\anaconda3\\lib\\site-packages\\sklearn\\pipeline.py\", line 405, in fit\n",
      "    self._final_estimator.fit(Xt, y, **fit_params_last_step)\n",
      "  File \"C:\\Users\\vmore\\AppData\\Roaming\\Python\\Python38\\site-packages\\scikeras\\wrappers.py\", line 762, in fit\n",
      "    self._fit(\n",
      "  File \"C:\\Users\\vmore\\AppData\\Roaming\\Python\\Python38\\site-packages\\scikeras\\wrappers.py\", line 918, in _fit\n",
      "    X, y = self._initialize(X, y)\n",
      "  File \"C:\\Users\\vmore\\AppData\\Roaming\\Python\\Python38\\site-packages\\scikeras\\wrappers.py\", line 855, in _initialize\n",
      "    self.model_ = self._build_keras_model()\n",
      "  File \"C:\\Users\\vmore\\AppData\\Roaming\\Python\\Python38\\site-packages\\scikeras\\wrappers.py\", line 431, in _build_keras_model\n",
      "    model = final_build_fn(**build_params)\n",
      "  File \"<ipython-input-9-97001f790343>\", line 8, in get_CNN\n",
      "  File \"C:\\Users\\vmore\\anaconda3\\lib\\site-packages\\tensorflow\\python\\training\\tracking\\base.py\", line 587, in _method_wrapper\n",
      "    result = method(self, *args, **kwargs)\n",
      "  File \"C:\\Users\\vmore\\anaconda3\\lib\\site-packages\\keras\\utils\\traceback_utils.py\", line 67, in error_handler\n",
      "    raise e.with_traceback(filtered_tb) from None\n",
      "  File \"C:\\Users\\vmore\\anaconda3\\lib\\site-packages\\tensorflow\\python\\framework\\ops.py\", line 1963, in _create_c_op\n",
      "    raise ValueError(e.message)\n",
      "ValueError: Exception encountered when calling layer \"conv1d_55\" (type Conv1D).\n",
      "\n",
      "Negative dimension size caused by subtracting 5 from 4 for '{{node conv1d_55/Conv1D}} = Conv2D[T=DT_FLOAT, data_format=\"NHWC\", dilations=[1, 1, 1, 1], explicit_paddings=[], padding=\"VALID\", strides=[1, 1, 1, 1], use_cudnn_on_gpu=true](conv1d_55/Conv1D/ExpandDims, conv1d_55/Conv1D/ExpandDims_1)' with input shapes: [?,1,4,2], [1,5,2,2].\n",
      "\n",
      "Call arguments received by layer \"conv1d_55\" (type Conv1D):\n",
      "  • inputs=tf.Tensor(shape=(None, 4, 2), dtype=float32)\n",
      "\n",
      "--------------------------------------------------------------------------------\n",
      "1 fits failed with the following error:\n",
      "Traceback (most recent call last):\n",
      "  File \"C:\\Users\\vmore\\anaconda3\\lib\\site-packages\\sklearn\\model_selection\\_validation.py\", line 686, in _fit_and_score\n",
      "    estimator.fit(X_train, y_train, **fit_params)\n",
      "  File \"C:\\Users\\vmore\\anaconda3\\lib\\site-packages\\sklearn\\compose\\_target.py\", line 262, in fit\n",
      "    self.regressor_.fit(X, y_trans, **fit_params)\n",
      "  File \"C:\\Users\\vmore\\anaconda3\\lib\\site-packages\\sklearn\\pipeline.py\", line 405, in fit\n",
      "    self._final_estimator.fit(Xt, y, **fit_params_last_step)\n",
      "  File \"C:\\Users\\vmore\\AppData\\Roaming\\Python\\Python38\\site-packages\\scikeras\\wrappers.py\", line 762, in fit\n",
      "    self._fit(\n",
      "  File \"C:\\Users\\vmore\\AppData\\Roaming\\Python\\Python38\\site-packages\\scikeras\\wrappers.py\", line 918, in _fit\n",
      "    X, y = self._initialize(X, y)\n",
      "  File \"C:\\Users\\vmore\\AppData\\Roaming\\Python\\Python38\\site-packages\\scikeras\\wrappers.py\", line 855, in _initialize\n",
      "    self.model_ = self._build_keras_model()\n",
      "  File \"C:\\Users\\vmore\\AppData\\Roaming\\Python\\Python38\\site-packages\\scikeras\\wrappers.py\", line 431, in _build_keras_model\n",
      "    model = final_build_fn(**build_params)\n",
      "  File \"<ipython-input-9-97001f790343>\", line 8, in get_CNN\n",
      "  File \"C:\\Users\\vmore\\anaconda3\\lib\\site-packages\\tensorflow\\python\\training\\tracking\\base.py\", line 587, in _method_wrapper\n",
      "    result = method(self, *args, **kwargs)\n",
      "  File \"C:\\Users\\vmore\\anaconda3\\lib\\site-packages\\keras\\utils\\traceback_utils.py\", line 67, in error_handler\n",
      "    raise e.with_traceback(filtered_tb) from None\n",
      "  File \"C:\\Users\\vmore\\anaconda3\\lib\\site-packages\\tensorflow\\python\\framework\\ops.py\", line 1963, in _create_c_op\n",
      "    raise ValueError(e.message)\n",
      "ValueError: Exception encountered when calling layer \"conv1d_57\" (type Conv1D).\n",
      "\n",
      "Negative dimension size caused by subtracting 5 from 4 for '{{node conv1d_57/Conv1D}} = Conv2D[T=DT_FLOAT, data_format=\"NHWC\", dilations=[1, 1, 1, 1], explicit_paddings=[], padding=\"VALID\", strides=[1, 1, 1, 1], use_cudnn_on_gpu=true](conv1d_57/Conv1D/ExpandDims, conv1d_57/Conv1D/ExpandDims_1)' with input shapes: [?,1,4,2], [1,5,2,2].\n",
      "\n",
      "Call arguments received by layer \"conv1d_57\" (type Conv1D):\n",
      "  • inputs=tf.Tensor(shape=(None, 4, 2), dtype=float32)\n",
      "\n",
      "--------------------------------------------------------------------------------\n",
      "1 fits failed with the following error:\n",
      "Traceback (most recent call last):\n",
      "  File \"C:\\Users\\vmore\\anaconda3\\lib\\site-packages\\sklearn\\model_selection\\_validation.py\", line 686, in _fit_and_score\n",
      "    estimator.fit(X_train, y_train, **fit_params)\n",
      "  File \"C:\\Users\\vmore\\anaconda3\\lib\\site-packages\\sklearn\\compose\\_target.py\", line 262, in fit\n",
      "    self.regressor_.fit(X, y_trans, **fit_params)\n",
      "  File \"C:\\Users\\vmore\\anaconda3\\lib\\site-packages\\sklearn\\pipeline.py\", line 405, in fit\n",
      "    self._final_estimator.fit(Xt, y, **fit_params_last_step)\n",
      "  File \"C:\\Users\\vmore\\AppData\\Roaming\\Python\\Python38\\site-packages\\scikeras\\wrappers.py\", line 762, in fit\n",
      "    self._fit(\n",
      "  File \"C:\\Users\\vmore\\AppData\\Roaming\\Python\\Python38\\site-packages\\scikeras\\wrappers.py\", line 918, in _fit\n",
      "    X, y = self._initialize(X, y)\n",
      "  File \"C:\\Users\\vmore\\AppData\\Roaming\\Python\\Python38\\site-packages\\scikeras\\wrappers.py\", line 855, in _initialize\n",
      "    self.model_ = self._build_keras_model()\n",
      "  File \"C:\\Users\\vmore\\AppData\\Roaming\\Python\\Python38\\site-packages\\scikeras\\wrappers.py\", line 431, in _build_keras_model\n",
      "    model = final_build_fn(**build_params)\n",
      "  File \"<ipython-input-9-97001f790343>\", line 8, in get_CNN\n",
      "  File \"C:\\Users\\vmore\\anaconda3\\lib\\site-packages\\tensorflow\\python\\training\\tracking\\base.py\", line 587, in _method_wrapper\n",
      "    result = method(self, *args, **kwargs)\n",
      "  File \"C:\\Users\\vmore\\anaconda3\\lib\\site-packages\\keras\\utils\\traceback_utils.py\", line 67, in error_handler\n",
      "    raise e.with_traceback(filtered_tb) from None\n",
      "  File \"C:\\Users\\vmore\\anaconda3\\lib\\site-packages\\tensorflow\\python\\framework\\ops.py\", line 1963, in _create_c_op\n",
      "    raise ValueError(e.message)\n",
      "ValueError: Exception encountered when calling layer \"conv1d_59\" (type Conv1D).\n",
      "\n",
      "Negative dimension size caused by subtracting 5 from 4 for '{{node conv1d_59/Conv1D}} = Conv2D[T=DT_FLOAT, data_format=\"NHWC\", dilations=[1, 1, 1, 1], explicit_paddings=[], padding=\"VALID\", strides=[1, 1, 1, 1], use_cudnn_on_gpu=true](conv1d_59/Conv1D/ExpandDims, conv1d_59/Conv1D/ExpandDims_1)' with input shapes: [?,1,4,4], [1,5,4,4].\n",
      "\n",
      "Call arguments received by layer \"conv1d_59\" (type Conv1D):\n",
      "  • inputs=tf.Tensor(shape=(None, 4, 4), dtype=float32)\n",
      "\n",
      "--------------------------------------------------------------------------------\n",
      "1 fits failed with the following error:\n",
      "Traceback (most recent call last):\n",
      "  File \"C:\\Users\\vmore\\anaconda3\\lib\\site-packages\\sklearn\\model_selection\\_validation.py\", line 686, in _fit_and_score\n",
      "    estimator.fit(X_train, y_train, **fit_params)\n",
      "  File \"C:\\Users\\vmore\\anaconda3\\lib\\site-packages\\sklearn\\compose\\_target.py\", line 262, in fit\n",
      "    self.regressor_.fit(X, y_trans, **fit_params)\n",
      "  File \"C:\\Users\\vmore\\anaconda3\\lib\\site-packages\\sklearn\\pipeline.py\", line 405, in fit\n",
      "    self._final_estimator.fit(Xt, y, **fit_params_last_step)\n",
      "  File \"C:\\Users\\vmore\\AppData\\Roaming\\Python\\Python38\\site-packages\\scikeras\\wrappers.py\", line 762, in fit\n",
      "    self._fit(\n",
      "  File \"C:\\Users\\vmore\\AppData\\Roaming\\Python\\Python38\\site-packages\\scikeras\\wrappers.py\", line 918, in _fit\n",
      "    X, y = self._initialize(X, y)\n",
      "  File \"C:\\Users\\vmore\\AppData\\Roaming\\Python\\Python38\\site-packages\\scikeras\\wrappers.py\", line 855, in _initialize\n",
      "    self.model_ = self._build_keras_model()\n",
      "  File \"C:\\Users\\vmore\\AppData\\Roaming\\Python\\Python38\\site-packages\\scikeras\\wrappers.py\", line 431, in _build_keras_model\n",
      "    model = final_build_fn(**build_params)\n",
      "  File \"<ipython-input-9-97001f790343>\", line 8, in get_CNN\n",
      "  File \"C:\\Users\\vmore\\anaconda3\\lib\\site-packages\\tensorflow\\python\\training\\tracking\\base.py\", line 587, in _method_wrapper\n",
      "    result = method(self, *args, **kwargs)\n",
      "  File \"C:\\Users\\vmore\\anaconda3\\lib\\site-packages\\keras\\utils\\traceback_utils.py\", line 67, in error_handler\n",
      "    raise e.with_traceback(filtered_tb) from None\n",
      "  File \"C:\\Users\\vmore\\anaconda3\\lib\\site-packages\\tensorflow\\python\\framework\\ops.py\", line 1963, in _create_c_op\n",
      "    raise ValueError(e.message)\n",
      "ValueError: Exception encountered when calling layer \"conv1d_61\" (type Conv1D).\n",
      "\n",
      "Negative dimension size caused by subtracting 5 from 4 for '{{node conv1d_61/Conv1D}} = Conv2D[T=DT_FLOAT, data_format=\"NHWC\", dilations=[1, 1, 1, 1], explicit_paddings=[], padding=\"VALID\", strides=[1, 1, 1, 1], use_cudnn_on_gpu=true](conv1d_61/Conv1D/ExpandDims, conv1d_61/Conv1D/ExpandDims_1)' with input shapes: [?,1,4,4], [1,5,4,4].\n",
      "\n",
      "Call arguments received by layer \"conv1d_61\" (type Conv1D):\n",
      "  • inputs=tf.Tensor(shape=(None, 4, 4), dtype=float32)\n",
      "\n",
      "--------------------------------------------------------------------------------\n",
      "1 fits failed with the following error:\n",
      "Traceback (most recent call last):\n",
      "  File \"C:\\Users\\vmore\\anaconda3\\lib\\site-packages\\sklearn\\model_selection\\_validation.py\", line 686, in _fit_and_score\n",
      "    estimator.fit(X_train, y_train, **fit_params)\n",
      "  File \"C:\\Users\\vmore\\anaconda3\\lib\\site-packages\\sklearn\\compose\\_target.py\", line 262, in fit\n",
      "    self.regressor_.fit(X, y_trans, **fit_params)\n",
      "  File \"C:\\Users\\vmore\\anaconda3\\lib\\site-packages\\sklearn\\pipeline.py\", line 405, in fit\n",
      "    self._final_estimator.fit(Xt, y, **fit_params_last_step)\n",
      "  File \"C:\\Users\\vmore\\AppData\\Roaming\\Python\\Python38\\site-packages\\scikeras\\wrappers.py\", line 762, in fit\n",
      "    self._fit(\n",
      "  File \"C:\\Users\\vmore\\AppData\\Roaming\\Python\\Python38\\site-packages\\scikeras\\wrappers.py\", line 918, in _fit\n",
      "    X, y = self._initialize(X, y)\n",
      "  File \"C:\\Users\\vmore\\AppData\\Roaming\\Python\\Python38\\site-packages\\scikeras\\wrappers.py\", line 855, in _initialize\n",
      "    self.model_ = self._build_keras_model()\n",
      "  File \"C:\\Users\\vmore\\AppData\\Roaming\\Python\\Python38\\site-packages\\scikeras\\wrappers.py\", line 431, in _build_keras_model\n",
      "    model = final_build_fn(**build_params)\n",
      "  File \"<ipython-input-9-97001f790343>\", line 8, in get_CNN\n",
      "  File \"C:\\Users\\vmore\\anaconda3\\lib\\site-packages\\tensorflow\\python\\training\\tracking\\base.py\", line 587, in _method_wrapper\n",
      "    result = method(self, *args, **kwargs)\n",
      "  File \"C:\\Users\\vmore\\anaconda3\\lib\\site-packages\\keras\\utils\\traceback_utils.py\", line 67, in error_handler\n",
      "    raise e.with_traceback(filtered_tb) from None\n",
      "  File \"C:\\Users\\vmore\\anaconda3\\lib\\site-packages\\tensorflow\\python\\framework\\ops.py\", line 1963, in _create_c_op\n",
      "    raise ValueError(e.message)\n",
      "ValueError: Exception encountered when calling layer \"conv1d_63\" (type Conv1D).\n",
      "\n",
      "Negative dimension size caused by subtracting 5 from 4 for '{{node conv1d_63/Conv1D}} = Conv2D[T=DT_FLOAT, data_format=\"NHWC\", dilations=[1, 1, 1, 1], explicit_paddings=[], padding=\"VALID\", strides=[1, 1, 1, 1], use_cudnn_on_gpu=true](conv1d_63/Conv1D/ExpandDims, conv1d_63/Conv1D/ExpandDims_1)' with input shapes: [?,1,4,6], [1,5,6,6].\n",
      "\n",
      "Call arguments received by layer \"conv1d_63\" (type Conv1D):\n",
      "  • inputs=tf.Tensor(shape=(None, 4, 6), dtype=float32)\n",
      "\n",
      "--------------------------------------------------------------------------------\n",
      "1 fits failed with the following error:\n",
      "Traceback (most recent call last):\n",
      "  File \"C:\\Users\\vmore\\anaconda3\\lib\\site-packages\\sklearn\\model_selection\\_validation.py\", line 686, in _fit_and_score\n",
      "    estimator.fit(X_train, y_train, **fit_params)\n",
      "  File \"C:\\Users\\vmore\\anaconda3\\lib\\site-packages\\sklearn\\compose\\_target.py\", line 262, in fit\n",
      "    self.regressor_.fit(X, y_trans, **fit_params)\n",
      "  File \"C:\\Users\\vmore\\anaconda3\\lib\\site-packages\\sklearn\\pipeline.py\", line 405, in fit\n",
      "    self._final_estimator.fit(Xt, y, **fit_params_last_step)\n",
      "  File \"C:\\Users\\vmore\\AppData\\Roaming\\Python\\Python38\\site-packages\\scikeras\\wrappers.py\", line 762, in fit\n",
      "    self._fit(\n",
      "  File \"C:\\Users\\vmore\\AppData\\Roaming\\Python\\Python38\\site-packages\\scikeras\\wrappers.py\", line 918, in _fit\n",
      "    X, y = self._initialize(X, y)\n",
      "  File \"C:\\Users\\vmore\\AppData\\Roaming\\Python\\Python38\\site-packages\\scikeras\\wrappers.py\", line 855, in _initialize\n",
      "    self.model_ = self._build_keras_model()\n",
      "  File \"C:\\Users\\vmore\\AppData\\Roaming\\Python\\Python38\\site-packages\\scikeras\\wrappers.py\", line 431, in _build_keras_model\n",
      "    model = final_build_fn(**build_params)\n",
      "  File \"<ipython-input-9-97001f790343>\", line 8, in get_CNN\n",
      "  File \"C:\\Users\\vmore\\anaconda3\\lib\\site-packages\\tensorflow\\python\\training\\tracking\\base.py\", line 587, in _method_wrapper\n",
      "    result = method(self, *args, **kwargs)\n",
      "  File \"C:\\Users\\vmore\\anaconda3\\lib\\site-packages\\keras\\utils\\traceback_utils.py\", line 67, in error_handler\n",
      "    raise e.with_traceback(filtered_tb) from None\n",
      "  File \"C:\\Users\\vmore\\anaconda3\\lib\\site-packages\\tensorflow\\python\\framework\\ops.py\", line 1963, in _create_c_op\n",
      "    raise ValueError(e.message)\n",
      "ValueError: Exception encountered when calling layer \"conv1d_65\" (type Conv1D).\n",
      "\n",
      "Negative dimension size caused by subtracting 5 from 4 for '{{node conv1d_65/Conv1D}} = Conv2D[T=DT_FLOAT, data_format=\"NHWC\", dilations=[1, 1, 1, 1], explicit_paddings=[], padding=\"VALID\", strides=[1, 1, 1, 1], use_cudnn_on_gpu=true](conv1d_65/Conv1D/ExpandDims, conv1d_65/Conv1D/ExpandDims_1)' with input shapes: [?,1,4,6], [1,5,6,6].\n",
      "\n",
      "Call arguments received by layer \"conv1d_65\" (type Conv1D):\n",
      "  • inputs=tf.Tensor(shape=(None, 4, 6), dtype=float32)\n",
      "\n",
      "--------------------------------------------------------------------------------\n",
      "1 fits failed with the following error:\n",
      "Traceback (most recent call last):\n",
      "  File \"C:\\Users\\vmore\\anaconda3\\lib\\site-packages\\sklearn\\model_selection\\_validation.py\", line 686, in _fit_and_score\n",
      "    estimator.fit(X_train, y_train, **fit_params)\n",
      "  File \"C:\\Users\\vmore\\anaconda3\\lib\\site-packages\\sklearn\\compose\\_target.py\", line 262, in fit\n",
      "    self.regressor_.fit(X, y_trans, **fit_params)\n",
      "  File \"C:\\Users\\vmore\\anaconda3\\lib\\site-packages\\sklearn\\pipeline.py\", line 405, in fit\n",
      "    self._final_estimator.fit(Xt, y, **fit_params_last_step)\n",
      "  File \"C:\\Users\\vmore\\AppData\\Roaming\\Python\\Python38\\site-packages\\scikeras\\wrappers.py\", line 762, in fit\n",
      "    self._fit(\n",
      "  File \"C:\\Users\\vmore\\AppData\\Roaming\\Python\\Python38\\site-packages\\scikeras\\wrappers.py\", line 918, in _fit\n",
      "    X, y = self._initialize(X, y)\n",
      "  File \"C:\\Users\\vmore\\AppData\\Roaming\\Python\\Python38\\site-packages\\scikeras\\wrappers.py\", line 855, in _initialize\n",
      "    self.model_ = self._build_keras_model()\n",
      "  File \"C:\\Users\\vmore\\AppData\\Roaming\\Python\\Python38\\site-packages\\scikeras\\wrappers.py\", line 431, in _build_keras_model\n",
      "    model = final_build_fn(**build_params)\n",
      "  File \"<ipython-input-9-97001f790343>\", line 8, in get_CNN\n",
      "  File \"C:\\Users\\vmore\\anaconda3\\lib\\site-packages\\tensorflow\\python\\training\\tracking\\base.py\", line 587, in _method_wrapper\n",
      "    result = method(self, *args, **kwargs)\n",
      "  File \"C:\\Users\\vmore\\anaconda3\\lib\\site-packages\\keras\\utils\\traceback_utils.py\", line 67, in error_handler\n",
      "    raise e.with_traceback(filtered_tb) from None\n",
      "  File \"C:\\Users\\vmore\\anaconda3\\lib\\site-packages\\tensorflow\\python\\framework\\ops.py\", line 1963, in _create_c_op\n",
      "    raise ValueError(e.message)\n",
      "ValueError: Exception encountered when calling layer \"conv1d_67\" (type Conv1D).\n",
      "\n",
      "Negative dimension size caused by subtracting 5 from 4 for '{{node conv1d_67/Conv1D}} = Conv2D[T=DT_FLOAT, data_format=\"NHWC\", dilations=[1, 1, 1, 1], explicit_paddings=[], padding=\"VALID\", strides=[1, 1, 1, 1], use_cudnn_on_gpu=true](conv1d_67/Conv1D/ExpandDims, conv1d_67/Conv1D/ExpandDims_1)' with input shapes: [?,1,4,8], [1,5,8,8].\n",
      "\n",
      "Call arguments received by layer \"conv1d_67\" (type Conv1D):\n",
      "  • inputs=tf.Tensor(shape=(None, 4, 8), dtype=float32)\n",
      "\n",
      "--------------------------------------------------------------------------------\n",
      "1 fits failed with the following error:\n",
      "Traceback (most recent call last):\n",
      "  File \"C:\\Users\\vmore\\anaconda3\\lib\\site-packages\\sklearn\\model_selection\\_validation.py\", line 686, in _fit_and_score\n",
      "    estimator.fit(X_train, y_train, **fit_params)\n",
      "  File \"C:\\Users\\vmore\\anaconda3\\lib\\site-packages\\sklearn\\compose\\_target.py\", line 262, in fit\n",
      "    self.regressor_.fit(X, y_trans, **fit_params)\n",
      "  File \"C:\\Users\\vmore\\anaconda3\\lib\\site-packages\\sklearn\\pipeline.py\", line 405, in fit\n",
      "    self._final_estimator.fit(Xt, y, **fit_params_last_step)\n",
      "  File \"C:\\Users\\vmore\\AppData\\Roaming\\Python\\Python38\\site-packages\\scikeras\\wrappers.py\", line 762, in fit\n",
      "    self._fit(\n",
      "  File \"C:\\Users\\vmore\\AppData\\Roaming\\Python\\Python38\\site-packages\\scikeras\\wrappers.py\", line 918, in _fit\n",
      "    X, y = self._initialize(X, y)\n",
      "  File \"C:\\Users\\vmore\\AppData\\Roaming\\Python\\Python38\\site-packages\\scikeras\\wrappers.py\", line 855, in _initialize\n",
      "    self.model_ = self._build_keras_model()\n",
      "  File \"C:\\Users\\vmore\\AppData\\Roaming\\Python\\Python38\\site-packages\\scikeras\\wrappers.py\", line 431, in _build_keras_model\n",
      "    model = final_build_fn(**build_params)\n",
      "  File \"<ipython-input-9-97001f790343>\", line 8, in get_CNN\n",
      "  File \"C:\\Users\\vmore\\anaconda3\\lib\\site-packages\\tensorflow\\python\\training\\tracking\\base.py\", line 587, in _method_wrapper\n",
      "    result = method(self, *args, **kwargs)\n",
      "  File \"C:\\Users\\vmore\\anaconda3\\lib\\site-packages\\keras\\utils\\traceback_utils.py\", line 67, in error_handler\n",
      "    raise e.with_traceback(filtered_tb) from None\n",
      "  File \"C:\\Users\\vmore\\anaconda3\\lib\\site-packages\\tensorflow\\python\\framework\\ops.py\", line 1963, in _create_c_op\n",
      "    raise ValueError(e.message)\n",
      "ValueError: Exception encountered when calling layer \"conv1d_69\" (type Conv1D).\n",
      "\n",
      "Negative dimension size caused by subtracting 5 from 4 for '{{node conv1d_69/Conv1D}} = Conv2D[T=DT_FLOAT, data_format=\"NHWC\", dilations=[1, 1, 1, 1], explicit_paddings=[], padding=\"VALID\", strides=[1, 1, 1, 1], use_cudnn_on_gpu=true](conv1d_69/Conv1D/ExpandDims, conv1d_69/Conv1D/ExpandDims_1)' with input shapes: [?,1,4,8], [1,5,8,8].\n",
      "\n",
      "Call arguments received by layer \"conv1d_69\" (type Conv1D):\n",
      "  • inputs=tf.Tensor(shape=(None, 4, 8), dtype=float32)\n",
      "\n",
      "--------------------------------------------------------------------------------\n",
      "1 fits failed with the following error:\n",
      "Traceback (most recent call last):\n",
      "  File \"C:\\Users\\vmore\\anaconda3\\lib\\site-packages\\sklearn\\model_selection\\_validation.py\", line 686, in _fit_and_score\n",
      "    estimator.fit(X_train, y_train, **fit_params)\n",
      "  File \"C:\\Users\\vmore\\anaconda3\\lib\\site-packages\\sklearn\\compose\\_target.py\", line 262, in fit\n",
      "    self.regressor_.fit(X, y_trans, **fit_params)\n",
      "  File \"C:\\Users\\vmore\\anaconda3\\lib\\site-packages\\sklearn\\pipeline.py\", line 405, in fit\n",
      "    self._final_estimator.fit(Xt, y, **fit_params_last_step)\n",
      "  File \"C:\\Users\\vmore\\AppData\\Roaming\\Python\\Python38\\site-packages\\scikeras\\wrappers.py\", line 762, in fit\n",
      "    self._fit(\n",
      "  File \"C:\\Users\\vmore\\AppData\\Roaming\\Python\\Python38\\site-packages\\scikeras\\wrappers.py\", line 918, in _fit\n",
      "    X, y = self._initialize(X, y)\n",
      "  File \"C:\\Users\\vmore\\AppData\\Roaming\\Python\\Python38\\site-packages\\scikeras\\wrappers.py\", line 855, in _initialize\n",
      "    self.model_ = self._build_keras_model()\n",
      "  File \"C:\\Users\\vmore\\AppData\\Roaming\\Python\\Python38\\site-packages\\scikeras\\wrappers.py\", line 431, in _build_keras_model\n",
      "    model = final_build_fn(**build_params)\n",
      "  File \"<ipython-input-9-97001f790343>\", line 8, in get_CNN\n",
      "  File \"C:\\Users\\vmore\\anaconda3\\lib\\site-packages\\tensorflow\\python\\training\\tracking\\base.py\", line 587, in _method_wrapper\n",
      "    result = method(self, *args, **kwargs)\n",
      "  File \"C:\\Users\\vmore\\anaconda3\\lib\\site-packages\\keras\\utils\\traceback_utils.py\", line 67, in error_handler\n",
      "    raise e.with_traceback(filtered_tb) from None\n",
      "  File \"C:\\Users\\vmore\\anaconda3\\lib\\site-packages\\tensorflow\\python\\framework\\ops.py\", line 1963, in _create_c_op\n",
      "    raise ValueError(e.message)\n",
      "ValueError: Exception encountered when calling layer \"conv1d_88\" (type Conv1D).\n",
      "\n",
      "Negative dimension size caused by subtracting 5 from 4 for '{{node conv1d_88/Conv1D}} = Conv2D[T=DT_FLOAT, data_format=\"NHWC\", dilations=[1, 1, 1, 1], explicit_paddings=[], padding=\"VALID\", strides=[1, 1, 1, 1], use_cudnn_on_gpu=true](conv1d_88/Conv1D/ExpandDims, conv1d_88/Conv1D/ExpandDims_1)' with input shapes: [?,1,4,2], [1,5,2,2].\n",
      "\n",
      "Call arguments received by layer \"conv1d_88\" (type Conv1D):\n",
      "  • inputs=tf.Tensor(shape=(None, 4, 2), dtype=float32)\n",
      "\n",
      "--------------------------------------------------------------------------------\n",
      "1 fits failed with the following error:\n",
      "Traceback (most recent call last):\n",
      "  File \"C:\\Users\\vmore\\anaconda3\\lib\\site-packages\\sklearn\\model_selection\\_validation.py\", line 686, in _fit_and_score\n",
      "    estimator.fit(X_train, y_train, **fit_params)\n",
      "  File \"C:\\Users\\vmore\\anaconda3\\lib\\site-packages\\sklearn\\compose\\_target.py\", line 262, in fit\n",
      "    self.regressor_.fit(X, y_trans, **fit_params)\n",
      "  File \"C:\\Users\\vmore\\anaconda3\\lib\\site-packages\\sklearn\\pipeline.py\", line 405, in fit\n",
      "    self._final_estimator.fit(Xt, y, **fit_params_last_step)\n",
      "  File \"C:\\Users\\vmore\\AppData\\Roaming\\Python\\Python38\\site-packages\\scikeras\\wrappers.py\", line 762, in fit\n",
      "    self._fit(\n",
      "  File \"C:\\Users\\vmore\\AppData\\Roaming\\Python\\Python38\\site-packages\\scikeras\\wrappers.py\", line 918, in _fit\n",
      "    X, y = self._initialize(X, y)\n",
      "  File \"C:\\Users\\vmore\\AppData\\Roaming\\Python\\Python38\\site-packages\\scikeras\\wrappers.py\", line 855, in _initialize\n",
      "    self.model_ = self._build_keras_model()\n",
      "  File \"C:\\Users\\vmore\\AppData\\Roaming\\Python\\Python38\\site-packages\\scikeras\\wrappers.py\", line 431, in _build_keras_model\n",
      "    model = final_build_fn(**build_params)\n",
      "  File \"<ipython-input-9-97001f790343>\", line 8, in get_CNN\n",
      "  File \"C:\\Users\\vmore\\anaconda3\\lib\\site-packages\\tensorflow\\python\\training\\tracking\\base.py\", line 587, in _method_wrapper\n",
      "    result = method(self, *args, **kwargs)\n",
      "  File \"C:\\Users\\vmore\\anaconda3\\lib\\site-packages\\keras\\utils\\traceback_utils.py\", line 67, in error_handler\n",
      "    raise e.with_traceback(filtered_tb) from None\n",
      "  File \"C:\\Users\\vmore\\anaconda3\\lib\\site-packages\\tensorflow\\python\\framework\\ops.py\", line 1963, in _create_c_op\n",
      "    raise ValueError(e.message)\n",
      "ValueError: Exception encountered when calling layer \"conv1d_90\" (type Conv1D).\n",
      "\n",
      "Negative dimension size caused by subtracting 5 from 4 for '{{node conv1d_90/Conv1D}} = Conv2D[T=DT_FLOAT, data_format=\"NHWC\", dilations=[1, 1, 1, 1], explicit_paddings=[], padding=\"VALID\", strides=[1, 1, 1, 1], use_cudnn_on_gpu=true](conv1d_90/Conv1D/ExpandDims, conv1d_90/Conv1D/ExpandDims_1)' with input shapes: [?,1,4,2], [1,5,2,2].\n",
      "\n",
      "Call arguments received by layer \"conv1d_90\" (type Conv1D):\n",
      "  • inputs=tf.Tensor(shape=(None, 4, 2), dtype=float32)\n",
      "\n",
      "--------------------------------------------------------------------------------\n",
      "1 fits failed with the following error:\n",
      "Traceback (most recent call last):\n",
      "  File \"C:\\Users\\vmore\\anaconda3\\lib\\site-packages\\sklearn\\model_selection\\_validation.py\", line 686, in _fit_and_score\n",
      "    estimator.fit(X_train, y_train, **fit_params)\n",
      "  File \"C:\\Users\\vmore\\anaconda3\\lib\\site-packages\\sklearn\\compose\\_target.py\", line 262, in fit\n",
      "    self.regressor_.fit(X, y_trans, **fit_params)\n",
      "  File \"C:\\Users\\vmore\\anaconda3\\lib\\site-packages\\sklearn\\pipeline.py\", line 405, in fit\n",
      "    self._final_estimator.fit(Xt, y, **fit_params_last_step)\n",
      "  File \"C:\\Users\\vmore\\AppData\\Roaming\\Python\\Python38\\site-packages\\scikeras\\wrappers.py\", line 762, in fit\n",
      "    self._fit(\n",
      "  File \"C:\\Users\\vmore\\AppData\\Roaming\\Python\\Python38\\site-packages\\scikeras\\wrappers.py\", line 918, in _fit\n",
      "    X, y = self._initialize(X, y)\n",
      "  File \"C:\\Users\\vmore\\AppData\\Roaming\\Python\\Python38\\site-packages\\scikeras\\wrappers.py\", line 855, in _initialize\n",
      "    self.model_ = self._build_keras_model()\n",
      "  File \"C:\\Users\\vmore\\AppData\\Roaming\\Python\\Python38\\site-packages\\scikeras\\wrappers.py\", line 431, in _build_keras_model\n",
      "    model = final_build_fn(**build_params)\n",
      "  File \"<ipython-input-9-97001f790343>\", line 8, in get_CNN\n",
      "  File \"C:\\Users\\vmore\\anaconda3\\lib\\site-packages\\tensorflow\\python\\training\\tracking\\base.py\", line 587, in _method_wrapper\n",
      "    result = method(self, *args, **kwargs)\n",
      "  File \"C:\\Users\\vmore\\anaconda3\\lib\\site-packages\\keras\\utils\\traceback_utils.py\", line 67, in error_handler\n",
      "    raise e.with_traceback(filtered_tb) from None\n",
      "  File \"C:\\Users\\vmore\\anaconda3\\lib\\site-packages\\tensorflow\\python\\framework\\ops.py\", line 1963, in _create_c_op\n",
      "    raise ValueError(e.message)\n",
      "ValueError: Exception encountered when calling layer \"conv1d_92\" (type Conv1D).\n",
      "\n",
      "Negative dimension size caused by subtracting 5 from 4 for '{{node conv1d_92/Conv1D}} = Conv2D[T=DT_FLOAT, data_format=\"NHWC\", dilations=[1, 1, 1, 1], explicit_paddings=[], padding=\"VALID\", strides=[1, 1, 1, 1], use_cudnn_on_gpu=true](conv1d_92/Conv1D/ExpandDims, conv1d_92/Conv1D/ExpandDims_1)' with input shapes: [?,1,4,4], [1,5,4,4].\n",
      "\n",
      "Call arguments received by layer \"conv1d_92\" (type Conv1D):\n",
      "  • inputs=tf.Tensor(shape=(None, 4, 4), dtype=float32)\n",
      "\n",
      "--------------------------------------------------------------------------------\n",
      "1 fits failed with the following error:\n",
      "Traceback (most recent call last):\n",
      "  File \"C:\\Users\\vmore\\anaconda3\\lib\\site-packages\\sklearn\\model_selection\\_validation.py\", line 686, in _fit_and_score\n",
      "    estimator.fit(X_train, y_train, **fit_params)\n",
      "  File \"C:\\Users\\vmore\\anaconda3\\lib\\site-packages\\sklearn\\compose\\_target.py\", line 262, in fit\n",
      "    self.regressor_.fit(X, y_trans, **fit_params)\n",
      "  File \"C:\\Users\\vmore\\anaconda3\\lib\\site-packages\\sklearn\\pipeline.py\", line 405, in fit\n",
      "    self._final_estimator.fit(Xt, y, **fit_params_last_step)\n",
      "  File \"C:\\Users\\vmore\\AppData\\Roaming\\Python\\Python38\\site-packages\\scikeras\\wrappers.py\", line 762, in fit\n",
      "    self._fit(\n",
      "  File \"C:\\Users\\vmore\\AppData\\Roaming\\Python\\Python38\\site-packages\\scikeras\\wrappers.py\", line 918, in _fit\n",
      "    X, y = self._initialize(X, y)\n",
      "  File \"C:\\Users\\vmore\\AppData\\Roaming\\Python\\Python38\\site-packages\\scikeras\\wrappers.py\", line 855, in _initialize\n",
      "    self.model_ = self._build_keras_model()\n",
      "  File \"C:\\Users\\vmore\\AppData\\Roaming\\Python\\Python38\\site-packages\\scikeras\\wrappers.py\", line 431, in _build_keras_model\n",
      "    model = final_build_fn(**build_params)\n",
      "  File \"<ipython-input-9-97001f790343>\", line 8, in get_CNN\n",
      "  File \"C:\\Users\\vmore\\anaconda3\\lib\\site-packages\\tensorflow\\python\\training\\tracking\\base.py\", line 587, in _method_wrapper\n",
      "    result = method(self, *args, **kwargs)\n",
      "  File \"C:\\Users\\vmore\\anaconda3\\lib\\site-packages\\keras\\utils\\traceback_utils.py\", line 67, in error_handler\n",
      "    raise e.with_traceback(filtered_tb) from None\n",
      "  File \"C:\\Users\\vmore\\anaconda3\\lib\\site-packages\\tensorflow\\python\\framework\\ops.py\", line 1963, in _create_c_op\n",
      "    raise ValueError(e.message)\n",
      "ValueError: Exception encountered when calling layer \"conv1d_94\" (type Conv1D).\n",
      "\n",
      "Negative dimension size caused by subtracting 5 from 4 for '{{node conv1d_94/Conv1D}} = Conv2D[T=DT_FLOAT, data_format=\"NHWC\", dilations=[1, 1, 1, 1], explicit_paddings=[], padding=\"VALID\", strides=[1, 1, 1, 1], use_cudnn_on_gpu=true](conv1d_94/Conv1D/ExpandDims, conv1d_94/Conv1D/ExpandDims_1)' with input shapes: [?,1,4,4], [1,5,4,4].\n",
      "\n",
      "Call arguments received by layer \"conv1d_94\" (type Conv1D):\n",
      "  • inputs=tf.Tensor(shape=(None, 4, 4), dtype=float32)\n",
      "\n",
      "--------------------------------------------------------------------------------\n",
      "1 fits failed with the following error:\n",
      "Traceback (most recent call last):\n",
      "  File \"C:\\Users\\vmore\\anaconda3\\lib\\site-packages\\sklearn\\model_selection\\_validation.py\", line 686, in _fit_and_score\n",
      "    estimator.fit(X_train, y_train, **fit_params)\n",
      "  File \"C:\\Users\\vmore\\anaconda3\\lib\\site-packages\\sklearn\\compose\\_target.py\", line 262, in fit\n",
      "    self.regressor_.fit(X, y_trans, **fit_params)\n",
      "  File \"C:\\Users\\vmore\\anaconda3\\lib\\site-packages\\sklearn\\pipeline.py\", line 405, in fit\n",
      "    self._final_estimator.fit(Xt, y, **fit_params_last_step)\n",
      "  File \"C:\\Users\\vmore\\AppData\\Roaming\\Python\\Python38\\site-packages\\scikeras\\wrappers.py\", line 762, in fit\n",
      "    self._fit(\n",
      "  File \"C:\\Users\\vmore\\AppData\\Roaming\\Python\\Python38\\site-packages\\scikeras\\wrappers.py\", line 918, in _fit\n",
      "    X, y = self._initialize(X, y)\n",
      "  File \"C:\\Users\\vmore\\AppData\\Roaming\\Python\\Python38\\site-packages\\scikeras\\wrappers.py\", line 855, in _initialize\n",
      "    self.model_ = self._build_keras_model()\n",
      "  File \"C:\\Users\\vmore\\AppData\\Roaming\\Python\\Python38\\site-packages\\scikeras\\wrappers.py\", line 431, in _build_keras_model\n",
      "    model = final_build_fn(**build_params)\n",
      "  File \"<ipython-input-9-97001f790343>\", line 8, in get_CNN\n",
      "  File \"C:\\Users\\vmore\\anaconda3\\lib\\site-packages\\tensorflow\\python\\training\\tracking\\base.py\", line 587, in _method_wrapper\n",
      "    result = method(self, *args, **kwargs)\n",
      "  File \"C:\\Users\\vmore\\anaconda3\\lib\\site-packages\\keras\\utils\\traceback_utils.py\", line 67, in error_handler\n",
      "    raise e.with_traceback(filtered_tb) from None\n",
      "  File \"C:\\Users\\vmore\\anaconda3\\lib\\site-packages\\tensorflow\\python\\framework\\ops.py\", line 1963, in _create_c_op\n",
      "    raise ValueError(e.message)\n",
      "ValueError: Exception encountered when calling layer \"conv1d_96\" (type Conv1D).\n",
      "\n",
      "Negative dimension size caused by subtracting 5 from 4 for '{{node conv1d_96/Conv1D}} = Conv2D[T=DT_FLOAT, data_format=\"NHWC\", dilations=[1, 1, 1, 1], explicit_paddings=[], padding=\"VALID\", strides=[1, 1, 1, 1], use_cudnn_on_gpu=true](conv1d_96/Conv1D/ExpandDims, conv1d_96/Conv1D/ExpandDims_1)' with input shapes: [?,1,4,6], [1,5,6,6].\n",
      "\n",
      "Call arguments received by layer \"conv1d_96\" (type Conv1D):\n",
      "  • inputs=tf.Tensor(shape=(None, 4, 6), dtype=float32)\n",
      "\n",
      "--------------------------------------------------------------------------------\n",
      "1 fits failed with the following error:\n",
      "Traceback (most recent call last):\n",
      "  File \"C:\\Users\\vmore\\anaconda3\\lib\\site-packages\\sklearn\\model_selection\\_validation.py\", line 686, in _fit_and_score\n",
      "    estimator.fit(X_train, y_train, **fit_params)\n",
      "  File \"C:\\Users\\vmore\\anaconda3\\lib\\site-packages\\sklearn\\compose\\_target.py\", line 262, in fit\n",
      "    self.regressor_.fit(X, y_trans, **fit_params)\n",
      "  File \"C:\\Users\\vmore\\anaconda3\\lib\\site-packages\\sklearn\\pipeline.py\", line 405, in fit\n",
      "    self._final_estimator.fit(Xt, y, **fit_params_last_step)\n",
      "  File \"C:\\Users\\vmore\\AppData\\Roaming\\Python\\Python38\\site-packages\\scikeras\\wrappers.py\", line 762, in fit\n",
      "    self._fit(\n",
      "  File \"C:\\Users\\vmore\\AppData\\Roaming\\Python\\Python38\\site-packages\\scikeras\\wrappers.py\", line 918, in _fit\n",
      "    X, y = self._initialize(X, y)\n",
      "  File \"C:\\Users\\vmore\\AppData\\Roaming\\Python\\Python38\\site-packages\\scikeras\\wrappers.py\", line 855, in _initialize\n",
      "    self.model_ = self._build_keras_model()\n",
      "  File \"C:\\Users\\vmore\\AppData\\Roaming\\Python\\Python38\\site-packages\\scikeras\\wrappers.py\", line 431, in _build_keras_model\n",
      "    model = final_build_fn(**build_params)\n",
      "  File \"<ipython-input-9-97001f790343>\", line 8, in get_CNN\n",
      "  File \"C:\\Users\\vmore\\anaconda3\\lib\\site-packages\\tensorflow\\python\\training\\tracking\\base.py\", line 587, in _method_wrapper\n",
      "    result = method(self, *args, **kwargs)\n",
      "  File \"C:\\Users\\vmore\\anaconda3\\lib\\site-packages\\keras\\utils\\traceback_utils.py\", line 67, in error_handler\n",
      "    raise e.with_traceback(filtered_tb) from None\n",
      "  File \"C:\\Users\\vmore\\anaconda3\\lib\\site-packages\\tensorflow\\python\\framework\\ops.py\", line 1963, in _create_c_op\n",
      "    raise ValueError(e.message)\n",
      "ValueError: Exception encountered when calling layer \"conv1d_98\" (type Conv1D).\n",
      "\n",
      "Negative dimension size caused by subtracting 5 from 4 for '{{node conv1d_98/Conv1D}} = Conv2D[T=DT_FLOAT, data_format=\"NHWC\", dilations=[1, 1, 1, 1], explicit_paddings=[], padding=\"VALID\", strides=[1, 1, 1, 1], use_cudnn_on_gpu=true](conv1d_98/Conv1D/ExpandDims, conv1d_98/Conv1D/ExpandDims_1)' with input shapes: [?,1,4,6], [1,5,6,6].\n",
      "\n",
      "Call arguments received by layer \"conv1d_98\" (type Conv1D):\n",
      "  • inputs=tf.Tensor(shape=(None, 4, 6), dtype=float32)\n",
      "\n",
      "--------------------------------------------------------------------------------\n",
      "1 fits failed with the following error:\n",
      "Traceback (most recent call last):\n",
      "  File \"C:\\Users\\vmore\\anaconda3\\lib\\site-packages\\sklearn\\model_selection\\_validation.py\", line 686, in _fit_and_score\n",
      "    estimator.fit(X_train, y_train, **fit_params)\n",
      "  File \"C:\\Users\\vmore\\anaconda3\\lib\\site-packages\\sklearn\\compose\\_target.py\", line 262, in fit\n",
      "    self.regressor_.fit(X, y_trans, **fit_params)\n",
      "  File \"C:\\Users\\vmore\\anaconda3\\lib\\site-packages\\sklearn\\pipeline.py\", line 405, in fit\n",
      "    self._final_estimator.fit(Xt, y, **fit_params_last_step)\n",
      "  File \"C:\\Users\\vmore\\AppData\\Roaming\\Python\\Python38\\site-packages\\scikeras\\wrappers.py\", line 762, in fit\n",
      "    self._fit(\n",
      "  File \"C:\\Users\\vmore\\AppData\\Roaming\\Python\\Python38\\site-packages\\scikeras\\wrappers.py\", line 918, in _fit\n",
      "    X, y = self._initialize(X, y)\n",
      "  File \"C:\\Users\\vmore\\AppData\\Roaming\\Python\\Python38\\site-packages\\scikeras\\wrappers.py\", line 855, in _initialize\n",
      "    self.model_ = self._build_keras_model()\n",
      "  File \"C:\\Users\\vmore\\AppData\\Roaming\\Python\\Python38\\site-packages\\scikeras\\wrappers.py\", line 431, in _build_keras_model\n",
      "    model = final_build_fn(**build_params)\n",
      "  File \"<ipython-input-9-97001f790343>\", line 8, in get_CNN\n",
      "  File \"C:\\Users\\vmore\\anaconda3\\lib\\site-packages\\tensorflow\\python\\training\\tracking\\base.py\", line 587, in _method_wrapper\n",
      "    result = method(self, *args, **kwargs)\n",
      "  File \"C:\\Users\\vmore\\anaconda3\\lib\\site-packages\\keras\\utils\\traceback_utils.py\", line 67, in error_handler\n",
      "    raise e.with_traceback(filtered_tb) from None\n",
      "  File \"C:\\Users\\vmore\\anaconda3\\lib\\site-packages\\tensorflow\\python\\framework\\ops.py\", line 1963, in _create_c_op\n",
      "    raise ValueError(e.message)\n",
      "ValueError: Exception encountered when calling layer \"conv1d_100\" (type Conv1D).\n",
      "\n",
      "Negative dimension size caused by subtracting 5 from 4 for '{{node conv1d_100/Conv1D}} = Conv2D[T=DT_FLOAT, data_format=\"NHWC\", dilations=[1, 1, 1, 1], explicit_paddings=[], padding=\"VALID\", strides=[1, 1, 1, 1], use_cudnn_on_gpu=true](conv1d_100/Conv1D/ExpandDims, conv1d_100/Conv1D/ExpandDims_1)' with input shapes: [?,1,4,8], [1,5,8,8].\n",
      "\n",
      "Call arguments received by layer \"conv1d_100\" (type Conv1D):\n",
      "  • inputs=tf.Tensor(shape=(None, 4, 8), dtype=float32)\n",
      "\n",
      "--------------------------------------------------------------------------------\n",
      "1 fits failed with the following error:\n",
      "Traceback (most recent call last):\n",
      "  File \"C:\\Users\\vmore\\anaconda3\\lib\\site-packages\\sklearn\\model_selection\\_validation.py\", line 686, in _fit_and_score\n",
      "    estimator.fit(X_train, y_train, **fit_params)\n",
      "  File \"C:\\Users\\vmore\\anaconda3\\lib\\site-packages\\sklearn\\compose\\_target.py\", line 262, in fit\n",
      "    self.regressor_.fit(X, y_trans, **fit_params)\n",
      "  File \"C:\\Users\\vmore\\anaconda3\\lib\\site-packages\\sklearn\\pipeline.py\", line 405, in fit\n",
      "    self._final_estimator.fit(Xt, y, **fit_params_last_step)\n",
      "  File \"C:\\Users\\vmore\\AppData\\Roaming\\Python\\Python38\\site-packages\\scikeras\\wrappers.py\", line 762, in fit\n",
      "    self._fit(\n",
      "  File \"C:\\Users\\vmore\\AppData\\Roaming\\Python\\Python38\\site-packages\\scikeras\\wrappers.py\", line 918, in _fit\n",
      "    X, y = self._initialize(X, y)\n",
      "  File \"C:\\Users\\vmore\\AppData\\Roaming\\Python\\Python38\\site-packages\\scikeras\\wrappers.py\", line 855, in _initialize\n",
      "    self.model_ = self._build_keras_model()\n",
      "  File \"C:\\Users\\vmore\\AppData\\Roaming\\Python\\Python38\\site-packages\\scikeras\\wrappers.py\", line 431, in _build_keras_model\n",
      "    model = final_build_fn(**build_params)\n",
      "  File \"<ipython-input-9-97001f790343>\", line 8, in get_CNN\n",
      "  File \"C:\\Users\\vmore\\anaconda3\\lib\\site-packages\\tensorflow\\python\\training\\tracking\\base.py\", line 587, in _method_wrapper\n",
      "    result = method(self, *args, **kwargs)\n",
      "  File \"C:\\Users\\vmore\\anaconda3\\lib\\site-packages\\keras\\utils\\traceback_utils.py\", line 67, in error_handler\n",
      "    raise e.with_traceback(filtered_tb) from None\n",
      "  File \"C:\\Users\\vmore\\anaconda3\\lib\\site-packages\\tensorflow\\python\\framework\\ops.py\", line 1963, in _create_c_op\n",
      "    raise ValueError(e.message)\n",
      "ValueError: Exception encountered when calling layer \"conv1d_102\" (type Conv1D).\n",
      "\n",
      "Negative dimension size caused by subtracting 5 from 4 for '{{node conv1d_102/Conv1D}} = Conv2D[T=DT_FLOAT, data_format=\"NHWC\", dilations=[1, 1, 1, 1], explicit_paddings=[], padding=\"VALID\", strides=[1, 1, 1, 1], use_cudnn_on_gpu=true](conv1d_102/Conv1D/ExpandDims, conv1d_102/Conv1D/ExpandDims_1)' with input shapes: [?,1,4,8], [1,5,8,8].\n",
      "\n",
      "Call arguments received by layer \"conv1d_102\" (type Conv1D):\n",
      "  • inputs=tf.Tensor(shape=(None, 4, 8), dtype=float32)\n",
      "\n",
      "--------------------------------------------------------------------------------\n",
      "1 fits failed with the following error:\n",
      "Traceback (most recent call last):\n",
      "  File \"C:\\Users\\vmore\\anaconda3\\lib\\site-packages\\sklearn\\model_selection\\_validation.py\", line 686, in _fit_and_score\n",
      "    estimator.fit(X_train, y_train, **fit_params)\n",
      "  File \"C:\\Users\\vmore\\anaconda3\\lib\\site-packages\\sklearn\\compose\\_target.py\", line 262, in fit\n",
      "    self.regressor_.fit(X, y_trans, **fit_params)\n",
      "  File \"C:\\Users\\vmore\\anaconda3\\lib\\site-packages\\sklearn\\pipeline.py\", line 405, in fit\n",
      "    self._final_estimator.fit(Xt, y, **fit_params_last_step)\n",
      "  File \"C:\\Users\\vmore\\AppData\\Roaming\\Python\\Python38\\site-packages\\scikeras\\wrappers.py\", line 762, in fit\n",
      "    self._fit(\n",
      "  File \"C:\\Users\\vmore\\AppData\\Roaming\\Python\\Python38\\site-packages\\scikeras\\wrappers.py\", line 918, in _fit\n",
      "    X, y = self._initialize(X, y)\n",
      "  File \"C:\\Users\\vmore\\AppData\\Roaming\\Python\\Python38\\site-packages\\scikeras\\wrappers.py\", line 855, in _initialize\n",
      "    self.model_ = self._build_keras_model()\n",
      "  File \"C:\\Users\\vmore\\AppData\\Roaming\\Python\\Python38\\site-packages\\scikeras\\wrappers.py\", line 431, in _build_keras_model\n",
      "    model = final_build_fn(**build_params)\n",
      "  File \"<ipython-input-9-97001f790343>\", line 8, in get_CNN\n",
      "  File \"C:\\Users\\vmore\\anaconda3\\lib\\site-packages\\tensorflow\\python\\training\\tracking\\base.py\", line 587, in _method_wrapper\n",
      "    result = method(self, *args, **kwargs)\n",
      "  File \"C:\\Users\\vmore\\anaconda3\\lib\\site-packages\\keras\\utils\\traceback_utils.py\", line 67, in error_handler\n",
      "    raise e.with_traceback(filtered_tb) from None\n",
      "  File \"C:\\Users\\vmore\\anaconda3\\lib\\site-packages\\tensorflow\\python\\framework\\ops.py\", line 1963, in _create_c_op\n",
      "    raise ValueError(e.message)\n",
      "ValueError: Exception encountered when calling layer \"conv1d_114\" (type Conv1D).\n",
      "\n",
      "Negative dimension size caused by subtracting 5 from 4 for '{{node conv1d_114/Conv1D}} = Conv2D[T=DT_FLOAT, data_format=\"NHWC\", dilations=[1, 1, 1, 1], explicit_paddings=[], padding=\"VALID\", strides=[1, 1, 1, 1], use_cudnn_on_gpu=true](conv1d_114/Conv1D/ExpandDims, conv1d_114/Conv1D/ExpandDims_1)' with input shapes: [?,1,4,2], [1,5,2,2].\n",
      "\n",
      "Call arguments received by layer \"conv1d_114\" (type Conv1D):\n",
      "  • inputs=tf.Tensor(shape=(None, 4, 2), dtype=float32)\n",
      "\n",
      "--------------------------------------------------------------------------------\n",
      "1 fits failed with the following error:\n",
      "Traceback (most recent call last):\n",
      "  File \"C:\\Users\\vmore\\anaconda3\\lib\\site-packages\\sklearn\\model_selection\\_validation.py\", line 686, in _fit_and_score\n",
      "    estimator.fit(X_train, y_train, **fit_params)\n",
      "  File \"C:\\Users\\vmore\\anaconda3\\lib\\site-packages\\sklearn\\compose\\_target.py\", line 262, in fit\n",
      "    self.regressor_.fit(X, y_trans, **fit_params)\n",
      "  File \"C:\\Users\\vmore\\anaconda3\\lib\\site-packages\\sklearn\\pipeline.py\", line 405, in fit\n",
      "    self._final_estimator.fit(Xt, y, **fit_params_last_step)\n",
      "  File \"C:\\Users\\vmore\\AppData\\Roaming\\Python\\Python38\\site-packages\\scikeras\\wrappers.py\", line 762, in fit\n",
      "    self._fit(\n",
      "  File \"C:\\Users\\vmore\\AppData\\Roaming\\Python\\Python38\\site-packages\\scikeras\\wrappers.py\", line 918, in _fit\n",
      "    X, y = self._initialize(X, y)\n",
      "  File \"C:\\Users\\vmore\\AppData\\Roaming\\Python\\Python38\\site-packages\\scikeras\\wrappers.py\", line 855, in _initialize\n",
      "    self.model_ = self._build_keras_model()\n",
      "  File \"C:\\Users\\vmore\\AppData\\Roaming\\Python\\Python38\\site-packages\\scikeras\\wrappers.py\", line 431, in _build_keras_model\n",
      "    model = final_build_fn(**build_params)\n",
      "  File \"<ipython-input-9-97001f790343>\", line 8, in get_CNN\n",
      "  File \"C:\\Users\\vmore\\anaconda3\\lib\\site-packages\\tensorflow\\python\\training\\tracking\\base.py\", line 587, in _method_wrapper\n",
      "    result = method(self, *args, **kwargs)\n",
      "  File \"C:\\Users\\vmore\\anaconda3\\lib\\site-packages\\keras\\utils\\traceback_utils.py\", line 67, in error_handler\n",
      "    raise e.with_traceback(filtered_tb) from None\n",
      "  File \"C:\\Users\\vmore\\anaconda3\\lib\\site-packages\\tensorflow\\python\\framework\\ops.py\", line 1963, in _create_c_op\n",
      "    raise ValueError(e.message)\n",
      "ValueError: Exception encountered when calling layer \"conv1d_116\" (type Conv1D).\n",
      "\n",
      "Negative dimension size caused by subtracting 5 from 4 for '{{node conv1d_116/Conv1D}} = Conv2D[T=DT_FLOAT, data_format=\"NHWC\", dilations=[1, 1, 1, 1], explicit_paddings=[], padding=\"VALID\", strides=[1, 1, 1, 1], use_cudnn_on_gpu=true](conv1d_116/Conv1D/ExpandDims, conv1d_116/Conv1D/ExpandDims_1)' with input shapes: [?,1,4,2], [1,5,2,2].\n",
      "\n",
      "Call arguments received by layer \"conv1d_116\" (type Conv1D):\n",
      "  • inputs=tf.Tensor(shape=(None, 4, 2), dtype=float32)\n",
      "\n",
      "--------------------------------------------------------------------------------\n",
      "1 fits failed with the following error:\n",
      "Traceback (most recent call last):\n",
      "  File \"C:\\Users\\vmore\\anaconda3\\lib\\site-packages\\sklearn\\model_selection\\_validation.py\", line 686, in _fit_and_score\n",
      "    estimator.fit(X_train, y_train, **fit_params)\n",
      "  File \"C:\\Users\\vmore\\anaconda3\\lib\\site-packages\\sklearn\\compose\\_target.py\", line 262, in fit\n",
      "    self.regressor_.fit(X, y_trans, **fit_params)\n",
      "  File \"C:\\Users\\vmore\\anaconda3\\lib\\site-packages\\sklearn\\pipeline.py\", line 405, in fit\n",
      "    self._final_estimator.fit(Xt, y, **fit_params_last_step)\n",
      "  File \"C:\\Users\\vmore\\AppData\\Roaming\\Python\\Python38\\site-packages\\scikeras\\wrappers.py\", line 762, in fit\n",
      "    self._fit(\n",
      "  File \"C:\\Users\\vmore\\AppData\\Roaming\\Python\\Python38\\site-packages\\scikeras\\wrappers.py\", line 918, in _fit\n",
      "    X, y = self._initialize(X, y)\n",
      "  File \"C:\\Users\\vmore\\AppData\\Roaming\\Python\\Python38\\site-packages\\scikeras\\wrappers.py\", line 855, in _initialize\n",
      "    self.model_ = self._build_keras_model()\n",
      "  File \"C:\\Users\\vmore\\AppData\\Roaming\\Python\\Python38\\site-packages\\scikeras\\wrappers.py\", line 431, in _build_keras_model\n",
      "    model = final_build_fn(**build_params)\n",
      "  File \"<ipython-input-9-97001f790343>\", line 8, in get_CNN\n",
      "  File \"C:\\Users\\vmore\\anaconda3\\lib\\site-packages\\tensorflow\\python\\training\\tracking\\base.py\", line 587, in _method_wrapper\n",
      "    result = method(self, *args, **kwargs)\n",
      "  File \"C:\\Users\\vmore\\anaconda3\\lib\\site-packages\\keras\\utils\\traceback_utils.py\", line 67, in error_handler\n",
      "    raise e.with_traceback(filtered_tb) from None\n",
      "  File \"C:\\Users\\vmore\\anaconda3\\lib\\site-packages\\tensorflow\\python\\framework\\ops.py\", line 1963, in _create_c_op\n",
      "    raise ValueError(e.message)\n",
      "ValueError: Exception encountered when calling layer \"conv1d_118\" (type Conv1D).\n",
      "\n",
      "Negative dimension size caused by subtracting 5 from 4 for '{{node conv1d_118/Conv1D}} = Conv2D[T=DT_FLOAT, data_format=\"NHWC\", dilations=[1, 1, 1, 1], explicit_paddings=[], padding=\"VALID\", strides=[1, 1, 1, 1], use_cudnn_on_gpu=true](conv1d_118/Conv1D/ExpandDims, conv1d_118/Conv1D/ExpandDims_1)' with input shapes: [?,1,4,4], [1,5,4,4].\n",
      "\n",
      "Call arguments received by layer \"conv1d_118\" (type Conv1D):\n",
      "  • inputs=tf.Tensor(shape=(None, 4, 4), dtype=float32)\n",
      "\n",
      "--------------------------------------------------------------------------------\n",
      "1 fits failed with the following error:\n",
      "Traceback (most recent call last):\n",
      "  File \"C:\\Users\\vmore\\anaconda3\\lib\\site-packages\\sklearn\\model_selection\\_validation.py\", line 686, in _fit_and_score\n",
      "    estimator.fit(X_train, y_train, **fit_params)\n",
      "  File \"C:\\Users\\vmore\\anaconda3\\lib\\site-packages\\sklearn\\compose\\_target.py\", line 262, in fit\n",
      "    self.regressor_.fit(X, y_trans, **fit_params)\n",
      "  File \"C:\\Users\\vmore\\anaconda3\\lib\\site-packages\\sklearn\\pipeline.py\", line 405, in fit\n",
      "    self._final_estimator.fit(Xt, y, **fit_params_last_step)\n",
      "  File \"C:\\Users\\vmore\\AppData\\Roaming\\Python\\Python38\\site-packages\\scikeras\\wrappers.py\", line 762, in fit\n",
      "    self._fit(\n",
      "  File \"C:\\Users\\vmore\\AppData\\Roaming\\Python\\Python38\\site-packages\\scikeras\\wrappers.py\", line 918, in _fit\n",
      "    X, y = self._initialize(X, y)\n",
      "  File \"C:\\Users\\vmore\\AppData\\Roaming\\Python\\Python38\\site-packages\\scikeras\\wrappers.py\", line 855, in _initialize\n",
      "    self.model_ = self._build_keras_model()\n",
      "  File \"C:\\Users\\vmore\\AppData\\Roaming\\Python\\Python38\\site-packages\\scikeras\\wrappers.py\", line 431, in _build_keras_model\n",
      "    model = final_build_fn(**build_params)\n",
      "  File \"<ipython-input-9-97001f790343>\", line 8, in get_CNN\n",
      "  File \"C:\\Users\\vmore\\anaconda3\\lib\\site-packages\\tensorflow\\python\\training\\tracking\\base.py\", line 587, in _method_wrapper\n",
      "    result = method(self, *args, **kwargs)\n",
      "  File \"C:\\Users\\vmore\\anaconda3\\lib\\site-packages\\keras\\utils\\traceback_utils.py\", line 67, in error_handler\n",
      "    raise e.with_traceback(filtered_tb) from None\n",
      "  File \"C:\\Users\\vmore\\anaconda3\\lib\\site-packages\\tensorflow\\python\\framework\\ops.py\", line 1963, in _create_c_op\n",
      "    raise ValueError(e.message)\n",
      "ValueError: Exception encountered when calling layer \"conv1d_120\" (type Conv1D).\n",
      "\n",
      "Negative dimension size caused by subtracting 5 from 4 for '{{node conv1d_120/Conv1D}} = Conv2D[T=DT_FLOAT, data_format=\"NHWC\", dilations=[1, 1, 1, 1], explicit_paddings=[], padding=\"VALID\", strides=[1, 1, 1, 1], use_cudnn_on_gpu=true](conv1d_120/Conv1D/ExpandDims, conv1d_120/Conv1D/ExpandDims_1)' with input shapes: [?,1,4,4], [1,5,4,4].\n",
      "\n",
      "Call arguments received by layer \"conv1d_120\" (type Conv1D):\n",
      "  • inputs=tf.Tensor(shape=(None, 4, 4), dtype=float32)\n",
      "\n",
      "--------------------------------------------------------------------------------\n",
      "1 fits failed with the following error:\n",
      "Traceback (most recent call last):\n",
      "  File \"C:\\Users\\vmore\\anaconda3\\lib\\site-packages\\sklearn\\model_selection\\_validation.py\", line 686, in _fit_and_score\n",
      "    estimator.fit(X_train, y_train, **fit_params)\n",
      "  File \"C:\\Users\\vmore\\anaconda3\\lib\\site-packages\\sklearn\\compose\\_target.py\", line 262, in fit\n",
      "    self.regressor_.fit(X, y_trans, **fit_params)\n",
      "  File \"C:\\Users\\vmore\\anaconda3\\lib\\site-packages\\sklearn\\pipeline.py\", line 405, in fit\n",
      "    self._final_estimator.fit(Xt, y, **fit_params_last_step)\n",
      "  File \"C:\\Users\\vmore\\AppData\\Roaming\\Python\\Python38\\site-packages\\scikeras\\wrappers.py\", line 762, in fit\n",
      "    self._fit(\n",
      "  File \"C:\\Users\\vmore\\AppData\\Roaming\\Python\\Python38\\site-packages\\scikeras\\wrappers.py\", line 918, in _fit\n",
      "    X, y = self._initialize(X, y)\n",
      "  File \"C:\\Users\\vmore\\AppData\\Roaming\\Python\\Python38\\site-packages\\scikeras\\wrappers.py\", line 855, in _initialize\n",
      "    self.model_ = self._build_keras_model()\n",
      "  File \"C:\\Users\\vmore\\AppData\\Roaming\\Python\\Python38\\site-packages\\scikeras\\wrappers.py\", line 431, in _build_keras_model\n",
      "    model = final_build_fn(**build_params)\n",
      "  File \"<ipython-input-9-97001f790343>\", line 8, in get_CNN\n",
      "  File \"C:\\Users\\vmore\\anaconda3\\lib\\site-packages\\tensorflow\\python\\training\\tracking\\base.py\", line 587, in _method_wrapper\n",
      "    result = method(self, *args, **kwargs)\n",
      "  File \"C:\\Users\\vmore\\anaconda3\\lib\\site-packages\\keras\\utils\\traceback_utils.py\", line 67, in error_handler\n",
      "    raise e.with_traceback(filtered_tb) from None\n",
      "  File \"C:\\Users\\vmore\\anaconda3\\lib\\site-packages\\tensorflow\\python\\framework\\ops.py\", line 1963, in _create_c_op\n",
      "    raise ValueError(e.message)\n",
      "ValueError: Exception encountered when calling layer \"conv1d_122\" (type Conv1D).\n",
      "\n",
      "Negative dimension size caused by subtracting 5 from 4 for '{{node conv1d_122/Conv1D}} = Conv2D[T=DT_FLOAT, data_format=\"NHWC\", dilations=[1, 1, 1, 1], explicit_paddings=[], padding=\"VALID\", strides=[1, 1, 1, 1], use_cudnn_on_gpu=true](conv1d_122/Conv1D/ExpandDims, conv1d_122/Conv1D/ExpandDims_1)' with input shapes: [?,1,4,6], [1,5,6,6].\n",
      "\n",
      "Call arguments received by layer \"conv1d_122\" (type Conv1D):\n",
      "  • inputs=tf.Tensor(shape=(None, 4, 6), dtype=float32)\n",
      "\n",
      "--------------------------------------------------------------------------------\n",
      "1 fits failed with the following error:\n",
      "Traceback (most recent call last):\n",
      "  File \"C:\\Users\\vmore\\anaconda3\\lib\\site-packages\\sklearn\\model_selection\\_validation.py\", line 686, in _fit_and_score\n",
      "    estimator.fit(X_train, y_train, **fit_params)\n",
      "  File \"C:\\Users\\vmore\\anaconda3\\lib\\site-packages\\sklearn\\compose\\_target.py\", line 262, in fit\n",
      "    self.regressor_.fit(X, y_trans, **fit_params)\n",
      "  File \"C:\\Users\\vmore\\anaconda3\\lib\\site-packages\\sklearn\\pipeline.py\", line 405, in fit\n",
      "    self._final_estimator.fit(Xt, y, **fit_params_last_step)\n",
      "  File \"C:\\Users\\vmore\\AppData\\Roaming\\Python\\Python38\\site-packages\\scikeras\\wrappers.py\", line 762, in fit\n",
      "    self._fit(\n",
      "  File \"C:\\Users\\vmore\\AppData\\Roaming\\Python\\Python38\\site-packages\\scikeras\\wrappers.py\", line 918, in _fit\n",
      "    X, y = self._initialize(X, y)\n",
      "  File \"C:\\Users\\vmore\\AppData\\Roaming\\Python\\Python38\\site-packages\\scikeras\\wrappers.py\", line 855, in _initialize\n",
      "    self.model_ = self._build_keras_model()\n",
      "  File \"C:\\Users\\vmore\\AppData\\Roaming\\Python\\Python38\\site-packages\\scikeras\\wrappers.py\", line 431, in _build_keras_model\n",
      "    model = final_build_fn(**build_params)\n",
      "  File \"<ipython-input-9-97001f790343>\", line 8, in get_CNN\n",
      "  File \"C:\\Users\\vmore\\anaconda3\\lib\\site-packages\\tensorflow\\python\\training\\tracking\\base.py\", line 587, in _method_wrapper\n",
      "    result = method(self, *args, **kwargs)\n",
      "  File \"C:\\Users\\vmore\\anaconda3\\lib\\site-packages\\keras\\utils\\traceback_utils.py\", line 67, in error_handler\n",
      "    raise e.with_traceback(filtered_tb) from None\n",
      "  File \"C:\\Users\\vmore\\anaconda3\\lib\\site-packages\\tensorflow\\python\\framework\\ops.py\", line 1963, in _create_c_op\n",
      "    raise ValueError(e.message)\n",
      "ValueError: Exception encountered when calling layer \"conv1d_124\" (type Conv1D).\n",
      "\n",
      "Negative dimension size caused by subtracting 5 from 4 for '{{node conv1d_124/Conv1D}} = Conv2D[T=DT_FLOAT, data_format=\"NHWC\", dilations=[1, 1, 1, 1], explicit_paddings=[], padding=\"VALID\", strides=[1, 1, 1, 1], use_cudnn_on_gpu=true](conv1d_124/Conv1D/ExpandDims, conv1d_124/Conv1D/ExpandDims_1)' with input shapes: [?,1,4,6], [1,5,6,6].\n",
      "\n",
      "Call arguments received by layer \"conv1d_124\" (type Conv1D):\n",
      "  • inputs=tf.Tensor(shape=(None, 4, 6), dtype=float32)\n",
      "\n",
      "--------------------------------------------------------------------------------\n",
      "1 fits failed with the following error:\n",
      "Traceback (most recent call last):\n",
      "  File \"C:\\Users\\vmore\\anaconda3\\lib\\site-packages\\sklearn\\model_selection\\_validation.py\", line 686, in _fit_and_score\n",
      "    estimator.fit(X_train, y_train, **fit_params)\n",
      "  File \"C:\\Users\\vmore\\anaconda3\\lib\\site-packages\\sklearn\\compose\\_target.py\", line 262, in fit\n",
      "    self.regressor_.fit(X, y_trans, **fit_params)\n",
      "  File \"C:\\Users\\vmore\\anaconda3\\lib\\site-packages\\sklearn\\pipeline.py\", line 405, in fit\n",
      "    self._final_estimator.fit(Xt, y, **fit_params_last_step)\n",
      "  File \"C:\\Users\\vmore\\AppData\\Roaming\\Python\\Python38\\site-packages\\scikeras\\wrappers.py\", line 762, in fit\n",
      "    self._fit(\n",
      "  File \"C:\\Users\\vmore\\AppData\\Roaming\\Python\\Python38\\site-packages\\scikeras\\wrappers.py\", line 918, in _fit\n",
      "    X, y = self._initialize(X, y)\n",
      "  File \"C:\\Users\\vmore\\AppData\\Roaming\\Python\\Python38\\site-packages\\scikeras\\wrappers.py\", line 855, in _initialize\n",
      "    self.model_ = self._build_keras_model()\n",
      "  File \"C:\\Users\\vmore\\AppData\\Roaming\\Python\\Python38\\site-packages\\scikeras\\wrappers.py\", line 431, in _build_keras_model\n",
      "    model = final_build_fn(**build_params)\n",
      "  File \"<ipython-input-9-97001f790343>\", line 8, in get_CNN\n",
      "  File \"C:\\Users\\vmore\\anaconda3\\lib\\site-packages\\tensorflow\\python\\training\\tracking\\base.py\", line 587, in _method_wrapper\n",
      "    result = method(self, *args, **kwargs)\n",
      "  File \"C:\\Users\\vmore\\anaconda3\\lib\\site-packages\\keras\\utils\\traceback_utils.py\", line 67, in error_handler\n",
      "    raise e.with_traceback(filtered_tb) from None\n",
      "  File \"C:\\Users\\vmore\\anaconda3\\lib\\site-packages\\tensorflow\\python\\framework\\ops.py\", line 1963, in _create_c_op\n",
      "    raise ValueError(e.message)\n",
      "ValueError: Exception encountered when calling layer \"conv1d_126\" (type Conv1D).\n",
      "\n",
      "Negative dimension size caused by subtracting 5 from 4 for '{{node conv1d_126/Conv1D}} = Conv2D[T=DT_FLOAT, data_format=\"NHWC\", dilations=[1, 1, 1, 1], explicit_paddings=[], padding=\"VALID\", strides=[1, 1, 1, 1], use_cudnn_on_gpu=true](conv1d_126/Conv1D/ExpandDims, conv1d_126/Conv1D/ExpandDims_1)' with input shapes: [?,1,4,8], [1,5,8,8].\n",
      "\n",
      "Call arguments received by layer \"conv1d_126\" (type Conv1D):\n",
      "  • inputs=tf.Tensor(shape=(None, 4, 8), dtype=float32)\n",
      "\n",
      "--------------------------------------------------------------------------------\n",
      "1 fits failed with the following error:\n",
      "Traceback (most recent call last):\n",
      "  File \"C:\\Users\\vmore\\anaconda3\\lib\\site-packages\\sklearn\\model_selection\\_validation.py\", line 686, in _fit_and_score\n",
      "    estimator.fit(X_train, y_train, **fit_params)\n",
      "  File \"C:\\Users\\vmore\\anaconda3\\lib\\site-packages\\sklearn\\compose\\_target.py\", line 262, in fit\n",
      "    self.regressor_.fit(X, y_trans, **fit_params)\n",
      "  File \"C:\\Users\\vmore\\anaconda3\\lib\\site-packages\\sklearn\\pipeline.py\", line 405, in fit\n",
      "    self._final_estimator.fit(Xt, y, **fit_params_last_step)\n",
      "  File \"C:\\Users\\vmore\\AppData\\Roaming\\Python\\Python38\\site-packages\\scikeras\\wrappers.py\", line 762, in fit\n",
      "    self._fit(\n",
      "  File \"C:\\Users\\vmore\\AppData\\Roaming\\Python\\Python38\\site-packages\\scikeras\\wrappers.py\", line 918, in _fit\n",
      "    X, y = self._initialize(X, y)\n",
      "  File \"C:\\Users\\vmore\\AppData\\Roaming\\Python\\Python38\\site-packages\\scikeras\\wrappers.py\", line 855, in _initialize\n",
      "    self.model_ = self._build_keras_model()\n",
      "  File \"C:\\Users\\vmore\\AppData\\Roaming\\Python\\Python38\\site-packages\\scikeras\\wrappers.py\", line 431, in _build_keras_model\n",
      "    model = final_build_fn(**build_params)\n",
      "  File \"<ipython-input-9-97001f790343>\", line 8, in get_CNN\n",
      "  File \"C:\\Users\\vmore\\anaconda3\\lib\\site-packages\\tensorflow\\python\\training\\tracking\\base.py\", line 587, in _method_wrapper\n",
      "    result = method(self, *args, **kwargs)\n",
      "  File \"C:\\Users\\vmore\\anaconda3\\lib\\site-packages\\keras\\utils\\traceback_utils.py\", line 67, in error_handler\n",
      "    raise e.with_traceback(filtered_tb) from None\n",
      "  File \"C:\\Users\\vmore\\anaconda3\\lib\\site-packages\\tensorflow\\python\\framework\\ops.py\", line 1963, in _create_c_op\n",
      "    raise ValueError(e.message)\n",
      "ValueError: Exception encountered when calling layer \"conv1d_128\" (type Conv1D).\n",
      "\n",
      "Negative dimension size caused by subtracting 5 from 4 for '{{node conv1d_128/Conv1D}} = Conv2D[T=DT_FLOAT, data_format=\"NHWC\", dilations=[1, 1, 1, 1], explicit_paddings=[], padding=\"VALID\", strides=[1, 1, 1, 1], use_cudnn_on_gpu=true](conv1d_128/Conv1D/ExpandDims, conv1d_128/Conv1D/ExpandDims_1)' with input shapes: [?,1,4,8], [1,5,8,8].\n",
      "\n",
      "Call arguments received by layer \"conv1d_128\" (type Conv1D):\n",
      "  • inputs=tf.Tensor(shape=(None, 4, 8), dtype=float32)\n",
      "\n",
      "\n",
      "C:\\Users\\vmore\\anaconda3\\lib\\site-packages\\sklearn\\model_selection\\_search.py:952: UserWarning:\n",
      "\n",
      "One or more of the test scores are non-finite: [-0.02767851 -0.02771452 -0.02762202 -0.02770818 -0.02777231 -0.02776677\n",
      " -0.02763852 -0.0277845  -0.02893666 -0.02835751 -0.02809779 -0.02806412\n",
      " -0.02810707 -0.02803076 -0.02813956 -0.02776709 -0.02765634 -0.02762588\n",
      " -0.02766219 -0.02778816 -0.02875558 -0.02795209 -0.02807369 -0.02792396\n",
      " -0.02864555 -0.02781964 -0.02905722 -0.02789388         nan         nan\n",
      "         nan         nan -0.02749829 -0.0275371  -0.0275584  -0.02761649\n",
      " -0.02768543 -0.0277041  -0.02754477 -0.02758917 -0.02890474 -0.02784031\n",
      " -0.02807327 -0.02763617 -0.0304922  -0.02847561 -0.02771589 -0.02806458\n",
      " -0.02773139 -0.02760116 -0.02760464 -0.0273513  -0.03053198 -0.02785157\n",
      " -0.02766035 -0.02797398 -0.0277614  -0.02837826 -0.02795699 -0.02792028\n",
      "         nan         nan         nan         nan -0.02775862 -0.0276481\n",
      " -0.02763614 -0.02761009 -0.02804341 -0.02762033 -0.02762573 -0.02757872\n",
      " -0.02972151 -0.02855182 -0.02829568 -0.02818259 -0.02957187 -0.02824904\n",
      " -0.02802896 -0.0279806  -0.02768043 -0.02775263 -0.02751877 -0.02762079\n",
      " -0.03034213 -0.02815351 -0.0279249  -0.02784866 -0.03047298 -0.02835647\n",
      " -0.02824148 -0.02829394         nan         nan         nan         nan\n",
      " -0.03091416 -0.03036508 -0.03040998 -0.03033935 -0.06661949 -0.02997121\n",
      " -0.02989161 -0.02999376 -0.03391795 -0.03266415 -0.0324228  -0.03245338\n",
      " -0.0325281  -0.03227021 -0.03225404 -0.03214848 -0.03031708 -0.03025099\n",
      " -0.03026427 -0.03025001 -0.03220195 -0.03195415 -0.03178849 -0.0318264\n",
      " -0.03260516 -0.03253685 -0.03250869 -0.03246981         nan         nan\n",
      "         nan         nan -0.11910218 -0.11910404 -0.0915757  -0.04855643\n",
      " -0.1191008  -0.11910211 -0.11910347 -0.11910321 -0.11910327 -0.09399344\n",
      " -0.11910327 -0.11910206 -0.11910441 -0.11910295 -0.11910482 -0.11910027\n",
      " -0.09277536 -0.11910147 -0.09277064 -0.05069664 -0.11910359 -0.11910353\n",
      " -0.11910295 -0.1191036  -0.11910329 -0.11910077 -0.11910267 -0.11910502\n",
      "         nan         nan         nan         nan]\n",
      "\n"
     ]
    },
    {
     "data": {
      "text/html": [
       "<style>#sk-container-id-1 {color: black;background-color: white;}#sk-container-id-1 pre{padding: 0;}#sk-container-id-1 div.sk-toggleable {background-color: white;}#sk-container-id-1 label.sk-toggleable__label {cursor: pointer;display: block;width: 100%;margin-bottom: 0;padding: 0.3em;box-sizing: border-box;text-align: center;}#sk-container-id-1 label.sk-toggleable__label-arrow:before {content: \"▸\";float: left;margin-right: 0.25em;color: #696969;}#sk-container-id-1 label.sk-toggleable__label-arrow:hover:before {color: black;}#sk-container-id-1 div.sk-estimator:hover label.sk-toggleable__label-arrow:before {color: black;}#sk-container-id-1 div.sk-toggleable__content {max-height: 0;max-width: 0;overflow: hidden;text-align: left;background-color: #f0f8ff;}#sk-container-id-1 div.sk-toggleable__content pre {margin: 0.2em;color: black;border-radius: 0.25em;background-color: #f0f8ff;}#sk-container-id-1 input.sk-toggleable__control:checked~div.sk-toggleable__content {max-height: 200px;max-width: 100%;overflow: auto;}#sk-container-id-1 input.sk-toggleable__control:checked~label.sk-toggleable__label-arrow:before {content: \"▾\";}#sk-container-id-1 div.sk-estimator input.sk-toggleable__control:checked~label.sk-toggleable__label {background-color: #d4ebff;}#sk-container-id-1 div.sk-label input.sk-toggleable__control:checked~label.sk-toggleable__label {background-color: #d4ebff;}#sk-container-id-1 input.sk-hidden--visually {border: 0;clip: rect(1px 1px 1px 1px);clip: rect(1px, 1px, 1px, 1px);height: 1px;margin: -1px;overflow: hidden;padding: 0;position: absolute;width: 1px;}#sk-container-id-1 div.sk-estimator {font-family: monospace;background-color: #f0f8ff;border: 1px dotted black;border-radius: 0.25em;box-sizing: border-box;margin-bottom: 0.5em;}#sk-container-id-1 div.sk-estimator:hover {background-color: #d4ebff;}#sk-container-id-1 div.sk-parallel-item::after {content: \"\";width: 100%;border-bottom: 1px solid gray;flex-grow: 1;}#sk-container-id-1 div.sk-label:hover label.sk-toggleable__label {background-color: #d4ebff;}#sk-container-id-1 div.sk-serial::before {content: \"\";position: absolute;border-left: 1px solid gray;box-sizing: border-box;top: 0;bottom: 0;left: 50%;z-index: 0;}#sk-container-id-1 div.sk-serial {display: flex;flex-direction: column;align-items: center;background-color: white;padding-right: 0.2em;padding-left: 0.2em;position: relative;}#sk-container-id-1 div.sk-item {position: relative;z-index: 1;}#sk-container-id-1 div.sk-parallel {display: flex;align-items: stretch;justify-content: center;background-color: white;position: relative;}#sk-container-id-1 div.sk-item::before, #sk-container-id-1 div.sk-parallel-item::before {content: \"\";position: absolute;border-left: 1px solid gray;box-sizing: border-box;top: 0;bottom: 0;left: 50%;z-index: -1;}#sk-container-id-1 div.sk-parallel-item {display: flex;flex-direction: column;z-index: 1;position: relative;background-color: white;}#sk-container-id-1 div.sk-parallel-item:first-child::after {align-self: flex-end;width: 50%;}#sk-container-id-1 div.sk-parallel-item:last-child::after {align-self: flex-start;width: 50%;}#sk-container-id-1 div.sk-parallel-item:only-child::after {width: 0;}#sk-container-id-1 div.sk-dashed-wrapped {border: 1px dashed gray;margin: 0 0.4em 0.5em 0.4em;box-sizing: border-box;padding-bottom: 0.4em;background-color: white;}#sk-container-id-1 div.sk-label label {font-family: monospace;font-weight: bold;display: inline-block;line-height: 1.2em;}#sk-container-id-1 div.sk-label-container {text-align: center;}#sk-container-id-1 div.sk-container {/* jupyter's `normalize.less` sets `[hidden] { display: none; }` but bootstrap.min.css set `[hidden] { display: none !important; }` so we also need the `!important` here to be able to override the default hidden behavior on the sphinx rendered scikit-learn.org. See: https://github.com/scikit-learn/scikit-learn/issues/21755 */display: inline-block !important;position: relative;}#sk-container-id-1 div.sk-text-repr-fallback {display: none;}</style><div id=\"sk-container-id-1\" class=\"sk-top-container\"><div class=\"sk-text-repr-fallback\"><pre>GridSearchCV(cv=TimeSeriesSplit(gap=0, max_train_size=None, n_splits=2, test_size=None),\n",
       "             estimator=TransformedTargetRegressor(regressor=Pipeline(steps=[(&#x27;std_sc&#x27;,\n",
       "                                                                             StandardScaler()),\n",
       "                                                                            (&#x27;cnn&#x27;,\n",
       "                                                                             KerasRegressor(batch_size=-1, epochs=12000, loss=&#x27;mean_absolute_error&#x27;, model=&lt;function get_CNN at 0x00000193CA8E9A60&gt;, optimizer=&#x27;adam&#x27;, shuffle=False, verbose=0))]),\n",
       "                                                  transformer=StandardScaler()),\n",
       "             n_jobs=5,\n",
       "             param_grid={&#x27;regressor__cnn__model__alpha&#x27;: [1e-05, 0.0001, 0.001,\n",
       "                                                          0.01, 0.1],\n",
       "                         &#x27;regressor__cnn__model__kernel_size&#x27;: [2, 3, 4, 5],\n",
       "                         &#x27;regressor__cnn__model__n_conv_layers&#x27;: [1, 2],\n",
       "                         &#x27;regressor__cnn__model__n_filters&#x27;: [2, 4, 6, 8]},\n",
       "             scoring=&#x27;neg_mean_absolute_error&#x27;)</pre><b>In a Jupyter environment, please rerun this cell to show the HTML representation or trust the notebook. <br />On GitHub, the HTML representation is unable to render, please try loading this page with nbviewer.org.</b></div><div class=\"sk-container\" hidden><div class=\"sk-item sk-dashed-wrapped\"><div class=\"sk-label-container\"><div class=\"sk-label sk-toggleable\"><input class=\"sk-toggleable__control sk-hidden--visually\" id=\"sk-estimator-id-1\" type=\"checkbox\" ><label for=\"sk-estimator-id-1\" class=\"sk-toggleable__label sk-toggleable__label-arrow\">GridSearchCV</label><div class=\"sk-toggleable__content\"><pre>GridSearchCV(cv=TimeSeriesSplit(gap=0, max_train_size=None, n_splits=2, test_size=None),\n",
       "             estimator=TransformedTargetRegressor(regressor=Pipeline(steps=[(&#x27;std_sc&#x27;,\n",
       "                                                                             StandardScaler()),\n",
       "                                                                            (&#x27;cnn&#x27;,\n",
       "                                                                             KerasRegressor(batch_size=-1, epochs=12000, loss=&#x27;mean_absolute_error&#x27;, model=&lt;function get_CNN at 0x00000193CA8E9A60&gt;, optimizer=&#x27;adam&#x27;, shuffle=False, verbose=0))]),\n",
       "                                                  transformer=StandardScaler()),\n",
       "             n_jobs=5,\n",
       "             param_grid={&#x27;regressor__cnn__model__alpha&#x27;: [1e-05, 0.0001, 0.001,\n",
       "                                                          0.01, 0.1],\n",
       "                         &#x27;regressor__cnn__model__kernel_size&#x27;: [2, 3, 4, 5],\n",
       "                         &#x27;regressor__cnn__model__n_conv_layers&#x27;: [1, 2],\n",
       "                         &#x27;regressor__cnn__model__n_filters&#x27;: [2, 4, 6, 8]},\n",
       "             scoring=&#x27;neg_mean_absolute_error&#x27;)</pre></div></div></div><div class=\"sk-parallel\"><div class=\"sk-parallel-item\"><div class=\"sk-item\"><div class=\"sk-label-container\"><div class=\"sk-label sk-toggleable\"><input class=\"sk-toggleable__control sk-hidden--visually\" id=\"sk-estimator-id-2\" type=\"checkbox\" ><label for=\"sk-estimator-id-2\" class=\"sk-toggleable__label sk-toggleable__label-arrow\">estimator: TransformedTargetRegressor</label><div class=\"sk-toggleable__content\"><pre>TransformedTargetRegressor(regressor=Pipeline(steps=[(&#x27;std_sc&#x27;,\n",
       "                                                      StandardScaler()),\n",
       "                                                     (&#x27;cnn&#x27;,\n",
       "                                                      KerasRegressor(batch_size=-1, epochs=12000, loss=&#x27;mean_absolute_error&#x27;, model=&lt;function get_CNN at 0x00000193CA8E9A60&gt;, optimizer=&#x27;adam&#x27;, shuffle=False, verbose=0))]),\n",
       "                           transformer=StandardScaler())</pre></div></div></div><div class=\"sk-serial\"><div class=\"sk-item sk-dashed-wrapped\"><div class=\"sk-parallel\"><div class=\"sk-parallel-item\"><div class=\"sk-item\"><div class=\"sk-label-container\"><div class=\"sk-label sk-toggleable\"><input class=\"sk-toggleable__control sk-hidden--visually\" id=\"sk-estimator-id-3\" type=\"checkbox\" ><label for=\"sk-estimator-id-3\" class=\"sk-toggleable__label sk-toggleable__label-arrow\">regressor: Pipeline</label><div class=\"sk-toggleable__content\"><pre>Pipeline(steps=[(&#x27;std_sc&#x27;, StandardScaler()),\n",
       "                (&#x27;cnn&#x27;,\n",
       "                 KerasRegressor(batch_size=-1, epochs=12000, loss=&#x27;mean_absolute_error&#x27;, model=&lt;function get_CNN at 0x00000193CA8E9A60&gt;, optimizer=&#x27;adam&#x27;, shuffle=False, verbose=0))])</pre></div></div></div><div class=\"sk-serial\"><div class=\"sk-item\"><div class=\"sk-serial\"><div class=\"sk-item\"><div class=\"sk-estimator sk-toggleable\"><input class=\"sk-toggleable__control sk-hidden--visually\" id=\"sk-estimator-id-4\" type=\"checkbox\" ><label for=\"sk-estimator-id-4\" class=\"sk-toggleable__label sk-toggleable__label-arrow\">StandardScaler</label><div class=\"sk-toggleable__content\"><pre>StandardScaler()</pre></div></div></div><div class=\"sk-item\"><div class=\"sk-estimator sk-toggleable\"><input class=\"sk-toggleable__control sk-hidden--visually\" id=\"sk-estimator-id-5\" type=\"checkbox\" ><label for=\"sk-estimator-id-5\" class=\"sk-toggleable__label sk-toggleable__label-arrow\">KerasRegressor</label><div class=\"sk-toggleable__content\"><pre>KerasRegressor(\n",
       "\tmodel=&lt;function get_CNN at 0x00000193CA8E9A60&gt;\n",
       "\tbuild_fn=None\n",
       "\twarm_start=False\n",
       "\trandom_state=None\n",
       "\toptimizer=adam\n",
       "\tloss=mean_absolute_error\n",
       "\tmetrics=None\n",
       "\tbatch_size=-1\n",
       "\tvalidation_batch_size=None\n",
       "\tverbose=0\n",
       "\tcallbacks=None\n",
       "\tvalidation_split=0.0\n",
       "\tshuffle=False\n",
       "\trun_eagerly=False\n",
       "\tepochs=12000\n",
       ")</pre></div></div></div></div></div></div></div></div><div class=\"sk-parallel-item\"><div class=\"sk-item\"><div class=\"sk-label-container\"><div class=\"sk-label sk-toggleable\"><input class=\"sk-toggleable__control sk-hidden--visually\" id=\"sk-estimator-id-6\" type=\"checkbox\" ><label for=\"sk-estimator-id-6\" class=\"sk-toggleable__label sk-toggleable__label-arrow\">transformer: StandardScaler</label><div class=\"sk-toggleable__content\"><pre>StandardScaler()</pre></div></div></div><div class=\"sk-serial\"><div class=\"sk-item\"><div class=\"sk-estimator sk-toggleable\"><input class=\"sk-toggleable__control sk-hidden--visually\" id=\"sk-estimator-id-7\" type=\"checkbox\" ><label for=\"sk-estimator-id-7\" class=\"sk-toggleable__label sk-toggleable__label-arrow\">StandardScaler</label><div class=\"sk-toggleable__content\"><pre>StandardScaler()</pre></div></div></div></div></div></div></div></div></div></div></div></div></div></div></div>"
      ],
      "text/plain": [
       "GridSearchCV(cv=TimeSeriesSplit(gap=0, max_train_size=None, n_splits=2, test_size=None),\n",
       "             estimator=TransformedTargetRegressor(regressor=Pipeline(steps=[('std_sc',\n",
       "                                                                             StandardScaler()),\n",
       "                                                                            ('cnn',\n",
       "                                                                             KerasRegressor(batch_size=-1, epochs=12000, loss='mean_absolute_error', model=<function get_CNN at 0x00000193CA8E9A60>, optimizer='adam', shuffle=False, verbose=0))]),\n",
       "                                                  transformer=StandardScaler()),\n",
       "             n_jobs=5,\n",
       "             param_grid={'regressor__cnn__model__alpha': [1e-05, 0.0001, 0.001,\n",
       "                                                          0.01, 0.1],\n",
       "                         'regressor__cnn__model__kernel_size': [2, 3, 4, 5],\n",
       "                         'regressor__cnn__model__n_conv_layers': [1, 2],\n",
       "                         'regressor__cnn__model__n_filters': [2, 4, 6, 8]},\n",
       "             scoring='neg_mean_absolute_error')"
      ]
     },
     "execution_count": 9,
     "metadata": {},
     "output_type": "execute_result"
    }
   ],
   "source": [
    "def get_CNN(n_conv_layers, alpha, n_filters, kernel_size):\n",
    "    target_shape = (12, 1)\n",
    "    input_shape=(12,)\n",
    "    model = keras.Sequential()\n",
    "    model.add(keras.layers.Reshape(target_shape, input_shape=input_shape))\n",
    "    \n",
    "    for i in range(n_conv_layers):\n",
    "        model.add(keras.layers.Conv1D(input_shape=target_shape, filters=n_filters, kernel_size=kernel_size, activation='relu', kernel_regularizer=keras.regularizers.L2(alpha),))\n",
    "        model.add(keras.layers.MaxPooling1D(pool_size=2, padding='same'))\n",
    "        target_shape=(input_shape[0]-kernel_size+1, n_filters)\n",
    "        \n",
    "    model.add(keras.layers.Flatten())\n",
    "    model.add(keras.layers.Dense(10, activation=\"relu\", kernel_regularizer=keras.regularizers.L2(alpha),))\n",
    "    model.add(keras.layers.Dense(10, activation=\"relu\", kernel_regularizer=keras.regularizers.L2(alpha),))\n",
    "    out = keras.layers.Dense(6, kernel_regularizer=keras.regularizers.L2(alpha),)\n",
    "    model.add(out)\n",
    "    return model\n",
    "\n",
    "cnn = KerasRegressor(\n",
    "    model=get_CNN,\n",
    "    loss=\"mean_absolute_error\",\n",
    "    optimizer='adam',\n",
    "    epochs=12000,\n",
    "    verbose=0,\n",
    "    shuffle=False,\n",
    "    batch_size=200,\n",
    ")\n",
    "\n",
    "cnn_pipeline = Pipeline(steps=[('std_sc', StandardScaler()),\n",
    "                               ('cnn', cnn)])\n",
    "\n",
    "y_transformer = StandardScaler()\n",
    "inner_estimator = TransformedTargetRegressor(regressor=cnn_pipeline,\n",
    "                                             transformer=y_transformer)\n",
    "\n",
    "param_grid_CNN = {'regressor__cnn__model__n_conv_layers': [1, 2],\n",
    "                  'regressor__cnn__model__n_filters': [2, 4, 6, 8],\n",
    "                  'regressor__cnn__model__alpha': [0.00001, 0.0001, 0.001, 0.01, 0.1],\n",
    "                  'regressor__cnn__model__kernel_size': [2, 3, 4, 5],\n",
    "                 }\n",
    "\n",
    "# param_grid_CNN = {'regressor__cnn__model__n_conv_layers': [2],\n",
    "#                   'regressor__cnn__model__n_filters': [4],\n",
    "#                   'regressor__cnn__model__alpha': [0.0001,],\n",
    "#                   'regressor__cnn__model__kernel_size': [4,],\n",
    "#                  }\n",
    "\n",
    "# TimeSeries Cross validation\n",
    "tscv = TimeSeriesSplit(n_splits=2)\n",
    "\n",
    "# Create the GridSearchCV object\n",
    "grid_search_CNN = GridSearchCV(inner_estimator, param_grid_CNN, cv=tscv, scoring='neg_mean_absolute_error',\n",
    "                              n_jobs = 5)\n",
    "\n",
    "# Fit the GridSearchCV object to the training data\n",
    "grid_search_CNN.fit(X_train, y_train)"
   ]
  },
  {
   "cell_type": "markdown",
   "id": "502d44d8",
   "metadata": {},
   "source": [
    "### Training"
   ]
  },
  {
   "cell_type": "code",
   "execution_count": 10,
   "id": "38624fd7",
   "metadata": {},
   "outputs": [],
   "source": [
    "best_CNN_score = grid_search_CNN.best_score_\n",
    "best_CNN_model = grid_search_CNN.best_estimator_"
   ]
  },
  {
   "cell_type": "code",
   "execution_count": 11,
   "id": "649cdc28",
   "metadata": {},
   "outputs": [
    {
     "name": "stdout",
     "output_type": "stream",
     "text": [
      "Model: \"sequential\"\n",
      "_________________________________________________________________\n",
      " Layer (type)                Output Shape              Param #   \n",
      "=================================================================\n",
      " reshape (Reshape)           (None, 12, 1)             0         \n",
      "                                                                 \n",
      " conv1d (Conv1D)             (None, 9, 8)              40        \n",
      "                                                                 \n",
      " max_pooling1d (MaxPooling1D  (None, 5, 8)             0         \n",
      " )                                                               \n",
      "                                                                 \n",
      " flatten (Flatten)           (None, 40)                0         \n",
      "                                                                 \n",
      " dense (Dense)               (None, 10)                410       \n",
      "                                                                 \n",
      " dense_1 (Dense)             (None, 10)                110       \n",
      "                                                                 \n",
      " dense_2 (Dense)             (None, 6)                 66        \n",
      "                                                                 \n",
      "=================================================================\n",
      "Total params: 626\n",
      "Trainable params: 626\n",
      "Non-trainable params: 0\n",
      "_________________________________________________________________\n"
     ]
    }
   ],
   "source": [
    "best_CNN_model.regressor_.named_steps['cnn'].model_.summary()"
   ]
  },
  {
   "cell_type": "code",
   "execution_count": 12,
   "id": "a711e08e",
   "metadata": {},
   "outputs": [
    {
     "data": {
      "text/plain": [
       "{'regressor__cnn__model__alpha': 0.0001,\n",
       " 'regressor__cnn__model__kernel_size': 4,\n",
       " 'regressor__cnn__model__n_conv_layers': 1,\n",
       " 'regressor__cnn__model__n_filters': 8}"
      ]
     },
     "execution_count": 12,
     "metadata": {},
     "output_type": "execute_result"
    }
   ],
   "source": [
    "grid_search_CNN.best_params_"
   ]
  },
  {
   "cell_type": "code",
   "execution_count": 13,
   "id": "fa1678a8",
   "metadata": {},
   "outputs": [
    {
     "data": {
      "text/html": [
       "<style>#sk-container-id-2 {color: black;background-color: white;}#sk-container-id-2 pre{padding: 0;}#sk-container-id-2 div.sk-toggleable {background-color: white;}#sk-container-id-2 label.sk-toggleable__label {cursor: pointer;display: block;width: 100%;margin-bottom: 0;padding: 0.3em;box-sizing: border-box;text-align: center;}#sk-container-id-2 label.sk-toggleable__label-arrow:before {content: \"▸\";float: left;margin-right: 0.25em;color: #696969;}#sk-container-id-2 label.sk-toggleable__label-arrow:hover:before {color: black;}#sk-container-id-2 div.sk-estimator:hover label.sk-toggleable__label-arrow:before {color: black;}#sk-container-id-2 div.sk-toggleable__content {max-height: 0;max-width: 0;overflow: hidden;text-align: left;background-color: #f0f8ff;}#sk-container-id-2 div.sk-toggleable__content pre {margin: 0.2em;color: black;border-radius: 0.25em;background-color: #f0f8ff;}#sk-container-id-2 input.sk-toggleable__control:checked~div.sk-toggleable__content {max-height: 200px;max-width: 100%;overflow: auto;}#sk-container-id-2 input.sk-toggleable__control:checked~label.sk-toggleable__label-arrow:before {content: \"▾\";}#sk-container-id-2 div.sk-estimator input.sk-toggleable__control:checked~label.sk-toggleable__label {background-color: #d4ebff;}#sk-container-id-2 div.sk-label input.sk-toggleable__control:checked~label.sk-toggleable__label {background-color: #d4ebff;}#sk-container-id-2 input.sk-hidden--visually {border: 0;clip: rect(1px 1px 1px 1px);clip: rect(1px, 1px, 1px, 1px);height: 1px;margin: -1px;overflow: hidden;padding: 0;position: absolute;width: 1px;}#sk-container-id-2 div.sk-estimator {font-family: monospace;background-color: #f0f8ff;border: 1px dotted black;border-radius: 0.25em;box-sizing: border-box;margin-bottom: 0.5em;}#sk-container-id-2 div.sk-estimator:hover {background-color: #d4ebff;}#sk-container-id-2 div.sk-parallel-item::after {content: \"\";width: 100%;border-bottom: 1px solid gray;flex-grow: 1;}#sk-container-id-2 div.sk-label:hover label.sk-toggleable__label {background-color: #d4ebff;}#sk-container-id-2 div.sk-serial::before {content: \"\";position: absolute;border-left: 1px solid gray;box-sizing: border-box;top: 0;bottom: 0;left: 50%;z-index: 0;}#sk-container-id-2 div.sk-serial {display: flex;flex-direction: column;align-items: center;background-color: white;padding-right: 0.2em;padding-left: 0.2em;position: relative;}#sk-container-id-2 div.sk-item {position: relative;z-index: 1;}#sk-container-id-2 div.sk-parallel {display: flex;align-items: stretch;justify-content: center;background-color: white;position: relative;}#sk-container-id-2 div.sk-item::before, #sk-container-id-2 div.sk-parallel-item::before {content: \"\";position: absolute;border-left: 1px solid gray;box-sizing: border-box;top: 0;bottom: 0;left: 50%;z-index: -1;}#sk-container-id-2 div.sk-parallel-item {display: flex;flex-direction: column;z-index: 1;position: relative;background-color: white;}#sk-container-id-2 div.sk-parallel-item:first-child::after {align-self: flex-end;width: 50%;}#sk-container-id-2 div.sk-parallel-item:last-child::after {align-self: flex-start;width: 50%;}#sk-container-id-2 div.sk-parallel-item:only-child::after {width: 0;}#sk-container-id-2 div.sk-dashed-wrapped {border: 1px dashed gray;margin: 0 0.4em 0.5em 0.4em;box-sizing: border-box;padding-bottom: 0.4em;background-color: white;}#sk-container-id-2 div.sk-label label {font-family: monospace;font-weight: bold;display: inline-block;line-height: 1.2em;}#sk-container-id-2 div.sk-label-container {text-align: center;}#sk-container-id-2 div.sk-container {/* jupyter's `normalize.less` sets `[hidden] { display: none; }` but bootstrap.min.css set `[hidden] { display: none !important; }` so we also need the `!important` here to be able to override the default hidden behavior on the sphinx rendered scikit-learn.org. See: https://github.com/scikit-learn/scikit-learn/issues/21755 */display: inline-block !important;position: relative;}#sk-container-id-2 div.sk-text-repr-fallback {display: none;}</style><div id=\"sk-container-id-2\" class=\"sk-top-container\"><div class=\"sk-text-repr-fallback\"><pre>TransformedTargetRegressor(regressor=Pipeline(steps=[(&#x27;std_sc&#x27;,\n",
       "                                                      StandardScaler()),\n",
       "                                                     (&#x27;cnn&#x27;,\n",
       "                                                      KerasRegressor(batch_size=-1, epochs=12000, loss=&#x27;mean_absolute_error&#x27;, model=&lt;function get_CNN at 0x00000193CA8E9A60&gt;, model__alpha=0.0001, model__kernel_size=4, model__n_conv_layers=1, model__n_filters=8, optimizer=&#x27;adam&#x27;, shuffle=False, verbose=0))]),\n",
       "                           transformer=StandardScaler())</pre><b>In a Jupyter environment, please rerun this cell to show the HTML representation or trust the notebook. <br />On GitHub, the HTML representation is unable to render, please try loading this page with nbviewer.org.</b></div><div class=\"sk-container\" hidden><div class=\"sk-item sk-dashed-wrapped\"><div class=\"sk-label-container\"><div class=\"sk-label sk-toggleable\"><input class=\"sk-toggleable__control sk-hidden--visually\" id=\"sk-estimator-id-8\" type=\"checkbox\" ><label for=\"sk-estimator-id-8\" class=\"sk-toggleable__label sk-toggleable__label-arrow\">TransformedTargetRegressor</label><div class=\"sk-toggleable__content\"><pre>TransformedTargetRegressor(regressor=Pipeline(steps=[(&#x27;std_sc&#x27;,\n",
       "                                                      StandardScaler()),\n",
       "                                                     (&#x27;cnn&#x27;,\n",
       "                                                      KerasRegressor(batch_size=-1, epochs=12000, loss=&#x27;mean_absolute_error&#x27;, model=&lt;function get_CNN at 0x00000193CA8E9A60&gt;, model__alpha=0.0001, model__kernel_size=4, model__n_conv_layers=1, model__n_filters=8, optimizer=&#x27;adam&#x27;, shuffle=False, verbose=0))]),\n",
       "                           transformer=StandardScaler())</pre></div></div></div><div class=\"sk-parallel\"><div class=\"sk-parallel-item\"><div class=\"sk-item\"><div class=\"sk-label-container\"><div class=\"sk-label sk-toggleable\"><input class=\"sk-toggleable__control sk-hidden--visually\" id=\"sk-estimator-id-9\" type=\"checkbox\" ><label for=\"sk-estimator-id-9\" class=\"sk-toggleable__label sk-toggleable__label-arrow\">regressor: Pipeline</label><div class=\"sk-toggleable__content\"><pre>Pipeline(steps=[(&#x27;std_sc&#x27;, StandardScaler()),\n",
       "                (&#x27;cnn&#x27;,\n",
       "                 KerasRegressor(batch_size=-1, epochs=12000, loss=&#x27;mean_absolute_error&#x27;, model=&lt;function get_CNN at 0x00000193CA8E9A60&gt;, model__alpha=0.0001, model__kernel_size=4, model__n_conv_layers=1, model__n_filters=8, optimizer=&#x27;adam&#x27;, shuffle=False, verbose=0))])</pre></div></div></div><div class=\"sk-serial\"><div class=\"sk-item\"><div class=\"sk-serial\"><div class=\"sk-item\"><div class=\"sk-estimator sk-toggleable\"><input class=\"sk-toggleable__control sk-hidden--visually\" id=\"sk-estimator-id-10\" type=\"checkbox\" ><label for=\"sk-estimator-id-10\" class=\"sk-toggleable__label sk-toggleable__label-arrow\">StandardScaler</label><div class=\"sk-toggleable__content\"><pre>StandardScaler()</pre></div></div></div><div class=\"sk-item\"><div class=\"sk-estimator sk-toggleable\"><input class=\"sk-toggleable__control sk-hidden--visually\" id=\"sk-estimator-id-11\" type=\"checkbox\" ><label for=\"sk-estimator-id-11\" class=\"sk-toggleable__label sk-toggleable__label-arrow\">KerasRegressor</label><div class=\"sk-toggleable__content\"><pre>KerasRegressor(\n",
       "\tmodel=&lt;function get_CNN at 0x00000193CA8E9A60&gt;\n",
       "\tbuild_fn=None\n",
       "\twarm_start=False\n",
       "\trandom_state=None\n",
       "\toptimizer=adam\n",
       "\tloss=mean_absolute_error\n",
       "\tmetrics=None\n",
       "\tbatch_size=-1\n",
       "\tvalidation_batch_size=None\n",
       "\tverbose=0\n",
       "\tcallbacks=None\n",
       "\tvalidation_split=0.0\n",
       "\tshuffle=False\n",
       "\trun_eagerly=False\n",
       "\tepochs=12000\n",
       "\tmodel__alpha=0.0001\n",
       "\tmodel__kernel_size=4\n",
       "\tmodel__n_conv_layers=1\n",
       "\tmodel__n_filters=8\n",
       ")</pre></div></div></div></div></div></div></div></div><div class=\"sk-parallel-item\"><div class=\"sk-item\"><div class=\"sk-label-container\"><div class=\"sk-label sk-toggleable\"><input class=\"sk-toggleable__control sk-hidden--visually\" id=\"sk-estimator-id-12\" type=\"checkbox\" ><label for=\"sk-estimator-id-12\" class=\"sk-toggleable__label sk-toggleable__label-arrow\">transformer: StandardScaler</label><div class=\"sk-toggleable__content\"><pre>StandardScaler()</pre></div></div></div><div class=\"sk-serial\"><div class=\"sk-item\"><div class=\"sk-estimator sk-toggleable\"><input class=\"sk-toggleable__control sk-hidden--visually\" id=\"sk-estimator-id-13\" type=\"checkbox\" ><label for=\"sk-estimator-id-13\" class=\"sk-toggleable__label sk-toggleable__label-arrow\">StandardScaler</label><div class=\"sk-toggleable__content\"><pre>StandardScaler()</pre></div></div></div></div></div></div></div></div></div></div>"
      ],
      "text/plain": [
       "TransformedTargetRegressor(regressor=Pipeline(steps=[('std_sc',\n",
       "                                                      StandardScaler()),\n",
       "                                                     ('cnn',\n",
       "                                                      KerasRegressor(batch_size=-1, epochs=12000, loss='mean_absolute_error', model=<function get_CNN at 0x00000193CA8E9A60>, model__alpha=0.0001, model__kernel_size=4, model__n_conv_layers=1, model__n_filters=8, optimizer='adam', shuffle=False, verbose=0))]),\n",
       "                           transformer=StandardScaler())"
      ]
     },
     "execution_count": 13,
     "metadata": {},
     "output_type": "execute_result"
    }
   ],
   "source": [
    "best_CNN_model"
   ]
  },
  {
   "cell_type": "code",
   "execution_count": 14,
   "id": "c4888490",
   "metadata": {},
   "outputs": [],
   "source": [
    "# best_MLP_model.regressor_.named_steps['mlp'].history_"
   ]
  },
  {
   "cell_type": "code",
   "execution_count": 15,
   "id": "27386a20",
   "metadata": {},
   "outputs": [
    {
     "data": {
      "text/plain": [
       "[<matplotlib.lines.Line2D at 0x193caa558e0>]"
      ]
     },
     "execution_count": 15,
     "metadata": {},
     "output_type": "execute_result"
    },
    {
     "data": {
      "image/png": "iVBORw0KGgoAAAANSUhEUgAAA2oAAAI/CAYAAAAGHyr7AAAAOXRFWHRTb2Z0d2FyZQBNYXRwbG90bGliIHZlcnNpb24zLjMuMiwgaHR0cHM6Ly9tYXRwbG90bGliLm9yZy8vihELAAAACXBIWXMAAAsTAAALEwEAmpwYAAAwOElEQVR4nO3df5Ck+V0f9ve3n+6endWddCfdSsD94A50IMRvsZyxTAyxID4pmDOYJBJ2IAZykctKSCqVIIoql13+w6EwCU4huFJhWcahkAkIOJMDYWPLpIiBO2GBOEknlgN0qx/c6rfu1+70zDd/dPdMb+/86Jmdfp7e2deramr7efrpp7/T39m7fc/n+6PUWgMAAMDq6HXdAAAAAC4nqAEAAKwYQQ0AAGDFCGoAAAArRlADAABYMYIaAADAiul39ca33HJLvfPOO7t6ewAAgE69613v+lit9cxuz3UW1O6888488sgjXb09AABAp0opf7bXc4Y+AgAArBhBDQAAYMUIagAAACtGUAMAAFgxghoAAMCKEdQAAABWjKAGAACwYgQ1AACAFSOoAQAArBhBDQAAYMUIagAAACtGUAMAAFgxghoAAMCKEdQAAABWjKAGAACwYgQ1AACAFSOoAQAArBhBDQAAYMUIagAAACtGUAMAAFgxghoAAMCKEdQAAABWjKA245/91p/kVT/6zq6bAQAAXOcEtRmfeXaUP77wdDa3atdNAQAArmOC2oxhf/xxXBptddwSAADgeiaozVibBLWLo82OWwIAAFzPBLUZKmoAAMAqENRmDLcraoIaAADQHUFtxpqgBgAArABBbcaaoY8AAMAKENRmbM9R2xTUAACA7ghqM9b6TZLk4oZVHwEAgO4sFNRKKfeWUh4rpZwrpbxxl+dfUEr5V6WU3y+lPFpK+dvH39TlU1EDAABWwYFBrZTSJHlTklcneXmS15VSXj532d9N8t5a61cm+cYkP1pKGR5zW5duezGRDUENAADoziIVtXuSnKu1Pl5rvZTkbUnum7umJrmxlFKS3JDkE0lGx9rSFqioAQAAq2CRoHZrkidmjs9Pzs368SRfkuTDSd6T5Ptrrddc2hk2Vn0EAAC6t0hQK7ucq3PHfzXJu5N8XpKvSvLjpZTnX3GjUu4vpTxSSnnkwoULh2zq8q0NJouJjCwmAgAAdGeRoHY+ye0zx7dlXDmb9beTvL2OnUvyJ0leNn+jWuuba61na61nz5w5c9Q2L42KGgAAsAoWCWoPJ7m7lHLXZIGQ1yZ5cO6aDyZ5VZKUUl6S5IuTPH6cDW3DdI7aRUENAADoUP+gC2qto1LKG5K8I0mT5C211kdLKa+fPP9Akn+Y5K2llPdkPFTyB2qtH1tiu5diTVADAABWwIFBLUlqrQ8leWju3AMzjz+c5D873qa1z9BHAABgFSy04fX1otcrGTY9y/MDAACdEtTmDPs9G14DAACdEtTmDPu9XNq0PD8AANAdQW3OmooaAADQMUFtzriiJqgBAADdEdTmDJueVR8BAIBOCWpz1gY9+6gBAACdEtTmqKgBAABdE9TmDPuCGgAA0C1Bbc5av8nFkeX5AQCA7ghqc4Z9c9QAAIBuCWpz1gx9BAAAOiaozVFRAwAAuiaozVmz4TUAANAxQW3OWr/JxQ2LiQAAAN0R1OYMVdQAAICOCWpzphte11q7bgoAAHCdEtTmrPV72arJaEtQAwAAuiGozRn2xx+JJfoBAICuCGpz1gQ1AACgY4LanGG/SRJ7qQEAAJ0R1OYY+ggAAHRNUJszHfp4cWQvNQAAoBuC2pzhdlBTUQMAALohqM3ZHvpo02sAAKAjgtqc7aGPG4IaAADQDUFtzpqKGgAA0DFBbc6wGS/Pb9VHAACgK4LanLWBVR8BAIBuCWpzho191AAAgG4JanN2KmqCGgAA0A1BbY6KGgAA0DVBbc72PmqCGgAA0BFBbc5af7zqo8VEAACArghqcwZNSaKiBgAAdEdQm1NKybDfy0UbXgMAAB0R1Hax1u/l4oagBgAAdENQ28Vav5dLKmoAAEBHBLVdrPUbc9QAAIDOCGq7GPZ7NrwGAAA6I6jtYtj0csny/AAAQEcEtV2sDVTUAACA7ghquxhX1AQ1AACgG4LaLsxRAwAAuiSo7WLYV1EDAAC6I6jtwtBHAACgS4LaLtYGjQ2vAQCAzghqu1BRAwAAuiSo7cJiIgAAQJcEtV2s9W14DQAAdEdQ28Ww3zNHDQAA6Iygtgtz1AAAgC4JarsY9nvZqslIVQ0AAOiAoLaLYX/8sVhQBAAA6IKgtothM/5YDH8EAAC6IKjtYm0wCWqGPgIAAB0Q1HahogYAAHRJUNuFOWoAAECXBLVdrPVV1AAAgO4IaruYVtTMUQMAALogqO1i2DRJVNQAAIBuCGq7GBr6CAAAdEhQ28XOYiKbHbcEAAC4Hglqu7CYCAAA0CVBbRcWEwEAALokqO1iuuG1fdQAAIAuCGq7MPQRAADokqC2C6s+AgAAXRLUdmGOGgAA0CVBbRfTOWoqagAAQBcWCmqllHtLKY+VUs6VUt64y/P/Synl3ZOvPyylbJZSXnj8zW1Hv+mlVwQ1AACgGwcGtVJKk+RNSV6d5OVJXldKefnsNbXWH6m1flWt9auS/GCSf19r/cQS2tuaYb9nw2sAAKATi1TU7klyrtb6eK31UpK3Jblvn+tfl+Rnj6NxXVrrNypqAABAJxYJarcmeWLm+Pzk3BVKKaeT3JvkF66+ad0a9nsWEwEAADqxSFAru5yre1z715L81l7DHksp95dSHimlPHLhwoVF29iJYdOz4TUAANCJRYLa+SS3zxzfluTDe1z72uwz7LHW+uZa69la69kzZ84s3soOrPV7hj4CAACdWCSoPZzk7lLKXaWUYcZh7MH5i0opL0jyDUl++Xib2I2hoAYAAHSkf9AFtdZRKeUNSd6RpEnyllrro6WU10+ef2By6bcl+fVa69NLa22LzFEDAAC6cmBQS5Ja60NJHpo798Dc8VuTvPW4Gta1QdPLhqAGAAB0YKENr69H/V7JaHOvNVMAAACWR1DbQ78pGW0JagAAQPsEtT30e72MDH0EAAA6IKjtYaCiBgAAdERQ20NjjhoAANARQW0P/aaXjS1DHwEAgPYJansY9Eo2DX0EAAA6IKjtoen1DH0EAAA6IajtYdAUG14DAACdENT20G8MfQQAALohqO2h3+upqAEAAJ0Q1PbQ79lHDQAA6Iagtod+0xPUAACATghqe+j3SkaGPgIAAB0Q1PbQb0q2arKlqgYAALRMUNvDoBl/NIY/AgAAbRPU9tD0SpJktGX4IwAA0C5BbQ/9SVDb2FRRAwAA2iWo7WE69NGm1wAAQNsEtT1sD3208iMAANAyQW0Pg2Yy9FFFDQAAaJmgtod+bzL00Rw1AACgZYLaHvrbFTVDHwEAgHYJanuYVtRGKmoAAEDLBLU9TCtq9lEDAADaJqjtob+96qOKGgAA0C5BbQ/9yT5qKmoAAEDbBLU9DFTUAACAjghqe9je8No+agAAQMsEtT1Mhz5ubBr6CAAAtEtQ24PFRAAAgK4IanvYWZ5fUAMAANolqO1huuH1pqAGAAC0TFDbgw2vAQCArghqezBHDQAA6IqgtgcbXgMAAF0R1PbQt48aAADQEUFtD9OgZjERAACgbYLaHqarPm6YowYAALRMUNvDdNXHTXPUAACAlglqe2gmQx9V1AAAgLYJansYNDa8BgAAuiGo7WFSUMto09BHAACgXYLaHkopGTTF8vwAAEDrBLV9ND1BDQAAaJ+gto9Br5eRxUQAAICWCWr7aJqSkeX5AQCAlglq++j3eoY+AgAArRPU9tHvFas+AgAArRPU9tG36iMAANABQW0f44qaoAYAALRLUNtHv+llU0UNAABomaC2j36vZMMcNQAAoGWC2j6aXlFRAwAAWieo7aPf9LIhqAEAAC0T1PbR75Vs2vAaAABomaC2j/EcNRU1AACgXYLaPvqNOWoAAED7BLV99Hs9G14DAACtE9T2Md7w2hw1AACgXYLaPgx9BAAAuiCo7aPf69nwGgAAaJ2gtg8VNQAAoAuC2j4ay/MDAAAdENT2Mej1VNQAAIDWCWr7aJqS0ZY5agAAQLsEtX0MesU+agAAQOsEtX00vV5G5qgBAAAtE9T2MTD0EQAA6ICgto+mV1TUAACA1glq++g3vYy2amoV1gAAgPYsFNRKKfeWUh4rpZwrpbxxj2u+sZTy7lLKo6WUf3+8zexGv1eSxBL9AABAq/oHXVBKaZK8Kck3Jzmf5OFSyoO11vfOXHNTkp9Icm+t9YOllBcvqb2t6jfjoDbaquk3HTcGAAC4bixSUbsnybla6+O11ktJ3pbkvrlrvjPJ22utH0ySWuuTx9vMbkwrapboBwAA2rRIULs1yRMzx+cn52Z9UZKbSynvLKW8q5TyXcfVwC71e+OPZ9OCIgAAQIsOHPqYpOxybj659JN8TZJXJVlP8h9KKb9da/3AZTcq5f4k9yfJHXfccfjWtmw69HHDEv0AAECLFqmonU9y+8zxbUk+vMs1v1ZrfbrW+rEkv5nkK+dvVGt9c631bK317JkzZ47a5tY0FhMBAAA6sEhQezjJ3aWUu0opwySvTfLg3DW/nOQ/KaX0Symnk/yFJO873qa2bzAZ+rixqaIGAAC058Chj7XWUSnlDUnekaRJ8pZa66OllNdPnn+g1vq+UsqvJfmDJFtJfqrW+ofLbHgbVNQAAIAuLDJHLbXWh5I8NHfugbnjH0nyI8fXtO7NLs8PAADQloU2vL5eTVd9HFn1EQAAaJGgto+dipo5agAAQHsEtX1sb3itogYAALRIUNtHv5kMfTRHDQAAaJGgto+dipqhjwAAQHsEtX30Lc8PAAB0QFDbx3QxkQ1BDQAAaJGgto/p8vybVn0EAABaJKjto5kMfdyw6iMAANAiQW0fg2ZaURPUAACA9ghq+9ipqBn6CAAAtEdQ28egseojAADQPkFtH832PmqCGgAA0B5BbR/TOWojFTUAAKBFgto+titqlucHAABaJKjtYzDZR83QRwAAoE2C2j6aRkUNAABon6C2j/720EcVNQAAoD2C2j76Vn0EAAA6IKjto1FRAwAAOiCo7aOUkn6vZLRpjhoAANAeQe0ATa9kU0UNAABokaB2gEHTM/QRAABolaB2gMbQRwAAoGWC2gEGTVFRAwAAWiWoHWBcURPUAACA9ghqB+j3zFEDAADaJagdoN+UjLbMUQMAANojqB2g3zNHDQAAaJegdoB+r2fVRwAAoFWC2gH6jQ2vAQCAdglqB+j3Sjas+ggAALRIUDtAv+mpqAEAAK0S1A7Q9Eo2zFEDAABaJKgdYGCOGgAA0DJB7QBNr5cNQQ0AAGiRoHaAQa9k04bXAABAiwS1AzS9kpFVHwEAgBYJagfoNyUjQx8BAIAWCWoH6Pd6GVn1EQAAaJGgdoB+T0UNAABol6B2gH5jjhoAANAuQe0ATa+nogYAALRKUDvAeMNrc9QAAID2CGoHsDw/AADQNkHtAIPG0EcAAKBdgtoBml7JyNBHAACgRYLaAQaW5wcAAFomqB2g6fVSa7IprAEAAC0R1A7Qb0qSGP4IAAC0RlA7QL83CWpWfgQAAFoiqB2g34w/IvPUAACAtghqB9ipqBn6CAAAtENQO8B0jprFRAAAgLYIageYVtQ2BDUAAKAlgtoB+r3xR7RpMREAAKAlgtoBpkMfNyzPDwAAtERQO8B2Rc3QRwAAoCWC2gGa6Rw1qz4CAAAtEdQOMF1MREUNAABoi6B2gO05ahYTAQAAWiKoHcAcNQAAoG2C2gGmFbWROWoAAEBLBLUDTOeojVTUAACAlghqB+g3hj4CAADtEtQO0Lc8PwAA0DJB7QDTOWoqagAAQFsEtQNsV9QENQAAoCWC2gF2luc39BEAAGiHoHaApmfDawAAoF0LBbVSyr2llMdKKedKKW/c5flvLKV8upTy7snX3zv+pnZjYNVHAACgZf2DLiilNEnelOSbk5xP8nAp5cFa63vnLv1/a63fsoQ2dmpaUbPhNQAA0JZFKmr3JDlXa3281nopyduS3LfcZq2OQWPDawAAoF2LBLVbkzwxc3x+cm7eXyyl/H4p5VdLKV96LK1bATsVNUENAABox4FDH5OUXc7Np5bfS/L5tdanSimvSfJLSe6+4kal3J/k/iS54447DtfSjkznqKmoAQAAbVmkonY+ye0zx7cl+fDsBbXWz9Ran5o8fijJoJRyy/yNaq1vrrWerbWePXPmzFU0uz3mqAEAAG1bJKg9nOTuUspdpZRhktcmeXD2glLK55RSyuTxPZP7fvy4G9uF6YbXKmoAAEBbDhz6WGsdlVLekOQdSZokb6m1PlpKef3k+QeSfEeSv1NKGSV5Nslra60nItmUUtL0SkY2vAYAAFqyyBy16XDGh+bOPTDz+MeT/PjxNm119HtFRQ0AAGjNQhteX+/6vWLVRwAAoDWC2gKaXsmmihoAANASQW0Bg6aXDas+AgAALRHUFqCiBgAAtElQW8C4oiaoAQAA7RDUFjCuqBn6CAAAtENQW0C/Kdkw9BEAAGiJoLaAfq9k09BHAACgJYLaAvq9ng2vAQCA1ghqC+g3JSNz1AAAgJYIagvoW54fAABokaC2gH7PhtcAAEB7BLUF9JuSkcVEAACAlghqCxhveK2iBgAAtENQW8Cw38vFkaAGAAC0Q1BbwLDfyyUVNQAAoCWC2gKGhj4CAAAtEtQWMGx6uWToIwAA0BJBbQHDvqAGAAC0R1BbgKAGAAC0SVBbgMVEAACANglqCxjvo1ZTq02vAQCA5RPUFrDWH39MqmoAAEAbBLUFDJtJUDNPDQAAaIGgtoBhX1ADAADaI6gtYGjoIwAA0CJBbQGDydDHjZHFRAAAgOUT1BawU1Hb7LglAADA9UBQW8B0MZGL5qgBAAAtENQWsGYxEQAAoEWC2gIGlucHAABaJKgtYDpHbWPTYiIAAMDyCWoLsJgIAADQJkFtAUNDHwEAgBYJaguYVtSs+ggAALRBUFvAtKJmjhoAANAGQW0BQ8vzAwAALRLUFrAT1CwmAgAALJ+gtoCdVR9V1AAAgOUT1BZg1UcAAKBNgtoCBk1JklyymAgAANACQW0BpZQMm56KGgAA0ApBbUHDvqAGAAC0Q1Bb0LDfy6VNqz4CAADLJ6gtyNBHAACgLYLaggb9kg2LiQAAAC0Q1BakogYAALRFUFvQsN/koqAGAAC0QFBb0HgxEUENAABYPkFtQcOm5NLIqo8AAMDyCWoLGvZ7FhMBAABaIagtyGIiAABAWwS1BQ37ghoAANAOQW1Bw35jMREAAKAVgtqCBk1RUQMAAFohqC1ord+zjxoAANAKQW1Ba/3G8vwAAEArBLUFrdnwGgAAaImgtqDp0Mda7aUGAAAsl6C2oGG/l1pj02sAAGDpBLUFrfWbJMlF89QAAIAlE9QWtDYYf1SW6AcAAJZNUFvQWn/8UVmiHwAAWDZBbUE7Qx8FNQAAYLkEtQUNtytq5qgBAADLJagtaDr00Rw1AABg2QS1BRn6CAAAtEVQW9B01ceLG4IaAACwXILagoaNOWoAAEA7BLUF2UcNAABoi6C2IHPUAACAtiwU1Eop95ZSHiulnCulvHGf6762lLJZSvmO42vializPD8AANCSA4NaKaVJ8qYkr07y8iSvK6W8fI/rfjjJO467katgZx81FTUAAGC5Fqmo3ZPkXK318VrrpSRvS3LfLtf990l+IcmTx9i+lWEfNQAAoC2LBLVbkzwxc3x+cm5bKeXWJN+W5IHja9pqMUcNAABoyyJBrexyrs4d/1iSH6i17juBq5RyfynlkVLKIxcuXFiwiath0JSUklzcMEcNAABYrv4C15xPcvvM8W1JPjx3zdkkbyulJMktSV5TShnVWn9p9qJa65uTvDlJzp49Ox/2VlopJcOmp6IGAAAs3SJB7eEkd5dS7kryoSSvTfKdsxfUWu+aPi6lvDXJr8yHtJNgrS+oAQAAy3dgUKu1jkopb8h4NccmyVtqrY+WUl4/ef7EzkubtzZoBDUAAGDpFqmopdb6UJKH5s7tGtBqrf/N1TdrNY0rauaoAQAAy7XQhteMGfoIAAC0QVA7hGG/sY8aAACwdILaIaioAQAAbRDUDmGt37OPGgAAsHSC2iFY9REAAGiDoHYIw6ZnjhoAALB0gtohrA0szw8AACyfoHYIFhMBAADaIKgdwlrfHDUAAGD5BLVDWOubowYAACyfoHYI46GP5qgBAADLJagdwnSOWq2166YAAAAnmKB2CGuDJrUmG5uCGgAAsDyC2iGs9ccf16VN89QAAIDlEdQOYTgJahc3zFMDAACWR1A7hGlFzRL9AADAMglqh7DWb5IIagAAwHIJaoewPUdNUAMAAJZIUDuE7Tlq9lIDAACWSFA7BEMfAQCANghqh7A2mK76KKgBAADLI6gdws4+aoY+AgAAyyOoHcLOPmoqagAAwPIIaodgjhoAANAGQe0Q1qz6CAAAtEBQO4SdoKaiBgAALI+gdghrg/HQRxteAwAAyySoHcKwUVEDAACWT1A7hEFTUkpyccMcNQAAYHkEtUMopWSt31NRAwAAlkpQO6S1fpPnVNQAAIAlEtQOaX3Q5DkbXgMAAEskqB3S+rDJsypqAADAEglqh3RqYOgjAACwXILaIZ0a9FTUAACApRLUDmldRQ0AAFgyQe2Q1gfmqAEAAMslqB3SqaFVHwEAgOUS1A7pVL/Js5dU1AAAgOUR1A5pfdgzRw0AAFgqQe2QzFEDAACWTVA7pOmqj7XWrpsCAACcUILaIa0NmmzV5NKmBUUAAIDlENQOaX3QJEmeuySoAQAAyyGoHdL6cBzUzFMDAACWRVA7pO2KmqAGAAAsiaB2SKcG449MRQ0AAFgWQe2QTg0MfQQAAJZLUDukncVEBDUAAGA5BLVDmi4m8txIUAMAAJZDUDuk7aGPlucHAACWRFA7pHVz1AAAgCUT1A7JYiIAAMCyCWqHtD1HzWIiAADAkghqh3SqP/7IbHgNAAAsi6B2SP2ml0FTDH0EAACWRlA7glODRlADAACWRlA7gvVBY+gjAACwNILaEawPmzxrMREAAGBJBLUjWB80eUZQAwAAlkRQO4L1oTlqAADA8ghqR/C8YV9FDQAAWBpB7QjWh4Y+AgAAyyOoHcHpYZNnL426bgYAAHBCCWpHcHrY5GkVNQAAYEkEtSNYH/Qtzw8AACyNoHYEp4dNnrk0Sq2166YAAAAnkKB2BOvDJls1uTja6ropAADACSSoHcHpYZMkhj8CAABLIagdwfOG/STJMza9BgAAlkBQO4L17YqaJfoBAIDjt1BQK6XcW0p5rJRyrpTyxl2ev6+U8gellHeXUh4ppXz98Td1dUyHPj59UUUNAAA4fv2DLiilNEnelOSbk5xP8nAp5cFa63tnLvuNJA/WWmsp5SuS/FySly2jwatgWlF7xhw1AABgCRapqN2T5Fyt9fFa66Ukb0ty3+wFtdan6s5a9c9LcqLXrT89maP27IahjwAAwPFbJKjdmuSJmePzk3OXKaV8Wynl/Un+nyTfczzNW02nVdQAAIAlWiSolV3OXVExq7X+Yq31ZUn+epJ/uOuNSrl/MoftkQsXLhyqoatkfSCoAQAAy7NIUDuf5PaZ49uSfHivi2utv5nkC0spt+zy3JtrrWdrrWfPnDlz6MauCvuoAQAAy7RIUHs4yd2llLtKKcMkr03y4OwFpZSXllLK5PErkgyTfPy4G7sqnrc22UdNUAMAAJbgwFUfa62jUsobkrwjSZPkLbXWR0spr588/0CSv5Hku0opG0meTfJfzSwucuKs9XspxT5qAADAchwY1JKk1vpQkofmzj0w8/iHk/zw8TZtdZVScnrQ5GkVNQAAYAkW2vCaK60P+4Y+AgAASyGoHdHpYWPoIwAAsBSC2hGdHjYqagAAwFIIake0Pmzy7IagBgAAHD9B7YhU1AAAgGUR1I7otMVEAACAJRHUjshiIgAAwLIIakd0emgfNQAAYDkEtSNaH/TzrKAGAAAsgaB2ROPFREaptXbdFAAA4IQR1I5ofdhkqyYXR1tdNwUAADhhBLUjOj1sksTwRwAA4NgJakc0DWrP2PQaAAA4ZoLaEZ0e9pPEEv0AAMCxE9SOaFpRe/qiihoAAHC8BLUjWp8OfTRHDQAAOGaC2hFtD33cMPQRAAA4XoLaEZ1WUQMAAJZEUDui9YGgBgAALIegdkT2UQMAAJZFUDui6Rw1FTUAAOC4CWpHdGrQSyn2UQMAAI6foHZEpZScHjR5WkUNAAA4ZoLaVVgf9g19BAAAjp2gdhVODxtDHwEAgGMnqF2F08NGRQ0AADh2gtpVOD1s8rSKGgAAcMwEtavwohvW8vGnLnXdDAAA4IQR1K7CLTes5WNPXey6GQAAwAkjqF2FMzeu5eNPX8poc6vrpgAAACeIoHYVztwwTK3JJ54x/BEAADg+gtpVOHPjWpLkwmcNfwQAAI6PoHYVbrlhHNQ+ZkERAADgGAlqV0FFDQAAWAZB7SpMK2qCGgAAcJwEtavwvLV+Tg8bS/QDAADHSlC7SrfcsKaiBgAAHCtB7Sp9zgtO5SOffrbrZgAAACeIoHaVbrtpPR/6pKAGAAAcH0HtKt1683o++pnnsrG51XVTAACAE0JQu0q33rSerZp89NPPdd0UAADghBDUrtKtN68nST70KcMfAQCA4yGoXaVbb5oENfPUAACAYyKoXaXPmwS184IaAABwTAS1q3Rq0OS2m9fzxxee6ropAADACSGoHYO7X3xDPvDnn+26GQAAwAkhqB2DL3rJjXn8wtMZWaIfAAA4BoLaMbj7JTfm0uZW/uwTz3TdFAAA4AQQ1I7BF73khiTJYx81/BEAALh6gtox+OLPuTHDppd3P/GprpsCAACcAILaMVjrN/myW5+f3/uzT3bdFAAA4AQQ1I7JK+64OX/woU/n0siCIgAAwNUR1I7JKz7/5lwabeU9H/p0100BAACucYLaMXnlF74oTa/knY892XVTAACAa5ygdkxuOj3M13z+zfmN9wlqAADA1RHUjtGrXvbivPcjn8n5T9pPDQAAODpB7Ri95ss/N0ny9t/7UMctAQAArmWC2jG6/YWn85de+qL83CNPZGurdt0cAADgGiWoHbP/8uztOf/JZ/Nv32+uGgAAcDSC2jF7zZd/bm69aT1veue51KqqBgAAHJ6gdswGTS+v/4YvyH/84KfyW+c+3nVzAACAa5CgtgT/xdnbc9vN6/kH/+rRbGxudd0cAADgGiOoLcGpQZO//9e+NH/05FP5yXf+cdfNAQAArjGC2pJ808tfkm/9ys/Lj/2bD+S3zn2s6+YAAADXEEFtif7Rt395vvDMDflvf/qR/Pbj5qsBAACLEdSW6Hlr/fzM9/2FfN5N6/nut/xufvZ3P2glSAAA4ECC2pK9+Pmn8i/v/7p87Z0vzA++/T357/7Fu/LEJ57pulkAAMAKE9Ra8KIb1vLT33NP3vjql+U3/+hC/sqPvjM/9IvvyeMXnuq6aQAAwAoqXQ3FO3v2bH3kkUc6ee8uffhTz+ZN/+5cfu6RJ7KxWfOXv+hM/sYrbs03fclL8ry1ftfNAwAAWlJKeVet9eyuzwlq3Xjys8/lZ377g/n5d53Phz71bIb9Xr7+pbfkG77oTL72zhfmiz/nxjS90nUzAQCAJbnqoFZKuTfJP0nSJPmpWuv/Nvf830zyA5PDp5L8nVrr7+93z+s9qE1tbdU8/KefyDse/fP8+ns/mvOffDZJcuOpfr7m82/O1975wnzFbS/IF3/OjTlzw1pKEd4AAOAkuKqgVkppknwgyTcnOZ/k4SSvq7W+d+aaVyZ5X631k6WUVyf5+7XWv7DffQW1K9Vac/6Tz+bhP/1EHv7TT+bhP/1Ezj25M4/tBeuD3Pmi07n15vXcdvPp3HrTem67eT2f+4L13HiqnxvW+nnB+iA9lTgAAFh5+wW1RSZF3ZPkXK318cnN3pbkviTbQa3W+v/NXP/bSW47enOvX6WU3P7C07n9hafz7a8Yf4SffPpS3veRz+T9H/1szl14Kk984pm8/6Ofzb9535O5NNq64h4vWB/kJc9fy03rw9wwCW83nOrnxrXx4+fNHp8aH08f37DWz/qgSb+5co2Zi6PNDJueih4AALRgkaB2a5InZo7PJ9mvWva9SX71ahrFjpufN8wrX3pLXvnSWy47v7VV87GnL+ZDn3w2H/n0c3nq4iiffW6UP77wVD7+1MV86pmNPPnZ5/L4hVGeuriZpy5u5LmNK4PdboZNL6cGvawPm5waNGl6JY9feDpJ8sovfFFOD5usDZqs9XsZNr0Mml6G/cmfTdl+PD0/bHoZ9EuGTZNBUzLo97LW9LI26KXf66XplTS9klODZvLakrWmSb8p6Tclg15PlRAAgOvKIkFtt38h7zpespTyn2Yc1L5+j+fvT3J/ktxxxx0LNpHd9HolL77xVF5846l89YKv2djcytOTQPf0pVGeem6Uz14c/zk9/+zG5vjr0maemzze3Kr5zLOjDJuS5zY286lnNvLcaDMXN7aysTn9qrk02sqlzcXC4KG/35L0m3Ho6zcl/d440E2DXL8paabneiX9Zvp458+mKRlsP9fLWr93xbX9plz2eP7cXs81vfG9Bs04eI7bNrl/b3xtr5c0vZJeKSklKpQAAOxpkaB2PsntM8e3Jfnw/EWllK9I8lNJXl1r/fhuN6q1vjnJm5PxHLVDt5arMmh6uen0MDedHi7tPWqtGW2NQ9vG5ji4jR9ffu7ixvjP0eZWtuo4RD63sTl5fnztaHMro62ajc2tjDZrNra2sjGqGW2N7zf//GhrfDzarJP7bWW0ORpfO/PcaPIeF0fjEDq9d9sLoPZK0ivj4JaS9HtlXK3sj6uY/Umlcbr6Z6+MHw/7vfRKJtdMQ+POtb0yPu71SprJa2Yfl+33zSQ0lpm2ZHI8vW7neOf6mdf3xq8vmb/n5Li3+3skM8e9/d5jkXbMtjuXvdde12zfu5eZtu/22USYBgA6sUhQezjJ3aWUu5J8KMlrk3zn7AWllDuSvD3Jf11r/cCxt5JrRinjatJgl3luq25zGvq2dkLgNPRNz+0W+kZbO+Fxc4/gONqq2dqq2ao1m3X8+LmNrWzVmpqMz2/WPH1pM5dG4/Mbm+M/R5vja2od3//S5la2tpLNWvPMpVFGW3U7cG5Orpl+bdXL/9zcmt5r/J7jr/G9tybnOtqxY2XNhreS3cNcr7d7GCyZHPf2C4PT1+0XnK98fZm7JhmHzvVhk2YS/qftLZPvY/t4Epanz22H0kl7pz8bJSV1MoCiZPxLgqZXUic/J73JLxTmP6+SnV8KlMmgjDozEKPWZG3Qu6x9s6/dLxtPfyFRZ35up38/kmxXtae/rNi5985nlIz//my3efJ8SXb95cL085t+ZtPvf/zedbuaPm13Sdn+ezloyuSz2mnDoNfb+b6v6KfL+yzzz+3yOc337Xy/L3qPnT7c+XmfN983s9/D7M/K/M/n/Pvv1q/TLun1Ln/v3d5zNPlvYa+UnB40lz0/HSo/+9+1/uSXSgDXkgODWq11VEp5Q5J3ZLw8/1tqrY+WUl4/ef6BJH8vyYuS/MTkP4SjvVYvgVU1/gdgc/CFJ9zOP0J3QuROsJscb10Z9KbXbtXxHMr9wuD0notcs9ufO6Fy9vrp63f+Eb3nNVs755L5e+ay5y8LsTn4mt3aMT3euuL7mPn8rvjeLr9mc2vrsvfIHu95cbQ1DuR1pj/Hl6dm8rlPjjNzvNMndRKyZv6hnHGw2RhtZXMS4ErJ9i8Adn52ctnnCV0ZB+rLz83vTVrmrt85v1sa3f81868re75m7zbs9T7zr9vr3ldct09bs1Bb519x+DZcfn7v46Pce6/Pbv5wz9cs2IZ5i37Ge917fdCk19v5f8PmVt2eKnGQ2f+279aII/Xfkj6DRX/uyx4dedU/l7t8X89f7+cffftX5FqySEUttdaHkjw0d+6Bmcffl+T7jrdpQBemv/3u7fp7b1jMNHwm4yA4reJMA9zG5tZ2eBxff3llbBomZ/9nW2u2K8Qllw9PLSXj6vO0ejypRl/epml76vZrdwLtTpDdLTBP/0xyRWVzWnnfaXdNf1I129wav9fmJEgnO+2cDdCZCdCXB+rJJzR7fu65+dC92z3mv8fd7j/9Kz/9xcOVfTp3PPMeqXX7H2Pb9537RcJ8f5eyc9/pLwCSnc952pb5NtQk/aZk2PQy2qq5OLNQVs34FzFJkjIe8t0rmYxQuLztu31f89923eM18xfOHtZ6dfe+4h/ie937CPfb7zXZpw2LtvXyz2H318xfuOdnt09b93rNFa/bpw2X3e8qv7/51u7X1mcubWZra/zz3296WeuXXJrM9z9ISbms4rxfP1/Wvu2/5Iv9bBylH7LHa3b778au91qwf/duy8Hf1wuXOPVnWRYKagBwGNPwNK+ZnFO9BoD9XXsTiQAAAE44QQ0AAGDFCGoAAAArRlADAABYMYIaAADAihHUAAAAVoygBgAAsGIENQAAgBUjqAEAAKwYQQ0AAGDFCGoAAAArRlADAABYMYIaAADAihHUAAAAVoygBgAAsGIENQAAgBUjqAEAAKwYQQ0AAGDFCGoAAAArRlADAABYMYIaAADAihHUAAAAVoygBgAAsGJKrbWbNy7lQpI/6+TN93dLko913Qg6oe+vX/r++qXvr1/6/vqk369fq9r3n19rPbPbE50FtVVVSnmk1nq263bQPn1//dL31y99f/3S99cn/X79uhb73tBHAACAFSOoAQAArBhB7Upv7roBdEbfX7/0/fVL31+/9P31Sb9fv665vjdHDQAAYMWoqAEAAKwYQW1GKeXeUspjpZRzpZQ3dt0erk4p5fZSyr8rpbyvlPJoKeX7J+dfWEr516WUP5r8efPMa35w0v+PlVL+6sz5rymlvGfy3P9ZSildfE8cTimlKaX8x1LKr0yO9f11oJRyUynl50sp75/8/f+L+v7kK6X8T5P/1v9hKeVnSymn9PvJVUp5SynlyVLKH86cO7b+LqWslVL+5eT875RS7mz1G2RXe/T7j0z+e/8HpZRfLKXcNPPcNd3vgtpEKaVJ8qYkr07y8iSvK6W8vNtWcZVGSf7nWuuXJPm6JH930qdvTPIbtda7k/zG5DiT516b5EuT3JvkJyY/F0nyk0nuT3L35OveNr8Rjuz7k7xv5ljfXx/+SZJfq7W+LMlXZvwzoO9PsFLKrUn+hyRna61flqTJuF/1+8n11lzZN8fZ39+b5JO11pcm+T+S/PDSvhMO4625st//dZIvq7V+RZIPJPnB5GT0u6C2454k52qtj9daLyV5W5L7Om4TV6HW+pFa6+9NHn8243+s3Zpxv/7zyWX/PMlfnzy+L8nbaq0Xa61/kuRckntKKZ+b5Pm11v9Qx5M6f3rmNayoUsptSf7zJD81c1rfn3CllOcn+ctJ/mmS1Fov1Vo/FX1/PegnWS+l9JOcTvLh6PcTq9b6m0k+MXf6OPt79l4/n+RVqqvd263fa62/XmsdTQ5/O8ltk8fXfL8LajtuTfLEzPH5yTlOgEnp+quT/E6Sl9RaP5KMw1ySF08u2+tn4NbJ4/nzrLYfS/K/JtmaOafvT74vSHIhyT8r42GvP1VKeV70/YlWa/1Qkn+c5INJPpLk07XWX49+v94cZ39vv2YSAj6d5EVLaznH5XuS/Ork8TXf74Lajt3SsiUxT4BSyg1JfiHJ/1hr/cx+l+5yru5znhVVSvmWJE/WWt+16Et2Oafvr039JK9I8pO11q9O8nQmw5/2oO9PgMlcpPuS3JXk85I8r5Tyt/Z7yS7n9PvJdZT+9rNwjSml/FDG015+Znpql8uuqX4X1HacT3L7zPFtGQ+b4BpWShlkHNJ+ptb69snpP5+UvTP588nJ+b1+Bs5np4w+e57V9ZeSfGsp5U8zHsb8V0op/1f0/fXgfJLztdbfmRz/fMbBTd+fbN+U5E9qrRdqrRtJ3p7kldHv15vj7O/t10yG074gVw61ZEWUUr47ybck+Zt1Z++xa77fBbUdDye5u5RyVyllmPHkwwc7bhNXYTKm+J8meV+t9X+feerBJN89efzdSX555vxrJyv+3JXx5NLfnQyf+Gwp5esm9/yumdewgmqtP1hrva3WemfGf5f/ba31b0Xfn3i11o8meaKU8sWTU69K8t7o+5Pug0m+rpRyetJfr8p4XrJ+v74cZ3/P3us7Mv7/iIraCiql3JvkB5J8a631mZmnrv1+r7X6mnwleU3Gq8X8cZIf6ro9vq66P78+43L1HyR59+TrNRmPNf6NJH80+fOFM6/5oUn/P5bk1TPnzyb5w8lzP57JZvG+Vv8ryTcm+ZXJY31/HXwl+aokj0z+7v9Skpv1/cn/SvIPkrx/0mf/Ismafj+5X0l+NuP5iBsZV0G+9zj7O8mpJP93xgtQ/G6SL+j6e/a1Z7+fy3he2fTfeg+clH6fNgoAAIAVYegjAADAihHUAAAAVoygBgAAsGIENQAAgBUjqAEAAKwYQQ0AAGDFCGoAAAArRlADAABYMf8/XvbyDxecPTQAAAAASUVORK5CYII=\n",
      "text/plain": [
       "<Figure size 1080x720 with 1 Axes>"
      ]
     },
     "metadata": {
      "needs_background": "light"
     },
     "output_type": "display_data"
    }
   ],
   "source": [
    "plt.figure(figsize=(15,10))\n",
    "plt.plot(best_CNN_model.regressor_.named_steps['cnn'].history_['loss'])\n",
    "# dir(best_MLP_model.regressor_.named_steps['mlp'].history_.values)"
   ]
  },
  {
   "cell_type": "markdown",
   "id": "c523a290",
   "metadata": {},
   "source": [
    "### Forecasting"
   ]
  },
  {
   "cell_type": "code",
   "execution_count": 16,
   "id": "6c13510b",
   "metadata": {},
   "outputs": [],
   "source": [
    "y_pred_CNN = best_CNN_model.predict(X_test)"
   ]
  },
  {
   "cell_type": "code",
   "execution_count": 17,
   "id": "d1909d54",
   "metadata": {},
   "outputs": [
    {
     "data": {
      "text/html": [
       "<div>\n",
       "<style scoped>\n",
       "    .dataframe tbody tr th:only-of-type {\n",
       "        vertical-align: middle;\n",
       "    }\n",
       "\n",
       "    .dataframe tbody tr th {\n",
       "        vertical-align: top;\n",
       "    }\n",
       "\n",
       "    .dataframe thead th {\n",
       "        text-align: right;\n",
       "    }\n",
       "</style>\n",
       "<table border=\"1\" class=\"dataframe\">\n",
       "  <thead>\n",
       "    <tr style=\"text-align: right;\">\n",
       "      <th></th>\n",
       "      <th>t+1</th>\n",
       "      <th>t+2</th>\n",
       "      <th>t+3</th>\n",
       "      <th>t+4</th>\n",
       "      <th>t+5</th>\n",
       "      <th>t+6</th>\n",
       "    </tr>\n",
       "  </thead>\n",
       "  <tbody>\n",
       "    <tr>\n",
       "      <th>0</th>\n",
       "      <td>0.144056</td>\n",
       "      <td>0.134315</td>\n",
       "      <td>0.126401</td>\n",
       "      <td>0.120939</td>\n",
       "      <td>0.117577</td>\n",
       "      <td>0.116076</td>\n",
       "    </tr>\n",
       "    <tr>\n",
       "      <th>1</th>\n",
       "      <td>0.141696</td>\n",
       "      <td>0.136717</td>\n",
       "      <td>0.132824</td>\n",
       "      <td>0.130682</td>\n",
       "      <td>0.129808</td>\n",
       "      <td>0.130212</td>\n",
       "    </tr>\n",
       "    <tr>\n",
       "      <th>2</th>\n",
       "      <td>0.139401</td>\n",
       "      <td>0.136686</td>\n",
       "      <td>0.134737</td>\n",
       "      <td>0.134336</td>\n",
       "      <td>0.134723</td>\n",
       "      <td>0.136074</td>\n",
       "    </tr>\n",
       "    <tr>\n",
       "      <th>3</th>\n",
       "      <td>0.181563</td>\n",
       "      <td>0.192641</td>\n",
       "      <td>0.201201</td>\n",
       "      <td>0.208531</td>\n",
       "      <td>0.213214</td>\n",
       "      <td>0.216540</td>\n",
       "    </tr>\n",
       "    <tr>\n",
       "      <th>4</th>\n",
       "      <td>0.176129</td>\n",
       "      <td>0.186033</td>\n",
       "      <td>0.194985</td>\n",
       "      <td>0.203486</td>\n",
       "      <td>0.208912</td>\n",
       "      <td>0.212911</td>\n",
       "    </tr>\n",
       "    <tr>\n",
       "      <th>...</th>\n",
       "      <td>...</td>\n",
       "      <td>...</td>\n",
       "      <td>...</td>\n",
       "      <td>...</td>\n",
       "      <td>...</td>\n",
       "      <td>...</td>\n",
       "    </tr>\n",
       "    <tr>\n",
       "      <th>8737</th>\n",
       "      <td>0.220080</td>\n",
       "      <td>0.226273</td>\n",
       "      <td>0.231395</td>\n",
       "      <td>0.234574</td>\n",
       "      <td>0.233722</td>\n",
       "      <td>0.230931</td>\n",
       "    </tr>\n",
       "    <tr>\n",
       "      <th>8738</th>\n",
       "      <td>0.219168</td>\n",
       "      <td>0.218877</td>\n",
       "      <td>0.218002</td>\n",
       "      <td>0.216220</td>\n",
       "      <td>0.212013</td>\n",
       "      <td>0.206932</td>\n",
       "    </tr>\n",
       "    <tr>\n",
       "      <th>8739</th>\n",
       "      <td>0.241886</td>\n",
       "      <td>0.244753</td>\n",
       "      <td>0.245888</td>\n",
       "      <td>0.246332</td>\n",
       "      <td>0.244173</td>\n",
       "      <td>0.240978</td>\n",
       "    </tr>\n",
       "    <tr>\n",
       "      <th>8740</th>\n",
       "      <td>0.324230</td>\n",
       "      <td>0.345254</td>\n",
       "      <td>0.357092</td>\n",
       "      <td>0.363697</td>\n",
       "      <td>0.365703</td>\n",
       "      <td>0.364265</td>\n",
       "    </tr>\n",
       "    <tr>\n",
       "      <th>8741</th>\n",
       "      <td>0.313696</td>\n",
       "      <td>0.324470</td>\n",
       "      <td>0.330719</td>\n",
       "      <td>0.335315</td>\n",
       "      <td>0.336231</td>\n",
       "      <td>0.335323</td>\n",
       "    </tr>\n",
       "  </tbody>\n",
       "</table>\n",
       "<p>8742 rows × 6 columns</p>\n",
       "</div>"
      ],
      "text/plain": [
       "           t+1       t+2       t+3       t+4       t+5       t+6\n",
       "0     0.144056  0.134315  0.126401  0.120939  0.117577  0.116076\n",
       "1     0.141696  0.136717  0.132824  0.130682  0.129808  0.130212\n",
       "2     0.139401  0.136686  0.134737  0.134336  0.134723  0.136074\n",
       "3     0.181563  0.192641  0.201201  0.208531  0.213214  0.216540\n",
       "4     0.176129  0.186033  0.194985  0.203486  0.208912  0.212911\n",
       "...        ...       ...       ...       ...       ...       ...\n",
       "8737  0.220080  0.226273  0.231395  0.234574  0.233722  0.230931\n",
       "8738  0.219168  0.218877  0.218002  0.216220  0.212013  0.206932\n",
       "8739  0.241886  0.244753  0.245888  0.246332  0.244173  0.240978\n",
       "8740  0.324230  0.345254  0.357092  0.363697  0.365703  0.364265\n",
       "8741  0.313696  0.324470  0.330719  0.335315  0.336231  0.335323\n",
       "\n",
       "[8742 rows x 6 columns]"
      ]
     },
     "execution_count": 17,
     "metadata": {},
     "output_type": "execute_result"
    }
   ],
   "source": [
    "df_y_pred_CNN = pd.DataFrame(y_pred_CNN, columns=['t+1', 't+2', 't+3', 't+4', 't+5', 't+6'])\n",
    "df_y_pred_CNN"
   ]
  },
  {
   "cell_type": "code",
   "execution_count": 18,
   "id": "5f748941",
   "metadata": {},
   "outputs": [],
   "source": [
    "MAE_CNN_t1=metrics.mean_absolute_error(y_test['(t+1)'], df_y_pred_CNN['t+1'])\n",
    "MAE_CNN_t2=metrics.mean_absolute_error(y_test['(t+2)'], df_y_pred_CNN['t+2'])\n",
    "MAE_CNN_t3=metrics.mean_absolute_error(y_test['(t+3)'], df_y_pred_CNN['t+3'])\n",
    "MAE_CNN_t4=metrics.mean_absolute_error(y_test['(t+4)'], df_y_pred_CNN['t+4'])\n",
    "MAE_CNN_t5=metrics.mean_absolute_error(y_test['(t+5)'], df_y_pred_CNN['t+5'])\n",
    "MAE_CNN_t6=metrics.mean_absolute_error(y_test['(t+6)'], df_y_pred_CNN['t+6'])"
   ]
  },
  {
   "cell_type": "code",
   "execution_count": 19,
   "id": "378101ac",
   "metadata": {
    "scrolled": true
   },
   "outputs": [
    {
     "name": "stdout",
     "output_type": "stream",
     "text": [
      "MAE en t+1: 0.83%\n",
      "MAE en t+2: 1.68%\n",
      "MAE en t+3: 2.49%\n",
      "MAE en t+4: 3.25%\n",
      "MAE en t+5: 3.94%\n",
      "MAE en t+6: 4.58%\n"
     ]
    }
   ],
   "source": [
    "print('MAE en t+1: {:2.2%}'.format(MAE_CNN_t1))\n",
    "print('MAE en t+2: {:2.2%}'.format(MAE_CNN_t2))\n",
    "print('MAE en t+3: {:2.2%}'.format(MAE_CNN_t3))\n",
    "print('MAE en t+4: {:2.2%}'.format(MAE_CNN_t4))\n",
    "print('MAE en t+5: {:2.2%}'.format(MAE_CNN_t5))\n",
    "print('MAE en t+6: {:2.2%}'.format(MAE_CNN_t6))"
   ]
  },
  {
   "cell_type": "markdown",
   "id": "3a2d47db",
   "metadata": {},
   "source": [
    "### old version ###\n",
    "{'regressor__cnn__model__hidden_layer_sizes': (25,),\n",
    " 'regressor__cnn__model__kernel_size': 3,\n",
    " 'regressor__cnn__model__n_filters': 4}\n",
    " \n",
    "MAE en t+1: 0.86%\n",
    "MAE en t+2: 1.71%\n",
    "MAE en t+3: 2.52%\n",
    "MAE en t+4: 3.29%\n",
    "MAE en t+5: 3.99%\n",
    "MAE en t+6: 4.62%\n",
    "\n",
    "### previous v2 ###\n",
    "{'regressor__cnn__model__alpha': 0.0001,\n",
    " 'regressor__cnn__model__kernel_size': 3,\n",
    " 'regressor__cnn__model__n_conv_layers': 1,\n",
    " 'regressor__cnn__model__n_filters': 4}\n",
    " \n",
    "MAE en t+1: 0.88%\n",
    "MAE en t+2: 1.72%\n",
    "MAE en t+3: 2.53%\n",
    "MAE en t+4: 3.28%\n",
    "MAE en t+5: 3.97%\n",
    "MAE en t+6: 4.59%"
   ]
  },
  {
   "cell_type": "markdown",
   "id": "edf90cf2",
   "metadata": {},
   "source": [
    "# Guardar el modelo"
   ]
  },
  {
   "cell_type": "code",
   "execution_count": 20,
   "id": "5214515d",
   "metadata": {},
   "outputs": [],
   "source": [
    "# best_MLP_model.regressor_.named_steps['mlp'].model_.save('modelos/MLP_scikeras_model.h5')\n",
    "# joblib.dump(best_CNN_model, \"modelos/CNN_scikeras_model2.joblib\")"
   ]
  },
  {
   "cell_type": "markdown",
   "id": "8bc69edb",
   "metadata": {},
   "source": [
    "# Cargar el modelo"
   ]
  },
  {
   "cell_type": "code",
   "execution_count": 9,
   "id": "22b1dc58",
   "metadata": {},
   "outputs": [
    {
     "name": "stdout",
     "output_type": "stream",
     "text": [
      "Name: joblib\n",
      "Version: 1.1.1\n",
      "Summary: Lightweight pipelining with Python functions\n",
      "Home-page: https://joblib.readthedocs.io\n",
      "Author: Gael Varoquaux\n",
      "Author-email: gael.varoquaux@normalesup.org\n",
      "License: BSD\n",
      "Location: c:\\users\\vmore\\anaconda3\\envs\\deeplearning-labs\\lib\\site-packages\n",
      "Requires: \n",
      "Required-by: sacremoses, scikit-learn, scikit-optimize\n"
     ]
    }
   ],
   "source": [
    "!pip show joblib"
   ]
  },
  {
   "cell_type": "code",
   "execution_count": 10,
   "id": "49c62eb8",
   "metadata": {},
   "outputs": [
    {
     "name": "stdout",
     "output_type": "stream",
     "text": [
      "^C\n"
     ]
    }
   ],
   "source": [
    "!pip uninstall joblib"
   ]
  },
  {
   "cell_type": "code",
   "execution_count": 12,
   "id": "cae5dea0",
   "metadata": {},
   "outputs": [
    {
     "ename": "AttributeError",
     "evalue": "Can't get attribute 'get_CNN' on <module '__main__'>",
     "output_type": "error",
     "traceback": [
      "\u001b[1;31m---------------------------------------------------------------------------\u001b[0m",
      "\u001b[1;31mAttributeError\u001b[0m                            Traceback (most recent call last)",
      "Cell \u001b[1;32mIn [12], line 2\u001b[0m\n\u001b[0;32m      1\u001b[0m \u001b[38;5;66;03m# loaded_MLP = keras.models.load_model('modelos/MLP_scikeras_model.h5')\u001b[39;00m\n\u001b[1;32m----> 2\u001b[0m loaded_MLP \u001b[38;5;241m=\u001b[39m \u001b[43mjoblib\u001b[49m\u001b[38;5;241;43m.\u001b[39;49m\u001b[43mload\u001b[49m\u001b[43m(\u001b[49m\u001b[38;5;124;43m\"\u001b[39;49m\u001b[38;5;124;43mmodelos/CNN_scikeras_model2.joblib\u001b[39;49m\u001b[38;5;124;43m\"\u001b[39;49m\u001b[43m)\u001b[49m\n",
      "File \u001b[1;32m~\\anaconda3\\envs\\deeplearning-labs\\lib\\site-packages\\joblib\\numpy_pickle.py:587\u001b[0m, in \u001b[0;36mload\u001b[1;34m(filename, mmap_mode)\u001b[0m\n\u001b[0;32m    581\u001b[0m             \u001b[38;5;28;01mif\u001b[39;00m \u001b[38;5;28misinstance\u001b[39m(fobj, \u001b[38;5;28mstr\u001b[39m):\n\u001b[0;32m    582\u001b[0m                 \u001b[38;5;66;03m# if the returned file object is a string, this means we\u001b[39;00m\n\u001b[0;32m    583\u001b[0m                 \u001b[38;5;66;03m# try to load a pickle file generated with an version of\u001b[39;00m\n\u001b[0;32m    584\u001b[0m                 \u001b[38;5;66;03m# Joblib so we load it with joblib compatibility function.\u001b[39;00m\n\u001b[0;32m    585\u001b[0m                 \u001b[38;5;28;01mreturn\u001b[39;00m load_compatibility(fobj)\n\u001b[1;32m--> 587\u001b[0m             obj \u001b[38;5;241m=\u001b[39m \u001b[43m_unpickle\u001b[49m\u001b[43m(\u001b[49m\u001b[43mfobj\u001b[49m\u001b[43m,\u001b[49m\u001b[43m \u001b[49m\u001b[43mfilename\u001b[49m\u001b[43m,\u001b[49m\u001b[43m \u001b[49m\u001b[43mmmap_mode\u001b[49m\u001b[43m)\u001b[49m\n\u001b[0;32m    588\u001b[0m \u001b[38;5;28;01mreturn\u001b[39;00m obj\n",
      "File \u001b[1;32m~\\anaconda3\\envs\\deeplearning-labs\\lib\\site-packages\\joblib\\numpy_pickle.py:506\u001b[0m, in \u001b[0;36m_unpickle\u001b[1;34m(fobj, filename, mmap_mode)\u001b[0m\n\u001b[0;32m    504\u001b[0m obj \u001b[38;5;241m=\u001b[39m \u001b[38;5;28;01mNone\u001b[39;00m\n\u001b[0;32m    505\u001b[0m \u001b[38;5;28;01mtry\u001b[39;00m:\n\u001b[1;32m--> 506\u001b[0m     obj \u001b[38;5;241m=\u001b[39m \u001b[43munpickler\u001b[49m\u001b[38;5;241;43m.\u001b[39;49m\u001b[43mload\u001b[49m\u001b[43m(\u001b[49m\u001b[43m)\u001b[49m\n\u001b[0;32m    507\u001b[0m     \u001b[38;5;28;01mif\u001b[39;00m unpickler\u001b[38;5;241m.\u001b[39mcompat_mode:\n\u001b[0;32m    508\u001b[0m         warnings\u001b[38;5;241m.\u001b[39mwarn(\u001b[38;5;124m\"\u001b[39m\u001b[38;5;124mThe file \u001b[39m\u001b[38;5;124m'\u001b[39m\u001b[38;5;132;01m%s\u001b[39;00m\u001b[38;5;124m'\u001b[39m\u001b[38;5;124m has been generated with a \u001b[39m\u001b[38;5;124m\"\u001b[39m\n\u001b[0;32m    509\u001b[0m                       \u001b[38;5;124m\"\u001b[39m\u001b[38;5;124mjoblib version less than 0.10. \u001b[39m\u001b[38;5;124m\"\u001b[39m\n\u001b[0;32m    510\u001b[0m                       \u001b[38;5;124m\"\u001b[39m\u001b[38;5;124mPlease regenerate this pickle file.\u001b[39m\u001b[38;5;124m\"\u001b[39m\n\u001b[0;32m    511\u001b[0m                       \u001b[38;5;241m%\u001b[39m filename,\n\u001b[0;32m    512\u001b[0m                       \u001b[38;5;167;01mDeprecationWarning\u001b[39;00m, stacklevel\u001b[38;5;241m=\u001b[39m\u001b[38;5;241m3\u001b[39m)\n",
      "File \u001b[1;32m~\\anaconda3\\envs\\deeplearning-labs\\lib\\pickle.py:1212\u001b[0m, in \u001b[0;36m_Unpickler.load\u001b[1;34m(self)\u001b[0m\n\u001b[0;32m   1210\u001b[0m             \u001b[38;5;28;01mraise\u001b[39;00m \u001b[38;5;167;01mEOFError\u001b[39;00m\n\u001b[0;32m   1211\u001b[0m         \u001b[38;5;28;01massert\u001b[39;00m \u001b[38;5;28misinstance\u001b[39m(key, bytes_types)\n\u001b[1;32m-> 1212\u001b[0m         \u001b[43mdispatch\u001b[49m\u001b[43m[\u001b[49m\u001b[43mkey\u001b[49m\u001b[43m[\u001b[49m\u001b[38;5;241;43m0\u001b[39;49m\u001b[43m]\u001b[49m\u001b[43m]\u001b[49m\u001b[43m(\u001b[49m\u001b[38;5;28;43mself\u001b[39;49m\u001b[43m)\u001b[49m\n\u001b[0;32m   1213\u001b[0m \u001b[38;5;28;01mexcept\u001b[39;00m _Stop \u001b[38;5;28;01mas\u001b[39;00m stopinst:\n\u001b[0;32m   1214\u001b[0m     \u001b[38;5;28;01mreturn\u001b[39;00m stopinst\u001b[38;5;241m.\u001b[39mvalue\n",
      "File \u001b[1;32m~\\anaconda3\\envs\\deeplearning-labs\\lib\\pickle.py:1537\u001b[0m, in \u001b[0;36m_Unpickler.load_stack_global\u001b[1;34m(self)\u001b[0m\n\u001b[0;32m   1535\u001b[0m \u001b[38;5;28;01mif\u001b[39;00m \u001b[38;5;28mtype\u001b[39m(name) \u001b[38;5;129;01mis\u001b[39;00m \u001b[38;5;129;01mnot\u001b[39;00m \u001b[38;5;28mstr\u001b[39m \u001b[38;5;129;01mor\u001b[39;00m \u001b[38;5;28mtype\u001b[39m(module) \u001b[38;5;129;01mis\u001b[39;00m \u001b[38;5;129;01mnot\u001b[39;00m \u001b[38;5;28mstr\u001b[39m:\n\u001b[0;32m   1536\u001b[0m     \u001b[38;5;28;01mraise\u001b[39;00m UnpicklingError(\u001b[38;5;124m\"\u001b[39m\u001b[38;5;124mSTACK_GLOBAL requires str\u001b[39m\u001b[38;5;124m\"\u001b[39m)\n\u001b[1;32m-> 1537\u001b[0m \u001b[38;5;28mself\u001b[39m\u001b[38;5;241m.\u001b[39mappend(\u001b[38;5;28;43mself\u001b[39;49m\u001b[38;5;241;43m.\u001b[39;49m\u001b[43mfind_class\u001b[49m\u001b[43m(\u001b[49m\u001b[43mmodule\u001b[49m\u001b[43m,\u001b[49m\u001b[43m \u001b[49m\u001b[43mname\u001b[49m\u001b[43m)\u001b[49m)\n",
      "File \u001b[1;32m~\\anaconda3\\envs\\deeplearning-labs\\lib\\pickle.py:1581\u001b[0m, in \u001b[0;36m_Unpickler.find_class\u001b[1;34m(self, module, name)\u001b[0m\n\u001b[0;32m   1579\u001b[0m \u001b[38;5;28m__import__\u001b[39m(module, level\u001b[38;5;241m=\u001b[39m\u001b[38;5;241m0\u001b[39m)\n\u001b[0;32m   1580\u001b[0m \u001b[38;5;28;01mif\u001b[39;00m \u001b[38;5;28mself\u001b[39m\u001b[38;5;241m.\u001b[39mproto \u001b[38;5;241m>\u001b[39m\u001b[38;5;241m=\u001b[39m \u001b[38;5;241m4\u001b[39m:\n\u001b[1;32m-> 1581\u001b[0m     \u001b[38;5;28;01mreturn\u001b[39;00m \u001b[43m_getattribute\u001b[49m\u001b[43m(\u001b[49m\u001b[43msys\u001b[49m\u001b[38;5;241;43m.\u001b[39;49m\u001b[43mmodules\u001b[49m\u001b[43m[\u001b[49m\u001b[43mmodule\u001b[49m\u001b[43m]\u001b[49m\u001b[43m,\u001b[49m\u001b[43m \u001b[49m\u001b[43mname\u001b[49m\u001b[43m)\u001b[49m[\u001b[38;5;241m0\u001b[39m]\n\u001b[0;32m   1582\u001b[0m \u001b[38;5;28;01melse\u001b[39;00m:\n\u001b[0;32m   1583\u001b[0m     \u001b[38;5;28;01mreturn\u001b[39;00m \u001b[38;5;28mgetattr\u001b[39m(sys\u001b[38;5;241m.\u001b[39mmodules[module], name)\n",
      "File \u001b[1;32m~\\anaconda3\\envs\\deeplearning-labs\\lib\\pickle.py:331\u001b[0m, in \u001b[0;36m_getattribute\u001b[1;34m(obj, name)\u001b[0m\n\u001b[0;32m    329\u001b[0m         obj \u001b[38;5;241m=\u001b[39m \u001b[38;5;28mgetattr\u001b[39m(obj, subpath)\n\u001b[0;32m    330\u001b[0m     \u001b[38;5;28;01mexcept\u001b[39;00m \u001b[38;5;167;01mAttributeError\u001b[39;00m:\n\u001b[1;32m--> 331\u001b[0m         \u001b[38;5;28;01mraise\u001b[39;00m \u001b[38;5;167;01mAttributeError\u001b[39;00m(\u001b[38;5;124m\"\u001b[39m\u001b[38;5;124mCan\u001b[39m\u001b[38;5;124m'\u001b[39m\u001b[38;5;124mt get attribute \u001b[39m\u001b[38;5;132;01m{!r}\u001b[39;00m\u001b[38;5;124m on \u001b[39m\u001b[38;5;132;01m{!r}\u001b[39;00m\u001b[38;5;124m\"\u001b[39m\n\u001b[0;32m    332\u001b[0m                              \u001b[38;5;241m.\u001b[39mformat(name, obj)) \u001b[38;5;28;01mfrom\u001b[39;00m \u001b[38;5;28mNone\u001b[39m\n\u001b[0;32m    333\u001b[0m \u001b[38;5;28;01mreturn\u001b[39;00m obj, parent\n",
      "\u001b[1;31mAttributeError\u001b[0m: Can't get attribute 'get_CNN' on <module '__main__'>"
     ]
    }
   ],
   "source": [
    "# loaded_MLP = keras.models.load_model('modelos/MLP_scikeras_model.h5')\n",
    "loaded_MLP = joblib.load(\"modelos/CNN_scikeras_model2.joblib\")"
   ]
  },
  {
   "cell_type": "code",
   "execution_count": 22,
   "id": "6999110a",
   "metadata": {},
   "outputs": [],
   "source": [
    "# plt.figure(figsize=(15,10))\n",
    "# plt.plot(loaded_MLP.regressor_.named_steps['cnn'].history_['loss'][9000:])"
   ]
  },
  {
   "cell_type": "code",
   "execution_count": 6,
   "id": "f85acc90",
   "metadata": {},
   "outputs": [
    {
     "ename": "NameError",
     "evalue": "name 'loaded_MLP' is not defined",
     "output_type": "error",
     "traceback": [
      "\u001b[1;31m---------------------------------------------------------------------------\u001b[0m",
      "\u001b[1;31mNameError\u001b[0m                                 Traceback (most recent call last)",
      "Cell \u001b[1;32mIn[6], line 1\u001b[0m\n\u001b[1;32m----> 1\u001b[0m y_pred_MLP_loaded \u001b[38;5;241m=\u001b[39m \u001b[43mloaded_MLP\u001b[49m\u001b[38;5;241m.\u001b[39mpredict(X_test)\n",
      "\u001b[1;31mNameError\u001b[0m: name 'loaded_MLP' is not defined"
     ]
    }
   ],
   "source": [
    "y_pred_MLP_loaded = loaded_MLP.predict(X_test)"
   ]
  },
  {
   "cell_type": "code",
   "execution_count": 24,
   "id": "69d9c64f",
   "metadata": {},
   "outputs": [],
   "source": [
    "# y_pred_MLP_loaded"
   ]
  },
  {
   "cell_type": "code",
   "execution_count": 25,
   "id": "53111cdb",
   "metadata": {},
   "outputs": [],
   "source": [
    "# loaded_MLP.summary()"
   ]
  }
 ],
 "metadata": {
  "kernelspec": {
   "display_name": "Python 3 (ipykernel)",
   "language": "python",
   "name": "python3"
  },
  "language_info": {
   "codemirror_mode": {
    "name": "ipython",
    "version": 3
   },
   "file_extension": ".py",
   "mimetype": "text/x-python",
   "name": "python",
   "nbconvert_exporter": "python",
   "pygments_lexer": "ipython3",
   "version": "3.8.5"
  }
 },
 "nbformat": 4,
 "nbformat_minor": 5
}
